Workbook

Sheet 總覽
A1: 派網 USDT 交易對 動能策略回測總覽
A2: 回測區間：2026-09-01 00:00 ~ 2026-09-27 06:56（Dry Run）（台北時間）；市場：PERP；勝率 = 止盈筆數 ÷ 已平倉筆數；正報酬比例 = 報酬 > 0 的筆數 ÷ 已平倉（含時間出場）
A4: 方向 | B4: 總筆數 | C4: 已平倉 | D4: 止盈 | E4: 止損 | F4: 時間出場 | G4: 未平倉 | H4: 勝率 | I4: 盈虧平衡勝率 | J4: 平均報酬/筆 | K4: 累計報酬(單利加總) | L4: 平均持倉h | M4: 止盈平均持倉h | N4: 止損平均持倉h | O4: 時間出場平均報酬 | P4: 正報酬比例
A5: 全部 | B5: =COUNTIFS(交易明細!$B$2:$B$509,"<>") | C5: =D5+E5+F5 | D5: =COUNTIFS(交易明細!$J$2:$J$509,"止盈") | E5: =COUNTIFS(交易明細!$J$2:$J$509,"止損") | F5: =COUNTIFS(交易明細!$J$2:$J$509,"時間出場") | G5: =COUNTIFS(交易明細!$J$2:$J$509,"未平倉") | H5: =IFERROR(D5/C5,0) | I5: =IFERROR(AVERAGEIFS(交易明細!$AC$2:$AC$509,交易明細!$J$2:$J$509,"<>未平倉"),參數!$B$16) | J5: =IFERROR(AVERAGEIFS(交易明細!$L$2:$L$509,交易明細!$J$2:$J$509,"<>未平倉"),0) | K5: =SUMIFS(交易明細!$L$2:$L$509,交易明細!$J$2:$J$509,"<>未平倉") | L5: =IFERROR(AVERAGEIFS(交易明細!$K$2:$K$509,交易明細!$J$2:$J$509,"<>未平倉"),0) | M5: =IFERROR(AVERAGEIFS(交易明細!$K$2:$K$509,交易明細!$J$2:$J$509,"止盈"),0) | N5: =IFERROR(AVERAGEIFS(交易明細!$K$2:$K$509,交易明細!$J$2:$J$509,"止損"),0) | O5: =IFERROR(AVERAGEIFS(交易明細!$L$2:$L$509,交易明細!$J$2:$J$509,"時間出場"),0) | P5: =IFERROR(COUNTIFS(交易明細!$J$2:$J$509,"<>未平倉",交易明細!$L$2:$L$509,">0")/C5,0)
A6: 做多 | B6: =COUNTIFS(交易明細!$C$2:$C$509,"做多",交易明細!$B$2:$B$509,"<>") | C6: =D6+E6+F6 | D6: =COUNTIFS(交易明細!$C$2:$C$509,"做多",交易明細!$J$2:$J$509,"止盈") | E6: =COUNTIFS(交易明細!$C$2:$C$509,"做多",交易明細!$J$2:$J$509,"止損") | F6: =COUNTIFS(交易明細!$C$2:$C$509,"做多",交易明細!$J$2:$J$509,"時間出場") | G6: =COUNTIFS(交易明細!$C$2:$C$509,"做多",交易明細!$J$2:$J$509,"未平倉") | H6: =IFERROR(D6/C6,0) | I6: =IFERROR(AVERAGEIFS(交易明細!$AC$2:$AC$509,交易明細!$C$2:$C$509,"做多",交易明細!$J$2:$J$509,"<>未平倉"),參數!$B$16) | J6: =IFERROR(AVERAGEIFS(交易明細!$L$2:$L$509,交易明細!$C$2:$C$509,"做多",交易明細!$J$2:$J$509,"<>未平倉"),0) | K6: =SUMIFS(交易明細!$L$2:$L$509,交易明細!$C$2:$C$509,"做多",交易明細!$J$2:$J$509,"<>未平倉") | L6: =IFERROR(AVERAGEIFS(交易明細!$K$2:$K$509,交易明細!$C$2:$C$509,"做多",交易明細!$J$2:$J$509,"<>未平倉"),0) | M6: =IFERROR(AVERAGEIFS(交易明細!$K$2:$K$509,交易明細!$C$2:$C$509,"做多",交易明細!$J$2:$J$509,"止盈"),0) | N6: =IFERROR(AVERAGEIFS(交易明細!$K$2:$K$509,交易明細!$C$2:$C$509,"做多",交易明細!$J$2:$J$509,"止損"),0) | O6: =IFERROR(AVERAGEIFS(交易明細!$L$2:$L$509,交易明細!$C$2:$C$509,"做多",交易明細!$J$2:$J$509,"時間出場"),0) | P6: =IFERROR(COUNTIFS(交易明細!$C$2:$C$509,"做多",交易明細!$J$2:$J$509,"<>未平倉",交易明細!$L$2:$L$509,">0")/C6,0)
A7: 做空 | B7: =COUNTIFS(交易明細!$C$2:$C$509,"做空",交易明細!$B$2:$B$509,"<>") | C7: =D7+E7+F7 | D7: =COUNTIFS(交易明細!$C$2:$C$509,"做空",交易明細!$J$2:$J$509,"止盈") | E7: =COUNTIFS(交易明細!$C$2:$C$509,"做空",交易明細!$J$2:$J$509,"止損") | F7: =COUNTIFS(交易明細!$C$2:$C$509,"做空",交易明細!$J$2:$J$509,"時間出場") | G7: =COUNTIFS(交易明細!$C$2:$C$509,"做空",交易明細!$J$2:$J$509,"未平倉") | H7: =IFERROR(D7/C7,0) | I7: =IFERROR(AVERAGEIFS(交易明細!$AC$2:$AC$509,交易明細!$C$2:$C$509,"做空",交易明細!$J$2:$J$509,"<>未平倉"),參數!$B$16) | J7: =IFERROR(AVERAGEIFS(交易明細!$L$2:$L$509,交易明細!$C$2:$C$509,"做空",交易明細!$J$2:$J$509,"<>未平倉"),0) | K7: =SUMIFS(交易明細!$L$2:$L$509,交易明細!$C$2:$C$509,"做空",交易明細!$J$2:$J$509,"<>未平倉") | L7: =IFERROR(AVERAGEIFS(交易明細!$K$2:$K$509,交易明細!$C$2:$C$509,"做空",交易明細!$J$2:$J$509,"<>未平倉"),0) | M7: =IFERROR(AVERAGEIFS(交易明細!$K$2:$K$509,交易明細!$C$2:$C$509,"做空",交易明細!$J$2:$J$509,"止盈"),0) | N7: =IFERROR(AVERAGEIFS(交易明細!$K$2:$K$509,交易明細!$C$2:$C$509,"做空",交易明細!$J$2:$J$509,"止損"),0) | O7: =IFERROR(AVERAGEIFS(交易明細!$L$2:$L$509,交易明細!$C$2:$C$509,"做空",交易明細!$J$2:$J$509,"時間出場"),0) | P7: =IFERROR(COUNTIFS(交易明細!$C$2:$C$509,"做空",交易明細!$J$2:$J$509,"<>未平倉",交易明細!$L$2:$L$509,">0")/C7,0)
A9: 說明
A10: ・持倉時間以主K棒為精度（觸價當根收盤計）；同根雙觸發時改用更小週期K棒判定。
A11: ・止盈以止盈價成交；止損若遇開盤跳空穿越，以開盤價成交（較保守）。
A12: ・同一根1h同時碰到止盈與止損時，依參數頁設定判斷（見交易明細『判定說明』）。
A13: ・只含目前仍上架的交易對，已下架幣種不在內（存活者偏差，實際表現可能較差）。
A14: ・可在『參數』頁修改手續費，報酬率欄位會自動重算。

Sheet 運行紀錄
A1: 執行時間(台北) | B1: 最新K棒(開盤時間) | C1: 交易對數 | D1: 新開倉 | E1: 新平倉 | F1: 錯誤數 | G1: 耗時(秒)
A2: 46292.29 | B2: 46292.288 | C2: 433 | D2: 0 | E2: 0 | F2: 0 | G2: 163.9
A3: 46292.286 | B3: 46292.285 | C3: 433 | D3: 2 | E3: 2 | F3: 0 | G3: 186.1
A4: 46292.165 | B4: 46292.163 | C4: 433 | D4: 0 | E4: 2 | F4: 0 | G4: 183.8
A5: 46292.052 | B5: 46292.051 | C5: 433 | D5: 4 | E5: 2 | F5: 0 | G5: 160.8
A6: 46291.98 | B6: 46291.979 | C6: 433 | D6: 2 | E6: 0 | F6: 0 | G6: 148.2
A7: 46291.937 | B7: 46291.936 | C7: 433 | D7: 0 | E7: 0 | F7: 0 | G7: 163.1
A8: 46291.883 | B8: 46291.882 | C8: 433 | D8: 0 | E8: 0 | F8: 0 | G8: 140.5
A9: 46291.838 | B9: 46291.837 | C9: 433 | D9: 0 | E9: 2 | F9: 0 | G9: 186.6
A10: 46291.786 | B10: 46291.785 | C10: 433 | D10: 5 | E10: 7 | F10: 0 | G10: 157.8
A11: 46291.659 | B11: 46291.658 | C11: 433 | D11: 0 | E11: 0 | F11: 0 | G11: 175.7
A12: 46291.639 | B12: 46291.638 | C12: 433 | D12: 0 | E12: 0 | F12: 0 | G12: 177.9
A13: 46291.632 | B13: 46291.631 | C13: 433 | D13: 1 | E13: 1 | F13: 0 | G13: 172.6
... A121: 46277.944 | B121: 46277.875 | C121: 442 | D121: 190 | E121: 186 | F121: 0 | G121: 63

Sheet ATR區間監控
A1: ATR 區間監控（資料來自觀察組：ATR ≥ 2%，其他條件與主策略相同）
A2: 近 1 個月最佳區間：8% 以上（每筆 +0.96%）
A3: 若最佳區間連續數個月不再是 4–5%，代表市場結構可能改變，需要重新檢查策略。
A5: 月份 | B5: 2%–3% 筆數 | C5: 2%–3% 勝率 | D5: 2%–3% 每筆報酬 | E5: 3%–4% 筆數 | F5: 3%–4% 勝率 | G5: 3%–4% 每筆報酬 | H5: 4%–5% 筆數 | I5: 4%–5% 勝率 | J5: 4%–5% 每筆報酬 | K5: 5%–6% 筆數 | L5: 5%–6% 勝率 | M5: 5%–6% 每筆報酬 | N5: 6%–8% 筆數 | O5: 6%–8% 勝率 | P5: 6%–8% 每筆報酬 | Q5: 8% 以上 筆數 | R5: 8% 以上 勝率 | S5: 8% 以上 每筆報酬
A6: 2026-09 | B6: 189 | C6: 0.57671958 | D6: -0.0048624339 | E6: 92 | F6: 0.63043478 | G6: -0.00056521739 | H6: 63 | I6: 0.61904762 | J6: -0.0014761905 | K6: 53 | L6: 0.62264151 | M6: -0.0011886792 | N6: 74 | O6: 0.62162162 | P6: -0.0012702703 | Q6: 33 | R6: 0.75757576 | S6: 0.0096060606

Sheet 資金模擬
A1: 資金模擬：依訊號時間順序下單
A2: 藍字黃底的參數可直接修改，整份模擬會自動重算
A3: 參數 | D3: 績效摘要
A4: 初始本金 | B4: 100 | D4: 最終本金（已實現） | E4: =資金明細!R1014
A5: 下單比例 | B5: 0.02 | D5: 總報酬率 | E5: =E4/B4-1
A6: 本金更新級距 | B6: 50 | D6: 最高本金 | E6: =MAX(資金明細!$R$2:$R$1014)
A7: 槓桿倍數 | B7: 50 | D7: 最低本金 | E7: =MIN(資金明細!$R$2:$R$1014)
A8: 單邊手續費 | B8: =參數!B7 | D8: 最大回撤 | E8: =MIN(資金明細!$X$2:$X$1014)
A9: 下單基準模式 | B9: 2 | D9: 已下單筆數 | E9: =COUNTIFS(資金明細!$C$2:$C$1014,"進場",資金明細!$N$2:$N$1014,"已下單")
A10: 停止交易門檻 | B10: 0 | D10: 資金不足略過 | E10: =COUNTIFS(資金明細!$C$2:$C$1014,"進場",資金明細!$N$2:$N$1014,"資金不足略過")
D11: 止盈筆數 | E11: =COUNTIFS(資金明細!$C$2:$C$1014,"出場",資金明細!$N$2:$N$1014,"已下單",資金明細!$K$2:$K$1014,"止盈")
A12: 每筆止損約虧本金 | B12: =B5*B7*IFERROR(AVERAGE(交易明細!$AB$2:$AB$509),參數!B6) | D12: 止損筆數 | E12: =COUNTIFS(資金明細!$C$2:$C$1014,"出場",資金明細!$N$2:$N$1014,"已下單",資金明細!$K$2:$K$1014,"止損")
A13: （以全倉、本金=基準本金計；模式1在本金回落時實際比例會更高） | D13: 勝率 | E13: =IFERROR(E11/COUNTIFS(資金明細!$C$2:$C$1014,"出場",資金明細!$N$2:$N$1014,"已下單"),0)
A14: 下單基準模式：1=不回滾（原規則） 2=即時本金 | D14: 最大同時持倉 | E14: =MAX(資金明細!$U$2:$U$1014)
A15: 停止交易門檻：本金 ≤ 此值即停止開新倉 | D15: 最大占用保證金 | E15: =MAX(資金明細!$S$2:$S$1014)
D16: 期末下單金額 | E16: =B5*資金明細!V1014
D17: 未平倉浮動損益（未計入） | E17: =IF(資金明細!N1005="已下單",資金明細!O1005*交易明細!L504,0)+IF(資金明細!N1006="已下單",資金明細!O1006*交易明細!L505,0)+IF(資金明細!N1013="已下單",資金明細!O1013*交易明細!L508,0)+IF(資金明細!N1014="已下單",資金明細!O1014*交易明細!L509,0)
D18: 最大總曝險倍數 | E18: =MAX(資金明細!$Y$2:$Y$1014)
D19: 當時全部止損約虧本金 | E19: =E18*參數!B6
D20: 停止交易時間 | E20: =IFERROR(INDEX(資金明細!$B$2:$B$1014,MATCH(1,資金明細!$Z$2:$Z$1014,0)),"未觸發")
D21: 停止後略過筆數 | E21: =COUNTIFS(資金明細!$C$2:$C$1014,"進場",資金明細!$N$2:$N$1014,"已停止")
A23: 規則說明
A24: ・下單金額 = 下單基準本金 × 下單比例。模式1：基準本金 = 本金曾達到的最高『級距倍數』（不回滾）；模式2：基準本金 = 當下本金。
A25: ・本金 ≤ 停止交易門檻後不再開新倉（已持有的單照常結算），避免模擬出現本金歸零後又『復活』的情況。
A26: ・剩餘本金 = 已實現本金（只在出場時結算）；可用資金 = 剩餘本金 − 占用保證金，不足下單金額時略過該訊號。
A27: ・同一時間點先處理出場再處理進場；報酬率已含進出場手續費。
A28: ・以全倉模式計算：總曝險倍數 = 所有持倉部位合計 ÷ 本金；未模擬持倉中的浮動虧損與維持保證金。
A29: ・回測結束仍持倉的交易不計入最終本金，浮動損益另列。

Sheet 資金明細
A1: 序號 | B1: 時間 | C1: 種類 | D1: 交易編號 | E1: 交易對 | F1: 方向 | G1: 開倉價 | H1: 止盈價 | I1: 止損價 | J1: 出場價 | K1: 結果 | L1: 持倉小時 | M1: 下單金額 | N1: 狀態 | O1: 部位大小 | P1: 報酬率(含費) | Q1: 損益 | R1: 剩餘本金 | S1: 占用保證金 | T1: 可用資金 | U1: 持倉數 | V1: 下單基準本金 | W1: 最高本金 | X1: 回撤 | Y1: 總曝險倍數 | Z1: 已停止
A2: 0 | C2: 起始 | Q2: 0 | R2: =資金模擬!$B$4 | S2: 0 | T2: =R2-S2 | U2: 0 | V2: =資金模擬!$B$4 | W2: =R2 | X2: 0 | Y2: 0 | Z2: 0
A3: 1 | B3: 46266.042 | C3: 進場 | D3: 1 | E3: HEMI_USDT_PERP | F3: 做多 | G3: 0.01515 | H3: 0.0156045 | I3: 0.0143925 | M3: =資金模擬!$B$5*V2 | N3: =IF(Z2=1,"已停止",IF(T2>=M3,"已下單","資金不足略過")) | O3: =IF(N3="已下單",M3*資金模擬!$B$7,0) | Q3: 0 | R3: =R2+Q3 | S3: =S2+IF(N3="已下單",M3,0) | T3: =R3-S3 | U3: =U2+IF(N3="已下單",1,0) | V3: =IF(資金模擬!$B$9=2,MAX(R3,0),MAX(V2,FLOOR(MAX(R3,0),資金模擬!$B$6))) | W3: =MAX(W2,R3) | X3: =IF(W3>0,R3/W3-1,-1) | Y3: =IF(R3>0,S3*資金模擬!$B$7/R3,0) | Z3: =IF(OR(Z2=1,R3<=資金模擬!$B$10),1,0)
A4: 2 | B4: 46266.042 | C4: 進場 | D4: 2 | E4: SKYAI_USDT_PERP | F4: 做空 | G4: 0.0548 | H4: 0.053156 | I4: 0.05754 | M4: =資金模擬!$B$5*V3 | N4: =IF(Z3=1,"已停止",IF(T3>=M4,"已下單","資金不足略過")) | O4: =IF(N4="已下單",M4*資金模擬!$B$7,0) | Q4: 0 | R4: =R3+Q4 | S4: =S3+IF(N4="已下單",M4,0) | T4: =R4-S4 | U4: =U3+IF(N4="已下單",1,0) | V4: =IF(資金模擬!$B$9=2,MAX(R4,0),MAX(V3,FLOOR(MAX(R4,0),資金模擬!$B$6))) | W4: =MAX(W3,R4) | X4: =IF(W4>0,R4/W4-1,-1) | Y4: =IF(R4>0,S4*資金模擬!$B$7/R4,0) | Z4: =IF(OR(Z3=1,R4<=資金模擬!$B$10),1,0)
A5: 3 | B5: 46266.083 | C5: 出場 | D5: 1 | E5: HEMI_USDT_PERP | F5: 做多 | G5: 0.01515 | H5: 0.0156045 | I5: 0.0143925 | J5: 0.0156045 | K5: 止盈 | L5: =交易明細!K2 | M5: =M3 | N5: =N3 | O5: =O3 | P5: =交易明細!L2 | Q5: =IF(N5="已下單",O5*P5,0) | R5: =R4+Q5 | S5: =S4-IF(N5="已下單",M5,0) | T5: =R5-S5 | U5: =U4-IF(N5="已下單",1,0) | V5: =IF(資金模擬!$B$9=2,MAX(R5,0),MAX(V4,FLOOR(MAX(R5,0),資金模擬!$B$6))) | W5: =MAX(W4,R5) | X5: =IF(W5>0,R5/W5-1,-1) | Y5: =IF(R5>0,S5*資金模擬!$B$7/R5,0) | Z5: =IF(OR(Z4=1,R5<=資金模擬!$B$10),1,0)
A6: 4 | B6: 46266.125 | C6: 進場 | D6: 3 | E6: XMR_USDT_PERP | F6: 做多 | G6: 531.58 | H6: 547.5274 | I6: 505.001 | M6: =資金模擬!$B$5*V5 | N6: =IF(Z5=1,"已停止",IF(T5>=M6,"已下單","資金不足略過")) | O6: =IF(N6="已下單",M6*資金模擬!$B$7,0) | Q6: 0 | R6: =R5+Q6 | S6: =S5+IF(N6="已下單",M6,0) | T6: =R6-S6 | U6: =U5+IF(N6="已下單",1,0) | V6: =IF(資金模擬!$B$9=2,MAX(R6,0),MAX(V5,FLOOR(MAX(R6,0),資金模擬!$B$6))) | W6: =MAX(W5,R6) | X6: =IF(W6>0,R6/W6-1,-1) | Y6: =IF(R6>0,S6*資金模擬!$B$7/R6,0) | Z6: =IF(OR(Z5=1,R6<=資金模擬!$B$10),1,0)
A7: 5 | B7: 46266.25 | C7: 進場 | D7: 4 | E7: SKR_USDT_PERP | F7: 做多 | G7: 0.028369 | H7: 0.02922007 | I7: 0.02695055 | M7: =資金模擬!$B$5*V6 | N7: =IF(Z6=1,"已停止",IF(T6>=M7,"已下單","資金不足略過")) | O7: =IF(N7="已下單",M7*資金模擬!$B$7,0) | Q7: 0 | R7: =R6+Q7 | S7: =S6+IF(N7="已下單",M7,0) | T7: =R7-S7 | U7: =U6+IF(N7="已下單",1,0) | V7: =IF(資金模擬!$B$9=2,MAX(R7,0),MAX(V6,FLOOR(MAX(R7,0),資金模擬!$B$6))) | W7: =MAX(W6,R7) | X7: =IF(W7>0,R7/W7-1,-1) | Y7: =IF(R7>0,S7*資金模擬!$B$7/R7,0) | Z7: =IF(OR(Z6=1,R7<=資金模擬!$B$10),1,0)
A8: 6 | B8: 46266.292 | C8: 出場 | D8: 4 | E8: SKR_USDT_PERP | F8: 做多 | G8: 0.028369 | H8: 0.02922007 | I8: 0.02695055 | J8: 0.02922007 | K8: 止盈 | L8: =交易明細!K5 | M8: =M7 | N8: =N7 | O8: =O7 | P8: =交易明細!L5 | Q8: =IF(N8="已下單",O8*P8,0) | R8: =R7+Q8 | S8: =S7-IF(N8="已下單",M8,0) | T8: =R8-S8 | U8: =U7-IF(N8="已下單",1,0) | V8: =IF(資金模擬!$B$9=2,MAX(R8,0),MAX(V7,FLOOR(MAX(R8,0),資金模擬!$B$6))) | W8: =MAX(W7,R8) | X8: =IF(W8>0,R8/W8-1,-1) | Y8: =IF(R8>0,S8*資金模擬!$B$7/R8,0) | Z8: =IF(OR(Z7=1,R8<=資金模擬!$B$10),1,0)
A9: 7 | B9: 46266.333 | C9: 出場 | D9: 2 | E9: SKYAI_USDT_PERP | F9: 做空 | G9: 0.0548 | H9: 0.053156 | I9: 0.05754 | J9: 0.053156 | K9: 止盈 | L9: =交易明細!K3 | M9: =M4 | N9: =N4 | O9: =O4 | P9: =交易明細!L3 | Q9: =IF(N9="已下單",O9*P9,0) | R9: =R8+Q9 | S9: =S8-IF(N9="已下單",M9,0) | T9: =R9-S9 | U9: =U8-IF(N9="已下單",1,0) | V9: =IF(資金模擬!$B$9=2,MAX(R9,0),MAX(V8,FLOOR(MAX(R9,0),資金模擬!$B$6))) | W9: =MAX(W8,R9) | X9: =IF(W9>0,R9/W9-1,-1) | Y9: =IF(R9>0,S9*資金模擬!$B$7/R9,0) | Z9: =IF(OR(Z8=1,R9<=資金模擬!$B$10),1,0)
A10: 8 | B10: 46266.375 | C10: 進場 | D10: 5 | E10: PUMP_USDT_PERP | F10: 做多 | G10: 0.004605 | H10: 0.00474315 | I10: 0.00437475 | M10: =資金模擬!$B$5*V9 | N10: =IF(Z9=1,"已停止",IF(T9>=M10,"已下單","資金不足略過")) | O10: =IF(N10="已下單",M10*資金模擬!$B$7,0) | Q10: 0 | R10: =R9+Q10 | S10: =S9+IF(N10="已下單",M10,0) | T10: =R10-S10 | U10: =U9+IF(N10="已下單",1,0) | V10: =IF(資金模擬!$B$9=2,MAX(R10,0),MAX(V9,FLOOR(MAX(R10,0),資金模擬!$B$6))) | W10: =MAX(W9,R10) | X10: =IF(W10>0,R10/W10-1,-1) | Y10: =IF(R10>0,S10*資金模擬!$B$7/R10,0) | Z10: =IF(OR(Z9=1,R10<=資金模擬!$B$10),1,0)
A11: 9 | B11: 46266.75 | C11: 出場 | D11: 5 | E11: PUMP_USDT_PERP | F11: 做多 | G11: 0.004605 | H11: 0.00474315 | I11: 0.00437475 | J11: 0.00437475 | K11: 止損 | L11: =交易明細!K6 | M11: =M10 | N11: =N10 | O11: =O10 | P11: =交易明細!L6 | Q11: =IF(N11="已下單",O11*P11,0) | R11: =R10+Q11 | S11: =S10-IF(N11="已下單",M11,0) | T11: =R11-S11 | U11: =U10-IF(N11="已下單",1,0) | V11: =IF(資金模擬!$B$9=2,MAX(R11,0),MAX(V10,FLOOR(MAX(R11,0),資金模擬!$B$6))) | W11: =MAX(W10,R11) | X11: =IF(W11>0,R11/W11-1,-1) | Y11: =IF(R11>0,S11*資金模擬!$B$7/R11,0) | Z11: =IF(OR(Z10=1,R11<=資金模擬!$B$10),1,0)
A12: 10 | B12: 46266.75 | C12: 進場 | D12: 6 | E12: ARB_USDT_PERP | F12: 做多 | G12: 0.1099 | H12: 0.113197 | I12: 0.104405 | M12: =資金模擬!$B$5*V11 | N12: =IF(Z11=1,"已停止",IF(T11>=M12,"已下單","資金不足略過")) | O12: =IF(N12="已下單",M12*資金模擬!$B$7,0) | Q12: 0 | R12: =R11+Q12 | S12: =S11+IF(N12="已下單",M12,0) | T12: =R12-S12 | U12: =U11+IF(N12="已下單",1,0) | V12: =IF(資金模擬!$B$9=2,MAX(R12,0),MAX(V11,FLOOR(MAX(R12,0),資金模擬!$B$6))) | W12: =MAX(W11,R12) | X12: =IF(W12>0,R12/W12-1,-1) | Y12: =IF(R12>0,S12*資金模擬!$B$7/R12,0) | Z12: =IF(OR(Z11=1,R12<=資金模擬!$B$10),1,0)
A13: 11 | B13: 46266.75 | C13: 進場 | D13: 7 | E13: USELESS_USDT_PERP | F13: 做多 | G13: 0.09113 | H13: 0.0938639 | I13: 0.0865735 | M13: =資金模擬!$B$5*V12 | N13: =IF(Z12=1,"已停止",IF(T12>=M13,"已下單","資金不足略過")) | O13: =IF(N13="已下單",M13*資金模擬!$B$7,0) | Q13: 0 | R13: =R12+Q13 | S13: =S12+IF(N13="已下單",M13,0) | T13: =R13-S13 | U13: =U12+IF(N13="已下單",1,0) | V13: =IF(資金模擬!$B$9=2,MAX(R13,0),MAX(V12,FLOOR(MAX(R13,0),資金模擬!$B$6))) | W13: =MAX(W12,R13) | X13: =IF(W13>0,R13/W13-1,-1) | Y13: =IF(R13>0,S13*資金模擬!$B$7/R13,0) | Z13: =IF(OR(Z12=1,R13<=資金模擬!$B$10),1,0)
A14: 12 | B14: 46266.792 | C14: 出場 | D14: 6 | E14: ARB_USDT_PERP | F14: 做多 | G14: 0.1099 | H14: 0.113197 | I14: 0.104405 | J14: 0.113197 | K14: 止盈 | L14: =交易明細!K7 | M14: =M12 | N14: =N12 | O14: =O12 | P14: =交易明細!L7 | Q14: =IF(N14="已下單",O14*P14,0) | R14: =R13+Q14 | S14: =S13-IF(N14="已下單",M14,0) | T14: =R14-S14 | U14: =U13-IF(N14="已下單",1,0) | V14: =IF(資金模擬!$B$9=2,MAX(R14,0),MAX(V13,FLOOR(MAX(R14,0),資金模擬!$B$6))) | W14: =MAX(W13,R14) | X14: =IF(W14>0,R14/W14-1,-1) | Y14: =IF(R14>0,S14*資金模擬!$B$7/R14,0) | Z14: =IF(OR(Z13=1,R14<=資金模擬!$B$10),1,0)
A15: 13 | B15: 46266.792 | C15: 出場 | D15: 7 | E15: USELESS_USDT_PERP | F15: 做多 | G15: 0.09113 | H15: 0.0938639 | I15: 0.0865735 | J15: 0.0938639 | K15: 止盈 | L15: =交易明細!K8 | M15: =M13 | N15: =N13 | O15: =O13 | P15: =交易明細!L8 | Q15: =IF(N15="已下單",O15*P15,0) | R15: =R14+Q15 | S15: =S14-IF(N15="已下單",M15,0) | T15: =R15-S15 | U15: =U14-IF(N15="已下單",1,0) | V15: =IF(資金模擬!$B$9=2,MAX(R15,0),MAX(V14,FLOOR(MAX(R15,0),資金模擬!$B$6))) | W15: =MAX(W14,R15) | X15: =IF(W15>0,R15/W15-1,-1) | Y15: =IF(R15>0,S15*資金模擬!$B$7/R15,0) | Z15: =IF(OR(Z14=1,R15<=資金模擬!$B$10),1,0)
A16: 14 | B16: 46266.833 | C16: 進場 | D16: 8 | E16: HEMI_USDT_PERP | F16: 做多 | G16: 0.0161 | H16: 0.016583 | I16: 0.015295 | M16: =資金模擬!$B$5*V15 | N16: =IF(Z15=1,"已停止",IF(T15>=M16,"已下單","資金不足略過")) | O16: =IF(N16="已下單",M16*資金模擬!$B$7,0) | Q16: 0 | R16: =R15+Q16 | S16: =S15+IF(N16="已下單",M16,0) | T16: =R16-S16 | U16: =U15+IF(N16="已下單",1,0) | V16: =IF(資金模擬!$B$9=2,MAX(R16,0),MAX(V15,FLOOR(MAX(R16,0),資金模擬!$B$6))) | W16: =MAX(W15,R16) | X16: =IF(W16>0,R16/W16-1,-1) | Y16: =IF(R16>0,S16*資金模擬!$B$7/R16,0) | Z16: =IF(OR(Z15=1,R16<=資金模擬!$B$10),1,0)
A17: 15 | B17: 46266.917 | C17: 進場 | D17: 9 | E17: PUMP_USDT_PERP | F17: 做多 | G17: 0.004467 | H17: 0.00460101 | I17: 0.00424365 | M17: =資金模擬!$B$5*V16 | N17: =IF(Z16=1,"已停止",IF(T16>=M17,"已下單","資金不足略過")) | O17: =IF(N17="已下單",M17*資金模擬!$B$7,0) | Q17: 0 | R17: =R16+Q17 | S17: =S16+IF(N17="已下單",M17,0) | T17: =R17-S17 | U17: =U16+IF(N17="已下單",1,0) | V17: =IF(資金模擬!$B$9=2,MAX(R17,0),MAX(V16,FLOOR(MAX(R17,0),資金模擬!$B$6))) | W17: =MAX(W16,R17) | X17: =IF(W17>0,R17/W17-1,-1) | Y17: =IF(R17>0,S17*資金模擬!$B$7/R17,0) | Z17: =IF(OR(Z16=1,R17<=資金模擬!$B$10),1,0)
A18: 16 | B18: 46267 | C18: 出場 | D18: 3 | E18: XMR_USDT_PERP | F18: 做多 | G18: 531.58 | H18: 547.5274 | I18: 505.001 | J18: 505.001 | K18: 止損 | L18: =交易明細!K4 | M18: =M6 | N18: =N6 | O18: =O6 | P18: =交易明細!L4 | Q18: =IF(N18="已下單",O18*P18,0) | R18: =R17+Q18 | S18: =S17-IF(N18="已下單",M18,0) | T18: =R18-S18 | U18: =U17-IF(N18="已下單",1,0) | V18: =IF(資金模擬!$B$9=2,MAX(R18,0),MAX(V17,FLOOR(MAX(R18,0),資金模擬!$B$6))) | W18: =MAX(W17,R18) | X18: =IF(W18>0,R18/W18-1,-1) | Y18: =IF(R18>0,S18*資金模擬!$B$7/R18,0) | Z18: =IF(OR(Z17=1,R18<=資金模擬!$B$10),1,0)
A19: 17 | B19: 46267 | C19: 出場 | D19: 8 | E19: HEMI_USDT_PERP | F19: 做多 | G19: 0.0161 | H19: 0.016583 | I19: 0.015295 | J19: 0.016583 | K19: 止盈 | L19: =交易明細!K9 | M19: =M16 | N19: =N16 | O19: =O16 | P19: =交易明細!L9 | Q19: =IF(N19="已下單",O19*P19,0) | R19: =R18+Q19 | S19: =S18-IF(N19="已下單",M19,0) | T19: =R19-S19 | U19: =U18-IF(N19="已下單",1,0) | V19: =IF(資金模擬!$B$9=2,MAX(R19,0),MAX(V18,FLOOR(MAX(R19,0),資金模擬!$B$6))) | W19: =MAX(W18,R19) | X19: =IF(W19>0,R19/W19-1,-1) | Y19: =IF(R19>0,S19*資金模擬!$B$7/R19,0) | Z19: =IF(OR(Z18=1,R19<=資金模擬!$B$10),1,0)
A20: 18 | B20: 46267.083 | C20: 進場 | D20: 10 | E20: HEMI_USDT_PERP | F20: 做空 | G20: 0.01546 | H20: 0.0149962 | I20: 0.016233 | M20: =資金模擬!$B$5*V19 | N20: =IF(Z19=1,"已停止",IF(T19>=M20,"已下單","資金不足略過")) | O20: =IF(N20="已下單",M20*資金模擬!$B$7,0) | Q20: 0 | R20: =R19+Q20 | S20: =S19+IF(N20="已下單",M20,0) | T20: =R20-S20 | U20: =U19+IF(N20="已下單",1,0) | V20: =IF(資金模擬!$B$9=2,MAX(R20,0),MAX(V19,FLOOR(MAX(R20,0),資金模擬!$B$6))) | W20: =MAX(W19,R20) | X20: =IF(W20>0,R20/W20-1,-1) | Y20: =IF(R20>0,S20*資金模擬!$B$7/R20,0) | Z20: =IF(OR(Z19=1,R20<=資金模擬!$B$10),1,0)
A21: 19 | B21: 46267.125 | C21: 出場 | D21: 9 | E21: PUMP_USDT_PERP | F21: 做多 | G21: 0.004467 | H21: 0.00460101 | I21: 0.00424365 | J21: 0.00424365 | K21: 止損 | L21: =交易明細!K10 | M21: =M17 | N21: =N17 | O21: =O17 | P21: =交易明細!L10 | Q21: =IF(N21="已下單",O21*P21,0) | R21: =R20+Q21 | S21: =S20-IF(N21="已下單",M21,0) | T21: =R21-S21 | U21: =U20-IF(N21="已下單",1,0) | V21: =IF(資金模擬!$B$9=2,MAX(R21,0),MAX(V20,FLOOR(MAX(R21,0),資金模擬!$B$6))) | W21: =MAX(W20,R21) | X21: =IF(W21>0,R21/W21-1,-1) | Y21: =IF(R21>0,S21*資金模擬!$B$7/R21,0) | Z21: =IF(OR(Z20=1,R21<=資金模擬!$B$10),1,0)
A22: 20 | B22: 46267.167 | C22: 出場 | D22: 10 | E22: HEMI_USDT_PERP | F22: 做空 | G22: 0.01546 | H22: 0.0149962 | I22: 0.016233 | J22: 0.0149962 | K22: 止盈 | L22: =交易明細!K11 | M22: =M20 | N22: =N20 | O22: =O20 | P22: =交易明細!L11 | Q22: =IF(N22="已下單",O22*P22,0) | R22: =R21+Q22 | S22: =S21-IF(N22="已下單",M22,0) | T22: =R22-S22 | U22: =U21-IF(N22="已下單",1,0) | V22: =IF(資金模擬!$B$9=2,MAX(R22,0),MAX(V21,FLOOR(MAX(R22,0),資金模擬!$B$6))) | W22: =MAX(W21,R22) | X22: =IF(W22>0,R22/W22-1,-1) | Y22: =IF(R22>0,S22*資金模擬!$B$7/R22,0) | Z22: =IF(OR(Z21=1,R22<=資金模擬!$B$10),1,0)
A23: 21 | B23: 46267.417 | C23: 進場 | D23: 11 | E23: PUMP_USDT_PERP | F23: 做空 | G23: 0.004146 | H23: 0.00402162 | I23: 0.0043533 | M23: =資金模擬!$B$5*V22 | N23: =IF(Z22=1,"已停止",IF(T22>=M23,"已下單","資金不足略過")) | O23: =IF(N23="已下單",M23*資金模擬!$B$7,0) | Q23: 0 | R23: =R22+Q23 | S23: =S22+IF(N23="已下單",M23,0) | T23: =R23-S23 | U23: =U22+IF(N23="已下單",1,0) | V23: =IF(資金模擬!$B$9=2,MAX(R23,0),MAX(V22,FLOOR(MAX(R23,0),資金模擬!$B$6))) | W23: =MAX(W22,R23) | X23: =IF(W23>0,R23/W23-1,-1) | Y23: =IF(R23>0,S23*資金模擬!$B$7/R23,0) | Z23: =IF(OR(Z22=1,R23<=資金模擬!$B$10),1,0)
A24: 22 | B24: 46267.417 | C24: 進場 | D24: 12 | E24: 牛来_USDT_PERP | F24: 做空 | G24: 0.08327 | H24: 0.0807719 | I24: 0.0874335 | M24: =資金模擬!$B$5*V23 | N24: =IF(Z23=1,"已停止",IF(T23>=M24,"已下單","資金不足略過")) | O24: =IF(N24="已下單",M24*資金模擬!$B$7,0) | Q24: 0 | R24: =R23+Q24 | S24: =S23+IF(N24="已下單",M24,0) | T24: =R24-S24 | U24: =U23+IF(N24="已下單",1,0) | V24: =IF(資金模擬!$B$9=2,MAX(R24,0),MAX(V23,FLOOR(MAX(R24,0),資金模擬!$B$6))) | W24: =MAX(W23,R24) | X24: =IF(W24>0,R24/W24-1,-1) | Y24: =IF(R24>0,S24*資金模擬!$B$7/R24,0) | Z24: =IF(OR(Z23=1,R24<=資金模擬!$B$10),1,0)
A25: 23 | B25: 46267.458 | C25: 出場 | D25: 12 | E25: 牛来_USDT_PERP | F25: 做空 | G25: 0.08327 | H25: 0.0807719 | I25: 0.0874335 | J25: 0.0807719 | K25: 止盈 | L25: =交易明細!K13 | M25: =M24 | N25: =N24 | O25: =O24 | P25: =交易明細!L13 | Q25: =IF(N25="已下單",O25*P25,0) | R25: =R24+Q25 | S25: =S24-IF(N25="已下單",M25,0) | T25: =R25-S25 | U25: =U24-IF(N25="已下單",1,0) | V25: =IF(資金模擬!$B$9=2,MAX(R25,0),MAX(V24,FLOOR(MAX(R25,0),資金模擬!$B$6))) | W25: =MAX(W24,R25) | X25: =IF(W25>0,R25/W25-1,-1) | Y25: =IF(R25>0,S25*資金模擬!$B$7/R25,0) | Z25: =IF(OR(Z24=1,R25<=資金模擬!$B$10),1,0)
A26: 24 | B26: 46267.458 | C26: 進場 | D26: 13 | E26: UNI_USDT_PERP | F26: 做多 | G26: 6.019 | H26: 6.19957 | I26: 5.71805 | M26: =資金模擬!$B$5*V25 | N26: =IF(Z25=1,"已停止",IF(T25>=M26,"已下單","資金不足略過")) | O26: =IF(N26="已下單",M26*資金模擬!$B$7,0) | Q26: 0 | R26: =R25+Q26 | S26: =S25+IF(N26="已下單",M26,0) | T26: =R26-S26 | U26: =U25+IF(N26="已下單",1,0) | V26: =IF(資金模擬!$B$9=2,MAX(R26,0),MAX(V25,FLOOR(MAX(R26,0),資金模擬!$B$6))) | W26: =MAX(W25,R26) | X26: =IF(W26>0,R26/W26-1,-1) | Y26: =IF(R26>0,S26*資金模擬!$B$7/R26,0) | Z26: =IF(OR(Z25=1,R26<=資金模擬!$B$10),1,0)
A27: 25 | B27: 46267.5 | C27: 進場 | D27: 14 | E27: CRV_USDT_PERP | F27: 做多 | G27: 0.3838 | H27: 0.395314 | I27: 0.36461 | M27: =資金模擬!$B$5*V26 | N27: =IF(Z26=1,"已停止",IF(T26>=M27,"已下單","資金不足略過")) | O27: =IF(N27="已下單",M27*資金模擬!$B$7,0) | Q27: 0 | R27: =R26+Q27 | S27: =S26+IF(N27="已下單",M27,0) | T27: =R27-S27 | U27: =U26+IF(N27="已下單",1,0) | V27: =IF(資金模擬!$B$9=2,MAX(R27,0),MAX(V26,FLOOR(MAX(R27,0),資金模擬!$B$6))) | W27: =MAX(W26,R27) | X27: =IF(W27>0,R27/W27-1,-1) | Y27: =IF(R27>0,S27*資金模擬!$B$7/R27,0) | Z27: =IF(OR(Z26=1,R27<=資金模擬!$B$10),1,0)
A28: 26 | B28: 46267.5 | C28: 進場 | D28: 15 | E28: SKR_USDT_PERP | F28: 做空 | G28: 0.022381 | H28: 0.02170957 | I28: 0.02350005 | M28: =資金模擬!$B$5*V27 | N28: =IF(Z27=1,"已停止",IF(T27>=M28,"已下單","資金不足略過")) | O28: =IF(N28="已下單",M28*資金模擬!$B$7,0) | Q28: 0 | R28: =R27+Q28 | S28: =S27+IF(N28="已下單",M28,0) | T28: =R28-S28 | U28: =U27+IF(N28="已下單",1,0) | V28: =IF(資金模擬!$B$9=2,MAX(R28,0),MAX(V27,FLOOR(MAX(R28,0),資金模擬!$B$6))) | W28: =MAX(W27,R28) | X28: =IF(W28>0,R28/W28-1,-1) | Y28: =IF(R28>0,S28*資金模擬!$B$7/R28,0) | Z28: =IF(OR(Z27=1,R28<=資金模擬!$B$10),1,0)
A29: 27 | B29: 46267.542 | C29: 出場 | D29: 13 | E29: UNI_USDT_PERP | F29: 做多 | G29: 6.019 | H29: 6.19957 | I29: 5.71805 | J29: 6.19957 | K29: 止盈 | L29: =交易明細!K14 | M29: =M26 | N29: =N26 | O29: =O26 | P29: =交易明細!L14 | Q29: =IF(N29="已下單",O29*P29,0) | R29: =R28+Q29 | S29: =S28-IF(N29="已下單",M29,0) | T29: =R29-S29 | U29: =U28-IF(N29="已下單",1,0) | V29: =IF(資金模擬!$B$9=2,MAX(R29,0),MAX(V28,FLOOR(MAX(R29,0),資金模擬!$B$6))) | W29: =MAX(W28,R29) | X29: =IF(W29>0,R29/W29-1,-1) | Y29: =IF(R29>0,S29*資金模擬!$B$7/R29,0) | Z29: =IF(OR(Z28=1,R29<=資金模擬!$B$10),1,0)
A30: 28 | B30: 46267.542 | C30: 進場 | D30: 16 | E30: 牛来_USDT_PERP | F30: 做多 | G30: 0.08776 | H30: 0.0903928 | I30: 0.083372 | M30: =資金模擬!$B$5*V29 | N30: =IF(Z29=1,"已停止",IF(T29>=M30,"已下單","資金不足略過")) | O30: =IF(N30="已下單",M30*資金模擬!$B$7,0) | Q30: 0 | R30: =R29+Q30 | S30: =S29+IF(N30="已下單",M30,0) | T30: =R30-S30 | U30: =U29+IF(N30="已下單",1,0) | V30: =IF(資金模擬!$B$9=2,MAX(R30,0),MAX(V29,FLOOR(MAX(R30,0),資金模擬!$B$6))) | W30: =MAX(W29,R30) | X30: =IF(W30>0,R30/W30-1,-1) | Y30: =IF(R30>0,S30*資金模擬!$B$7/R30,0) | Z30: =IF(OR(Z29=1,R30<=資金模擬!$B$10),1,0)
A31: 29 | B31: 46267.583 | C31: 出場 | D31: 15 | E31: SKR_USDT_PERP | F31: 做空 | G31: 0.022381 | H31: 0.02170957 | I31: 0.02350005 | J31: 0.02350005 | K31: 止損 | L31: =交易明細!K16 | M31: =M28 | N31: =N28 | O31: =O28 | P31: =交易明細!L16 | Q31: =IF(N31="已下單",O31*P31,0) | R31: =R30+Q31 | S31: =S30-IF(N31="已下單",M31,0) | T31: =R31-S31 | U31: =U30-IF(N31="已下單",1,0) | V31: =IF(資金模擬!$B$9=2,MAX(R31,0),MAX(V30,FLOOR(MAX(R31,0),資金模擬!$B$6))) | W31: =MAX(W30,R31) | X31: =IF(W31>0,R31/W31-1,-1) | Y31: =IF(R31>0,S31*資金模擬!$B$7/R31,0) | Z31: =IF(OR(Z30=1,R31<=資金模擬!$B$10),1,0)
A32: 30 | B32: 46267.583 | C32: 出場 | D32: 16 | E32: 牛来_USDT_PERP | F32: 做多 | G32: 0.08776 | H32: 0.0903928 | I32: 0.083372 | J32: 0.0903928 | K32: 止盈 | L32: =交易明細!K17 | M32: =M30 | N32: =N30 | O32: =O30 | P32: =交易明細!L17 | Q32: =IF(N32="已下單",O32*P32,0) | R32: =R31+Q32 | S32: =S31-IF(N32="已下單",M32,0) | T32: =R32-S32 | U32: =U31-IF(N32="已下單",1,0) | V32: =IF(資金模擬!$B$9=2,MAX(R32,0),MAX(V31,FLOOR(MAX(R32,0),資金模擬!$B$6))) | W32: =MAX(W31,R32) | X32: =IF(W32>0,R32/W32-1,-1) | Y32: =IF(R32>0,S32*資金模擬!$B$7/R32,0) | Z32: =IF(OR(Z31=1,R32<=資金模擬!$B$10),1,0)
A33: 31 | B33: 46267.583 | C33: 進場 | D33: 17 | E33: PONS_USDT_PERP | F33: 做多 | G33: 0.4351 | H33: 0.448153 | I33: 0.413345 | M33: =資金模擬!$B$5*V32 | N33: =IF(Z32=1,"已停止",IF(T32>=M33,"已下單","資金不足略過")) | O33: =IF(N33="已下單",M33*資金模擬!$B$7,0) | Q33: 0 | R33: =R32+Q33 | S33: =S32+IF(N33="已下單",M33,0) | T33: =R33-S33 | U33: =U32+IF(N33="已下單",1,0) | V33: =IF(資金模擬!$B$9=2,MAX(R33,0),MAX(V32,FLOOR(MAX(R33,0),資金模擬!$B$6))) | W33: =MAX(W32,R33) | X33: =IF(W33>0,R33/W33-1,-1) | Y33: =IF(R33>0,S33*資金模擬!$B$7/R33,0) | Z33: =IF(OR(Z32=1,R33<=資金模擬!$B$10),1,0)
A34: 32 | B34: 46267.625 | C34: 進場 | D34: 18 | E34: HEMI_USDT_PERP | F34: 做空 | G34: 0.01439 | H34: 0.0139583 | I34: 0.0151095 | M34: =資金模擬!$B$5*V33 | N34: =IF(Z33=1,"已停止",IF(T33>=M34,"已下單","資金不足略過")) | O34: =IF(N34="已下單",M34*資金模擬!$B$7,0) | Q34: 0 | R34: =R33+Q34 | S34: =S33+IF(N34="已下單",M34,0) | T34: =R34-S34 | U34: =U33+IF(N34="已下單",1,0) | V34: =IF(資金模擬!$B$9=2,MAX(R34,0),MAX(V33,FLOOR(MAX(R34,0),資金模擬!$B$6))) | W34: =MAX(W33,R34) | X34: =IF(W34>0,R34/W34-1,-1) | Y34: =IF(R34>0,S34*資金模擬!$B$7/R34,0) | Z34: =IF(OR(Z33=1,R34<=資金模擬!$B$10),1,0)
A35: 33 | B35: 46267.625 | C35: 進場 | D35: 19 | E35: SKR_USDT_PERP | F35: 做空 | G35: 0.02203 | H35: 0.0213691 | I35: 0.0231315 | M35: =資金模擬!$B$5*V34 | N35: =IF(Z34=1,"已停止",IF(T34>=M35,"已下單","資金不足略過")) | O35: =IF(N35="已下單",M35*資金模擬!$B$7,0) | Q35: 0 | R35: =R34+Q35 | S35: =S34+IF(N35="已下單",M35,0) | T35: =R35-S35 | U35: =U34+IF(N35="已下單",1,0) | V35: =IF(資金模擬!$B$9=2,MAX(R35,0),MAX(V34,FLOOR(MAX(R35,0),資金模擬!$B$6))) | W35: =MAX(W34,R35) | X35: =IF(W35>0,R35/W35-1,-1) | Y35: =IF(R35>0,S35*資金模擬!$B$7/R35,0) | Z35: =IF(OR(Z34=1,R35<=資金模擬!$B$10),1,0)
A36: 34 | B36: 46267.667 | C36: 出場 | D36: 17 | E36: PONS_USDT_PERP | F36: 做多 | G36: 0.4351 | H36: 0.448153 | I36: 0.413345 | J36: 0.413345 | K36: 止損 | L36: =交易明細!K18 | M36: =M33 | N36: =N33 | O36: =O33 | P36: =交易明細!L18 | Q36: =IF(N36="已下單",O36*P36,0) | R36: =R35+Q36 | S36: =S35-IF(N36="已下單",M36,0) | T36: =R36-S36 | U36: =U35-IF(N36="已下單",1,0) | V36: =IF(資金模擬!$B$9=2,MAX(R36,0),MAX(V35,FLOOR(MAX(R36,0),資金模擬!$B$6))) | W36: =MAX(W35,R36) | X36: =IF(W36>0,R36/W36-1,-1) | Y36: =IF(R36>0,S36*資金模擬!$B$7/R36,0) | Z36: =IF(OR(Z35=1,R36<=資金模擬!$B$10),1,0)
A37: 35 | B37: 46267.667 | C37: 出場 | D37: 18 | E37: HEMI_USDT_PERP | F37: 做空 | G37: 0.01439 | H37: 0.0139583 | I37: 0.0151095 | J37: 0.0151095 | K37: 止損 | L37: =交易明細!K19 | M37: =M34 | N37: =N34 | O37: =O34 | P37: =交易明細!L19 | Q37: =IF(N37="已下單",O37*P37,0) | R37: =R36+Q37 | S37: =S36-IF(N37="已下單",M37,0) | T37: =R37-S37 | U37: =U36-IF(N37="已下單",1,0) | V37: =IF(資金模擬!$B$9=2,MAX(R37,0),MAX(V36,FLOOR(MAX(R37,0),資金模擬!$B$6))) | W37: =MAX(W36,R37) | X37: =IF(W37>0,R37/W37-1,-1) | Y37: =IF(R37>0,S37*資金模擬!$B$7/R37,0) | Z37: =IF(OR(Z36=1,R37<=資金模擬!$B$10),1,0)
A38: 36 | B38: 46267.667 | C38: 出場 | D38: 19 | E38: SKR_USDT_PERP | F38: 做空 | G38: 0.02203 | H38: 0.0213691 | I38: 0.0231315 | J38: 0.0213691 | K38: 止盈 | L38: =交易明細!K20 | M38: =M35 | N38: =N35 | O38: =O35 | P38: =交易明細!L20 | Q38: =IF(N38="已下單",O38*P38,0) | R38: =R37+Q38 | S38: =S37-IF(N38="已下單",M38,0) | T38: =R38-S38 | U38: =U37-IF(N38="已下單",1,0) | V38: =IF(資金模擬!$B$9=2,MAX(R38,0),MAX(V37,FLOOR(MAX(R38,0),資金模擬!$B$6))) | W38: =MAX(W37,R38) | X38: =IF(W38>0,R38/W38-1,-1) | Y38: =IF(R38>0,S38*資金模擬!$B$7/R38,0) | Z38: =IF(OR(Z37=1,R38<=資金模擬!$B$10),1,0)
A39: 37 | B39: 46267.75 | C39: 進場 | D39: 20 | E39: USELESS_USDT_PERP | F39: 做空 | G39: 0.10669 | H39: 0.1034893 | I39: 0.1120245 | M39: =資金模擬!$B$5*V38 | N39: =IF(Z38=1,"已停止",IF(T38>=M39,"已下單","資金不足略過")) | O39: =IF(N39="已下單",M39*資金模擬!$B$7,0) | Q39: 0 | R39: =R38+Q39 | S39: =S38+IF(N39="已下單",M39,0) | T39: =R39-S39 | U39: =U38+IF(N39="已下單",1,0) | V39: =IF(資金模擬!$B$9=2,MAX(R39,0),MAX(V38,FLOOR(MAX(R39,0),資金模擬!$B$6))) | W39: =MAX(W38,R39) | X39: =IF(W39>0,R39/W39-1,-1) | Y39: =IF(R39>0,S39*資金模擬!$B$7/R39,0) | Z39: =IF(OR(Z38=1,R39<=資金模擬!$B$10),1,0)
A40: 38 | B40: 46267.792 | C40: 出場 | D40: 14 | E40: CRV_USDT_PERP | F40: 做多 | G40: 0.3838 | H40: 0.395314 | I40: 0.36461 | J40: 0.36461 | K40: 止損 | L40: =交易明細!K15 | M40: =M27 | N40: =N27 | O40: =O27 | P40: =交易明細!L15 | Q40: =IF(N40="已下單",O40*P40,0) | R40: =R39+Q40 | S40: =S39-IF(N40="已下單",M40,0) | T40: =R40-S40 | U40: =U39-IF(N40="已下單",1,0) | V40: =IF(資金模擬!$B$9=2,MAX(R40,0),MAX(V39,FLOOR(MAX(R40,0),資金模擬!$B$6))) | W40: =MAX(W39,R40) | X40: =IF(W40>0,R40/W40-1,-1) | Y40: =IF(R40>0,S40*資金模擬!$B$7/R40,0) | Z40: =IF(OR(Z39=1,R40<=資金模擬!$B$10),1,0)
...

Sheet 參數
A1: 項目 | B1: 數值 | C1: 說明
A2: 市場 | B2: PERP | C2: PERP=永續合約 / SPOT=現貨
A3: 回測區間 | B3: 2026-09-01 00:00 ~ 2026-09-27 06:56（Dry Run） | C3: 台北時間
A4: K棒週期 | B4: 60 分鐘 | C4: 訊號於K棒收盤判斷、以收盤價進場
A5: 止盈 | B5: 0.03 | C5: 同方向
A6: 止損 | B6: 0.05 | C6: 反方向
A7: 單邊手續費 | B7: 0.0005 | C7: 進場、出場各扣一次（可直接改此格，報酬率會重算）
A8: 流動性門檻 (USDT) | B8: 50000 | C8: 近24h平均每小時成交額
A9: 動能門檻 | B9: 0.02 | C9: 收盤 vs 前一根收盤
A10: ATR 門檻 | B10: 0.02 | C10: ATR(14) ÷ 收盤
A11: 均線 | B11: MA20 | C11: 做多站上 / 做空跌破
A12: OBV 比較 | B12: 20 根前 | C12: 做多 OBV 上升 / 做空 OBV 下降
A13: 價格上限 | B13: 不限 | C13: 訊號當下收盤價須低於此值
A14: 時間停損 | B14: 無 | C14: 小時
A15: 同K棒雙觸發 | B15: 5M/15M/30M 依序判斷
A16: 盈虧平衡勝率 | B16: =IFERROR(AVERAGE(交易明細!$AC$2:$AC$509),(B6+2*B7)/(B5+B6)) | C16: 含手續費，各筆平均；勝率低於此值 = 長期虧損
A17: MA20乖離上限 | B17: 0.06 | C17: 超過不進場
A18: 1h漲跌幅上限 | B18: 0.1 | C18: 超過不進場
A19: 出場後冷卻 | B19: 1 | C19: K棒數
A20: 量比下限 | B20: 0.35 | C20: 訊號K量 ÷ 前20根均量
A21: 收盤強度下限 | B21: 不限 | C21: 1=收在順勢端極值
A22: 長週期趨勢過濾 | B22: 關閉 | C22: 1h K棒
A23: BTC 趨勢過濾 | B23: 關閉 | C23: BTC 收盤 vs 自身 MA20
A24: 24h盤整排除 | B24: 關閉 | C24: |24h漲跌| 低於此值不進場
A25: BTC同向乖離上限 | B25: 關閉 | C25: BTC 已同向偏離MA20超過此值不進場

Sheet 交易明細
A1: 編號 | B1: 交易對 | C1: 方向 | D1: 進場時間 | E1: 進場價 | F1: 止盈價 | G1: 止損價 | H1: 出場時間 | I1: 出場價 | J1: 結果 | K1: 持倉小時 | L1: 報酬率(含費) | M1: 判定說明 | N1: 前一根漲跌幅 | O1: ATR% | P1: 價格vsMA20 | Q1: OBV 20h變化 | R1: 24h成交額(USDT) | S1: 最大有利(MFE) | T1: 最大不利(MAE) | U1: 量比 | V1: 收盤強度 | W1: 長週期趨勢(順勢) | X1: 24h漲跌(順勢) | Y1: BTC 1h漲跌(順勢) | Z1: BTC vs MA20(順勢) | AA1: 止盈% | AB1: 止損% | AC1: 盈虧平衡勝率
A2: 1 | B2: HEMI_USDT_PERP | C2: 做多 | D2: 46266.042 | E2: 0.01515 | F2: 0.0156045 | G2: 0.0143925 | H2: 46266.083 | I2: 0.0156045 | J2: 止盈 | K2: =(H2-D2)*24 | L2: =IF(C2="做多",I2/E2-1,1-I2/E2)-2*參數!$B$7 | N2: 0.026422764 | O2: 0.054701059 | P2: 0.0068786761 | Q2: 30338196 | R2: 2527661.3 | S2: 0.03 | T2: 0 | U2: 1.4956062 | V2: 0.77586207 | W2: 0.26055664 | X2: 0.30042918 | Y2: 0.00078555596 | Z2: 0.0061873543 | AA2: 0.03 | AB2: 0.05 | AC2: =(AB2+2*參數!$B$7)/(AA2+AB2)
A3: 2 | B3: SKYAI_USDT_PERP | C3: 做空 | D3: 46266.042 | E3: 0.0548 | F3: 0.053156 | G3: 0.05754 | H3: 46266.333 | I3: 0.053156 | J3: 止盈 | K3: =(H3-D3)*24 | L3: =IF(C3="做多",I3/E3-1,1-I3/E3)-2*參數!$B$7 | N3: -0.021078957 | O3: 0.030368463 | P3: -0.0039894946 | Q3: -39041574 | R3: 3589003.9 | S3: 0.03 | T3: 0.023175182 | U3: 1.3689735 | V3: 0.62051282 | W3: -0.0030016839 | X3: -0.014626921 | Y3: -0.00078555596 | Z3: -0.0061873543 | AA3: 0.03 | AB3: 0.05 | AC3: =(AB3+2*參數!$B$7)/(AA3+AB3)
A4: 3 | B4: XMR_USDT_PERP | C4: 做多 | D4: 46266.125 | E4: 531.58 | F4: 547.5274 | G4: 505.001 | H4: 46267 | I4: 505.001 | J4: 止損 | K4: =(H4-D4)*24 | L4: =IF(C4="做多",I4/E4-1,1-I4/E4)-2*參數!$B$7 | N4: 0.031733401 | O4: 0.026396856 | P4: 0.030923037 | Q4: 1601.156 | R4: 2853090.7 | S4: 0.0025395989 | T4: 0.05 | U4: 1.1283006 | V4: 0.72727273 | W4: 0.10420645 | X4: 0.079109234 | Y4: 0.00146326 | Z4: 0.01045731 | AA4: 0.03 | AB4: 0.05 | AC4: =(AB4+2*參數!$B$7)/(AA4+AB4)
A5: 4 | B5: SKR_USDT_PERP | C5: 做多 | D5: 46266.25 | E5: 0.028369 | F5: 0.02922007 | G5: 0.02695055 | H5: 46266.292 | I5: 0.02922007 | J5: 止盈 | K5: =(H5-D5)*24 | L5: =IF(C5="做多",I5/E5-1,1-I5/E5)-2*參數!$B$7 | N5: 0.040453312 | O5: 0.097786744 | P5: 0.035117518 | Q5: 9164683 | R5: 8694027.9 | S5: 0.03 | T5: 0 | U5: 0.45094238 | V5: 0.55498362 | W5: 0.84713131 | X5: 0.24365438 | Y5: 0.0011999807 | Z5: 0.007557331 | AA5: 0.03 | AB5: 0.05 | AC5: =(AB5+2*參數!$B$7)/(AA5+AB5)
A6: 5 | B6: PUMP_USDT_PERP | C6: 做多 | D6: 46266.375 | E6: 0.004605 | F6: 0.00474315 | G6: 0.00437475 | H6: 46266.75 | I6: 0.00437475 | J6: 止損 | K6: =(H6-D6)*24 | L6: =IF(C6="做多",I6/E6-1,1-I6/E6)-2*參數!$B$7 | N6: 0.034831461 | O6: 0.02096548 | P6: 0.053655188 | Q6: 1426177257 | R6: 14089273 | S6: 0.007383279 | T6: 0.05 | U6: 1.9170565 | V6: 0.6437247 | W6: -0.01163502 | X6: 0.026298195 | Y6: 0.00086951429 | Z6: 0.001681065 | AA6: 0.03 | AB6: 0.05 | AC6: =(AB6+2*參數!$B$7)/(AA6+AB6)
A7: 6 | B7: ARB_USDT_PERP | C7: 做多 | D7: 46266.75 | E7: 0.1099 | F7: 0.113197 | G7: 0.104405 | H7: 46266.792 | I7: 0.113197 | J7: 止盈 | K7: =(H7-D7)*24 | L7: =IF(C7="做多",I7/E7-1,1-I7/E7)-2*參數!$B$7 | N7: 0.029026217 | O7: 0.033632461 | P7: 0.05227882 | Q7: 2948217.4 | R7: 1581318.7 | S7: 0.03 | T7: 0 | U7: 4.1841235 | V7: 0.85714286 | W7: 0.20810386 | X7: 0.27052023 | Y7: 0.00032498353 | Z7: -0.0093626988 | AA7: 0.03 | AB7: 0.05 | AC7: =(AB7+2*參數!$B$7)/(AA7+AB7)
A8: 7 | B8: USELESS_USDT_PERP | C8: 做多 | D8: 46266.75 | E8: 0.09113 | F8: 0.0938639 | G8: 0.0865735 | H8: 46266.792 | I8: 0.0938639 | J8: 止盈 | K8: =(H8-D8)*24 | L8: =IF(C8="做多",I8/E8-1,1-I8/E8)-2*參數!$B$7 | N8: 0.031349027 | O8: 0.041740657 | P8: 0.016939696 | Q8: 4835282 | R8: 3907392.9 | S8: 0.03 | T8: 0 | U8: 0.835276 | V8: 0.69976359 | W8: 0.32083375 | X8: 0.31652702 | Y8: 0.00032498353 | Z8: -0.0093626988 | AA8: 0.03 | AB8: 0.05 | AC8: =(AB8+2*參數!$B$7)/(AA8+AB8)
A9: 8 | B9: HEMI_USDT_PERP | C9: 做多 | D9: 46266.833 | E9: 0.0161 | F9: 0.016583 | G9: 0.015295 | H9: 46267 | I9: 0.016583 | J9: 止盈 | K9: =(H9-D9)*24 | L9: =IF(C9="做多",I9/E9-1,1-I9/E9)-2*參數!$B$7 | N9: 0.04005168 | O9: 0.053090481 | P9: 0.031852849 | Q9: 21786432 | R9: 2485334.3 | S9: 0.03 | T9: 0.032298137 | U9: 0.4854555 | V9: 0.59375 | W9: 0.23064223 | X9: 0.079812207 | Y9: 0.00087577576 | Z9: -0.0064017947 | AA9: 0.03 | AB9: 0.05 | AC9: =(AB9+2*參數!$B$7)/(AA9+AB9)
A10: 9 | B10: PUMP_USDT_PERP | C10: 做多 | D10: 46266.917 | E10: 0.004467 | F10: 0.00460101 | G10: 0.00424365 | H10: 46267.125 | I10: 0.00424365 | J10: 止損 | K10: =(H10-D10)*24 | L10: =IF(C10="做多",I10/E10-1,1-I10/E10)-2*參數!$B$7 | N10: 0.021495541 | O10: 0.020167129 | P10: 0.0016481114 | Q10: 275449570 | R10: 7439037.9 | S10: 0.0085068278 | T10: 0.05 | U10: 1.6434696 | V10: 0.8590604 | W10: -0.033451618 | X10: 0.048591549 | Y10: 0.00099921756 | Z10: -0.0056930735 | AA10: 0.03 | AB10: 0.05 | AC10: =(AB10+2*參數!$B$7)/(AA10+AB10)
A11: 10 | B11: HEMI_USDT_PERP | C11: 做空 | D11: 46267.083 | E11: 0.01546 | F11: 0.0149962 | G11: 0.016233 | H11: 46267.167 | I11: 0.0149962 | J11: 止盈 | K11: =(H11-D11)*24 | L11: =IF(C11="做多",I11/E11-1,1-I11/E11)-2*參數!$B$7 | N11: -0.046267736 | O11: 0.052110955 | P11: -0.0081159978 | Q11: -8331572 | R11: 1791699.9 | S11: 0.03 | T11: 0.022639069 | U11: 1.1712797 | V11: 0.98717949 | W11: -0.15883367 | X11: 0 | Y11: 0.0041207126 | Z11: 0.012855785 | AA11: 0.03 | AB11: 0.05 | AC11: =(AB11+2*參數!$B$7)/(AA11+AB11)
A12: 11 | B12: PUMP_USDT_PERP | C12: 做空 | D12: 46267.417 | E12: 0.004146 | F12: 0.00402162 | G12: 0.0043533 | H12: 46268.292 | I12: 0.00402162 | J12: 止盈 | K12: =(H12-D12)*24 | L12: =IF(C12="做多",I12/E12-1,1-I12/E12)-2*參數!$B$7 | N12: -0.042494226 | O12: 0.021872146 | P12: -0.053013864 | Q12: -426829056 | R12: 6398366.6 | S12: 0.03 | T12: 0.048962856 | U12: 11.390173 | V12: 0.98029557 | W12: 0.094619472 | X12: 0.085978836 | Y12: 0.0025460129 | Z12: 0.0090311359 | AA12: 0.03 | AB12: 0.05 | AC12: =(AB12+2*參數!$B$7)/(AA12+AB12)
A13: 12 | B13: 牛来_USDT_PERP | C13: 做空 | D13: 46267.417 | E13: 0.08327 | F13: 0.0807719 | G13: 0.0874335 | H13: 46267.458 | I13: 0.0807719 | J13: 止盈 | K13: =(H13-D13)*24 | L13: =IF(C13="做多",I13/E13-1,1-I13/E13)-2*參數!$B$7 | N13: -0.03387864 | O13: 0.077267799 | P13: -0.036617111 | Q13: -1142275 | R13: 1439472.3 | S13: 0.03 | T13: 0 | U13: 1.1270569 | V13: 0.85825893 | X13: 0.22997966 | Y13: 0.0025460129 | Z13: 0.0090311359 | AA13: 0.03 | AB13: 0.05 | AC13: =(AB13+2*參數!$B$7)/(AA13+AB13)
A14: 13 | B14: UNI_USDT_PERP | C14: 做多 | D14: 46267.458 | E14: 6.019 | F14: 6.19957 | G14: 5.71805 | H14: 46267.542 | I14: 6.19957 | J14: 止盈 | K14: =(H14-D14)*24 | L14: =IF(C14="做多",I14/E14-1,1-I14/E14)-2*參數!$B$7 | N14: 0.029592884 | O14: 0.021715373 | P14: 0.043905062 | Q14: 57862 | R14: 5340979.2 | S14: 0.03 | T14: 0.0093038711 | U14: 1.1662125 | V14: 0.912 | W14: 0.17884388 | X14: 0.15306513 | Y14: 0.0041164933 | Z14: -0.0040505433 | AA14: 0.03 | AB14: 0.05 | AC14: =(AB14+2*參數!$B$7)/(AA14+AB14)
A15: 14 | B15: CRV_USDT_PERP | C15: 做多 | D15: 46267.5 | E15: 0.3838 | F15: 0.395314 | G15: 0.36461 | H15: 46267.792 | I15: 0.36461 | J15: 止損 | K15: =(H15-D15)*24 | L15: =IF(C15="做多",I15/E15-1,1-I15/E15)-2*參數!$B$7 | N15: 0.021831736 | O15: 0.02279439 | P15: 0.047975316 | Q15: 830427.7 | R15: 1422562.1 | S15: 0.0039082856 | T15: 0.05 | U15: 1.2602945 | V15: 0.47340426 | W15: 0.19243281 | X15: 0.072366583 | Y15: 0.0030323454 | Z15: -0.00034405185 | AA15: 0.03 | AB15: 0.05 | AC15: =(AB15+2*參數!$B$7)/(AA15+AB15)
A16: 15 | B16: SKR_USDT_PERP | C16: 做空 | D16: 46267.5 | E16: 0.022381 | F16: 0.02170957 | G16: 0.02350005 | H16: 46267.583 | I16: 0.02350005 | J16: 止損 | K16: =(H16-D16)*24 | L16: =IF(C16="做多",I16/E16-1,1-I16/E16)-2*參數!$B$7 | N16: -0.047981624 | O16: 0.092341133 | P16: -0.046590585 | Q16: -49097315 | R16: 3136147.3 | S16: 0.023368035 | T16: 0.05 | U16: 2.0643051 | V16: 0.91827503 | W16: -0.12104546 | X16: 0.23718473 | Y16: -0.0030323454 | Z16: 0.00034405185 | AA16: 0.03 | AB16: 0.05 | AC16: =(AB16+2*參數!$B$7)/(AA16+AB16)
A17: 16 | B17: 牛来_USDT_PERP | C17: 做多 | D17: 46267.542 | E17: 0.08776 | F17: 0.0903928 | G17: 0.083372 | H17: 46267.583 | I17: 0.0903928 | J17: 止盈 | K17: =(H17-D17)*24 | L17: =IF(C17="做多",I17/E17-1,1-I17/E17)-2*參數!$B$7 | N17: 0.037965701 | O17: 0.07196519 | P17: 0.031172524 | Q17: 683387 | R17: 1408907.4 | S17: 0.03 | T17: 0 | U17: 0.7479348 | V17: 0.71016484 | X17: -0.13434602 | Y17: -0.0001070494 | Z17: -0.00024218265 | AA17: 0.03 | AB17: 0.05 | AC17: =(AB17+2*參數!$B$7)/(AA17+AB17)
A18: 17 | B18: PONS_USDT_PERP | C18: 做多 | D18: 46267.583 | E18: 0.4351 | F18: 0.448153 | G18: 0.413345 | H18: 46267.667 | I18: 0.413345 | J18: 止損 | K18: =(H18-D18)*24 | L18: =IF(C18="做多",I18/E18-1,1-I18/E18)-2*參數!$B$7 | N18: 0.02184124 | O18: 0.053547315 | P18: 0.028325633 | Q18: 816855 | R18: 1808502.9 | S18: 0 | T18: 0.05 | U18: 1.0906979 | V18: 0.6125 | Y18: 0.0011931481 | Z18: 0.0011165077 | AA18: 0.03 | AB18: 0.05 | AC18: =(AB18+2*參數!$B$7)/(AA18+AB18)
A19: 18 | B19: HEMI_USDT_PERP | C19: 做空 | D19: 46267.625 | E19: 0.01439 | F19: 0.0139583 | G19: 0.0151095 | H19: 46267.667 | I19: 0.0151095 | J19: 止損 | K19: =(H19-D19)*24 | L19: =IF(C19="做多",I19/E19-1,1-I19/E19)-2*參數!$B$7 | N19: -0.038744155 | O19: 0.12207165 | P19: -0.059876523 | Q19: -1169435 | R19: 1908493.6 | S19: 0 | T19: 0.05 | U19: 1.1861288 | V19: 0.75 | W19: -0.046956623 | X19: 0.068608414 | Y19: 0.00052049447 | Z19: -0.00086000208 | AA19: 0.03 | AB19: 0.05 | AC19: =(AB19+2*參數!$B$7)/(AA19+AB19)
A20: 19 | B20: SKR_USDT_PERP | C20: 做空 | D20: 46267.625 | E20: 0.02203 | F20: 0.0213691 | G20: 0.0231315 | H20: 46267.667 | I20: 0.0213691 | J20: 止盈 | K20: =(H20-D20)*24 | L20: =IF(C20="做多",I20/E20-1,1-I20/E20)-2*參數!$B$7 | N20: -0.060233768 | O20: 0.092695408 | P20: -0.040329677 | Q20: -15164838 | R20: 3097417.3 | S20: 0.03 | T20: 0 | U20: 1.2097253 | V20: 0.78487395 | W20: -0.081721799 | X20: 0.22644756 | Y20: 0.00052049447 | Z20: -0.00086000208 | AA20: 0.03 | AB20: 0.05 | AC20: =(AB20+2*參數!$B$7)/(AA20+AB20)
A21: 20 | B21: USELESS_USDT_PERP | C21: 做空 | D21: 46267.75 | E21: 0.10669 | F21: 0.1034893 | G21: 0.1120245 | H21: 46267.792 | I21: 0.1034893 | J21: 止盈 | K21: =(H21-D21)*24 | L21: =IF(C21="做多",I21/E21-1,1-I21/E21)-2*參數!$B$7 | N21: -0.048175573 | O21: 0.052449911 | P21: -0.03261929 | Q21: -5434054 | R21: 7681110.4 | S21: 0.03 | T21: 0 | U21: 0.96701401 | V21: 0.92624113 | W21: -0.32903816 | X21: -0.17074509 | Y21: 0.0013395019 | Z21: 0.008286054 | AA21: 0.03 | AB21: 0.05 | AC21: =(AB21+2*參數!$B$7)/(AA21+AB21)
A22: 21 | B22: UAI_USDT_PERP | C22: 做空 | D22: 46267.792 | E22: 0.5241 | F22: 0.508377 | G22: 0.550305 | H22: 46267.875 | I22: 0.550305 | J22: 止損 | K22: =(H22-D22)*24 | L22: =IF(C22="做多",I22/E22-1,1-I22/E22)-2*參數!$B$7 | N22: -0.04378763 | O22: 0.058423082 | P22: -0.021297654 | Q22: -795267 | R22: 4210824.8 | S22: 0.029765312 | T22: 0.05 | U22: 2.6197575 | V22: 0.80979827 | W22: -0.33525261 | X22: -0.23871425 | Y22: 0.0010102103 | Z22: 0.0083281764 | AA22: 0.03 | AB22: 0.05 | AC22: =(AB22+2*參數!$B$7)/(AA22+AB22)
A23: 22 | B23: ACE_USDT_PERP | C23: 做空 | D23: 46267.833 | E23: 0.19257 | F23: 0.1867929 | G23: 0.2021985 | H23: 46267.875 | I23: 0.1867929 | J23: 止盈 | K23: =(H23-D23)*24 | L23: =IF(C23="做多",I23/E23-1,1-I23/E23)-2*參數!$B$7 | N23: -0.050256461 | O23: 0.049316066 | P23: -0.051907067 | Q23: -1654553.7 | R23: 2513068 | S23: 0.03 | T23: 0 | U23: 1.5816156 | V23: 0.6308204 | W23: -0.04647144 | X23: -0.084412659 | Y23: -0.0019480892 | Z23: 0.0056958336 | AA23: 0.03 | AB23: 0.05 | AC23: =(AB23+2*參數!$B$7)/(AA23+AB23)
A24: 23 | B24: ARB_USDT_PERP | C24: 做空 | D24: 46267.833 | E24: 0.1076 | F24: 0.104372 | G24: 0.11298 | H24: 46267.958 | I24: 0.11298 | J24: 止損 | K24: =(H24-D24)*24 | L24: =IF(C24="做多",I24/E24-1,1-I24/E24)-2*參數!$B$7 | N24: -0.028880866 | O24: 0.031700992 | P24: -0.026904816 | Q24: -782584.1 | R24: 1241321.9 | S24: 0.0037174721 | T24: 0.05 | U24: 2.3873938 | V24: 0.67307692 | W24: -0.11265071 | X24: 0.050308914 | Y24: -0.0019480892 | Z24: 0.0056958336 | AA24: 0.03 | AB24: 0.05 | AC24: =(AB24+2*參數!$B$7)/(AA24+AB24)
A25: 24 | B25: UNI_USDT_PERP | C25: 做空 | D25: 46267.833 | E25: 5.744 | F25: 5.57168 | G25: 6.0312 | H25: 46268.75 | I25: 6.0312 | J25: 止損 | K25: =(H25-D25)*24 | L25: =IF(C25="做多",I25/E25-1,1-I25/E25)-2*參數!$B$7 | N25: -0.049478736 | O25: 0.028802558 | P25: -0.033086162 | Q25: -61964 | R25: 5926643.3 | S25: 0.018802228 | T25: 0.05 | U25: 1.3004845 | V25: 0.87749288 | W25: -0.091888583 | X25: 0.02578019 | Y25: -0.0019480892 | Z25: 0.0056958336 | AA25: 0.03 | AB25: 0.05 | AC25: =(AB25+2*參數!$B$7)/(AA25+AB25)
A26: 25 | B26: PONS_USDT_PERP | C26: 做多 | D26: 46267.917 | E26: 0.415 | F26: 0.42745 | G26: 0.39425 | H26: 46267.958 | I26: 0.39425 | J26: 止損 | K26: =(H26-D26)*24 | L26: =IF(C26="做多",I26/E26-1,1-I26/E26)-2*參數!$B$7 | N26: 0.072351421 | O26: 0.066860678 | P26: 0.0083094417 | Q26: 701572 | R26: 3206596.5 | S26: 0 | T26: 0.05 | U26: 2.4253182 | V26: 0.59577922 | X26: -0.038684271 | Y26: 0.0070416189 | Z26: -0.00078019808 | AA26: 0.03 | AB26: 0.05 | AC26: =(AB26+2*參數!$B$7)/(AA26+AB26)
A27: 26 | B27: LIT_USDT_PERP | C27: 做多 | D27: 46268 | E27: 3.672 | F27: 3.78216 | G27: 3.4884 | H27: 46268.083 | I27: 3.78216 | J27: 止盈 | K27: =(H27-D27)*24 | L27: =IF(C27="做多",I27/E27-1,1-I27/E27)-2*參數!$B$7 | N27: 0.025698324 | O27: 0.025186258 | P27: 0.034074908 | Q27: 134118.9 | R27: 2562400.1 | S27: 0.03 | T27: 0.0010893246 | U27: 1.2553863 | V27: 0.95 | W27: 0.021992886 | X27: -0.048704663 | Y27: 0.0029341504 | Z27: 0.0010861623 | AA27: 0.03 | AB27: 0.05 | AC27: =(AB27+2*參數!$B$7)/(AA27+AB27)
A28: 27 | B28: HEMI_USDT_PERP | C28: 做多 | D28: 46268.042 | E28: 0.01528 | F28: 0.0157384 | G28: 0.014516 | H28: 46268.083 | I28: 0.0157384 | J28: 止盈 | K28: =(H28-D28)*24 | L28: =IF(C28="做多",I28/E28-1,1-I28/E28)-2*參數!$B$7 | N28: 0.095340502 | O28: 0.079702011 | P28: 0.042398608 | Q28: 2348995 | R28: 1834088.2 | S28: 0.03 | T28: 0 | U28: 1.0328295 | V28: 0.95070423 | W28: 0.091140199 | X28: -0.057371993 | Y28: -0.0015326861 | Z28: -0.00026454269 | AA28: 0.03 | AB28: 0.05 | AC28: =(AB28+2*參數!$B$7)/(AA28+AB28)
A29: 28 | B29: HEMI_USDT_PERP | C29: 做空 | D29: 46268.125 | E29: 0.01431 | F29: 0.0138807 | G29: 0.0150255 | H29: 46268.167 | I29: 0.0138807 | J29: 止盈 | K29: =(H29-D29)*24 | L29: =IF(C29="做多",I29/E29-1,1-I29/E29)-2*參數!$B$7 | N29: -0.051061008 | O29: 0.082772179 | P29: -0.024373615 | Q29: -2655675 | R29: 1858306.5 | S29: 0.03 | T29: 0 | U29: 0.4579469 | V29: 0.85714286 | W29: -0.017202161 | X29: 0.070779221 | Y29: 0.00011764706 | Z29: -0.0022725819 | AA29: 0.03 | AB29: 0.05 | AC29: =(AB29+2*參數!$B$7)/(AA29+AB29)
A30: 29 | B30: MARSCOIN_USDT_PERP | C30: 做空 | D30: 46268.25 | E30: 0.06269 | F30: 0.0608093 | G30: 0.0658245 | H30: 46268.375 | I30: 0.0608093 | J30: 止盈 | K30: =(H30-D30)*24 | L30: =IF(C30="做多",I30/E30-1,1-I30/E30)-2*參數!$B$7 | N30: -0.051731962 | O30: 0.087712574 | P30: -0.03376207 | Q30: -3762358 | R30: 1201508.2 | S30: 0.03 | T30: 0.015951507 | U30: 2.0805189 | V30: 0.8902439 | X30: 0.083211465 | Y30: 0.001451572 | Z30: -0.00088918003 | AA30: 0.03 | AB30: 0.05 | AC30: =(AB30+2*參數!$B$7)/(AA30+AB30)
A31: 30 | B31: MAGMA_USDT_PERP | C31: 做空 | D31: 46268.292 | E31: 0.51536 | F31: 0.4998992 | G31: 0.541128 | H31: 46268.333 | I31: 0.4998992 | J31: 止盈 | K31: =(H31-D31)*24 | L31: =IF(C31="做多",I31/E31-1,1-I31/E31)-2*參數!$B$7 | N31: -0.057187809 | O31: 0.070373875 | P31: -0.024668122 | Q31: -428420 | R31: 3198859.6 | S31: 0.03 | T31: 0 | U31: 0.98500085 | V31: 0.70990056 | W31: -0.18520072 | X31: -0.11801458 | Y31: 0.0033099424 | Z31: 0.002227534 | AA31: 0.03 | AB31: 0.05 | AC31: =(AB31+2*參數!$B$7)/(AA31+AB31)
A32: 31 | B32: LIT_USDT_PERP | C32: 做多 | D32: 46268.333 | E32: 3.783 | F32: 3.89649 | G32: 3.59385 | H32: 46268.375 | I32: 3.89649 | J32: 止盈 | K32: =(H32-D32)*24 | L32: =IF(C32="做多",I32/E32-1,1-I32/E32)-2*參數!$B$7 | N32: 0.024925494 | O32: 0.023409322 | P32: 0.041876093 | Q32: 194510.6 | R32: 2112813.9 | S32: 0.03 | T32: 0 | U32: 0.95535242 | V32: 0.75396825 | W32: 0.047310298 | X32: 0.076244666 | Y32: 0.0039430415 | Z32: 0.0018588175 | AA32: 0.03 | AB32: 0.05 | AC32: =(AB32+2*參數!$B$7)/(AA32+AB32)
A33: 32 | B33: SKR_USDT_PERP | C33: 做空 | D33: 46268.417 | E33: 0.022336 | F33: 0.02166592 | G33: 0.0234528 | H33: 46268.458 | I33: 0.02166592 | J33: 止盈 | K33: =(H33-D33)*24 | L33: =IF(C33="做多",I33/E33-1,1-I33/E33)-2*參數!$B$7 | N33: -0.026711404 | O33: 0.067550648 | P33: -0.012260511 | Q33: -25430815 | R33: 1993873.9 | S33: 0.03 | T33: 0 | U33: 1.2506188 | V33: 0.7097325 | W33: 0.017713783 | X33: -0.078252474 | Y33: -0.0038429032 | Z33: -0.0026509834 | AA33: 0.03 | AB33: 0.05 | AC33: =(AB33+2*參數!$B$7)/(AA33+AB33)
A34: 33 | B34: HEMI_USDT_PERP | C34: 做多 | D34: 46268.75 | E34: 0.01608 | F34: 0.0165624 | G34: 0.015276 | H34: 46268.792 | I34: 0.0165624 | J34: 止盈 | K34: =(H34-D34)*24 | L34: =IF(C34="做多",I34/E34-1,1-I34/E34)-2*參數!$B$7 | N34: 0.020952381 | O34: 0.10585551 | P34: 0.0051256407 | Q34: 3899446 | R34: 1802330 | S34: 0.03 | T34: 0 | U34: 0.6606785 | V34: 0.71276596 | W34: 0.084793329 | X34: 0.10820124 | Y34: -0.0029482981 | Z34: 0.0020215265 | AA34: 0.03 | AB34: 0.05 | AC34: =(AB34+2*參數!$B$7)/(AA34+AB34)
A35: 34 | B35: LIT_USDT_PERP | C35: 做多 | D35: 46268.833 | E35: 3.935 | F35: 4.05305 | G35: 3.73825 | H35: 46269 | I35: 4.05305 | J35: 止盈 | K35: =(H35-D35)*24 | L35: =IF(C35="做多",I35/E35-1,1-I35/E35)-2*參數!$B$7 | N35: 0.026878914 | O35: 0.023062512 | P35: 0.029538735 | Q35: 72287.4 | R35: 2586180.6 | S35: 0.03 | T35: 0.0088945362 | U35: 1.0829726 | V35: 0.84251969 | W35: 0.075856789 | X35: 0.090329731 | Y35: 0.0026072297 | Z35: 0.0054302027 | AA35: 0.03 | AB35: 0.05 | AC35: =(AB35+2*參數!$B$7)/(AA35+AB35)
A36: 35 | B36: BTR_USDT_PERP | C36: 做多 | D36: 46268.917 | E36: 0.04945 | F36: 0.0509335 | G36: 0.0469775 | H36: 46269 | I36: 0.0469775 | J36: 止損 | K36: =(H36-D36)*24 | L36: =IF(C36="做多",I36/E36-1,1-I36/E36)-2*參數!$B$7 | N36: 0.033006058 | O36: 0.10322739 | P36: 0.049058605 | Q36: 1986953 | R36: 4007565.2 | S36: 0 | T36: 0.05 | U36: 0.52328497 | V36: 0.89956332 | W36: -0.50470803 | X36: -0.030202 | Y36: 0.0024321739 | Z36: 0.015050058 | AA36: 0.03 | AB36: 0.05 | AC36: =(AB36+2*參數!$B$7)/(AA36+AB36)
A37: 36 | B37: HEMI_USDT_PERP | C37: 做多 | D37: 46269 | E37: 0.01679 | F37: 0.0172937 | G37: 0.0159505 | H37: 46269.042 | I37: 0.0159505 | J37: 止損 | K37: =(H37-D37)*24 | L37: =IF(C37="做多",I37/E37-1,1-I37/E37)-2*參數!$B$7 | N37: 0.048064919 | O37: 0.081264273 | P37: 0.017760805 | Q37: 10234301 | R37: 1785837 | S37: 0 | T37: 0.05 | U37: 0.66813378 | V37: 0.74757282 | W37: 0.11152303 | X37: 0.20358423 | Y37: 0.010039946 | Z37: 0.04259471 | AA37: 0.03 | AB37: 0.05 | AC37: =(AB37+2*參數!$B$7)/(AA37+AB37)
A38: 37 | B38: UNI_USDT_PERP | C38: 做多 | D38: 46269.125 | E38: 6.266 | F38: 6.45398 | G38: 5.9527 | H38: 46269.25 | I38: 6.45398 | J38: 止盈 | K38: =(H38-D38)*24 | L38: =IF(C38="做多",I38/E38-1,1-I38/E38)-2*參數!$B$7 | N38: 0.022352749 | O38: 0.02290426 | P38: 0.051651072 | Q38: 131264 | R38: 4774840 | S38: 0.03 | T38: 0.012448133 | U38: 0.73569971 | V38: 0.86631016 | W38: 0.11328857 | X38: 0.081276963 | Y38: 0.0027133491 | Z38: 0.03378099 | AA38: 0.03 | AB38: 0.05 | AC38: =(AB38+2*參數!$B$7)/(AA38+AB38)
A39: 38 | B39: PUMP_USDT_PERP | C39: 做空 | D39: 46269.292 | E39: 0.004273 | F39: 0.00414481 | G39: 0.00448665 | H39: 46269.375 | I39: 0.00414481 | J39: 止盈 | K39: =(H39-D39)*24 | L39: =IF(C39="做多",I39/E39-1,1-I39/E39)-2*參數!$B$7 | N39: -0.025541619 | O39: 0.020282776 | P39: -0.023236145 | Q39: -20645662 | R39: 8456282.6 | S39: 0.03 | T39: 0.014041657 | U39: 0.57609076 | V39: 0.83687943 | W39: 0.015766622 | X39: -0.064259029 | Y39: 0.0053674634 | Z39: -0.021650359 | AA39: 0.03 | AB39: 0.05 | AC39: =(AB39+2*參數!$B$7)/(AA39+AB39)
A40: 39 | B40: TRUMP_USDT_PERP | C40: 做空 | D40: 46269.375 | E40: 2.334 | F40: 2.26398 | G40: 2.4507 | H40: 46269.875 | I40: 2.26398 | J40: 止盈 | K40: =(H40-D40)*24 | L40: =IF(C40="做多",I40/E40-1,1-I40/E40)-2*參數!$B$7 | N40: -0.021793797 | O40: 0.022900361 | P40: -0.0047757121 | Q40: -77474.4 | R40: 1531665.9 | S40: 0.03 | T40: 0.048414739 | U40: 1.1210298 | V40: 0.96363636 | W40: -0.0050164704 | X40: -0.06819222 | Y40: 0.0036168591 | Z40: -0.015161658 | AA40: 0.03 | AB40: 0.05 | AC40: =(AB40+2*參數!$B$7)/(AA40+AB40)
...

Sheet 幣種統計
A1: 交易對 | B1: 總筆數 | C1: 做多 | D1: 做空 | E1: 已平倉 | F1: 止盈 | G1: 止損 | H1: 勝率 | I1: 平均報酬/筆 | J1: 累計報酬 | K1: 平均持倉h | L1: 未平倉
A2: PONS_USDT_PERP | B2: =COUNTIFS(交易明細!$B$2:$B$509,$A2) | C2: =COUNTIFS(交易明細!$B$2:$B$509,$A2,交易明細!$C$2:$C$509,"做多") | D2: =COUNTIFS(交易明細!$B$2:$B$509,$A2,交易明細!$C$2:$C$509,"做空") | E2: =F2+G2+COUNTIFS(交易明細!$B$2:$B$509,$A2,交易明細!$J$2:$J$509,"時間出場") | F2: =COUNTIFS(交易明細!$B$2:$B$509,$A2,交易明細!$J$2:$J$509,"止盈") | G2: =COUNTIFS(交易明細!$B$2:$B$509,$A2,交易明細!$J$2:$J$509,"止損") | H2: =IFERROR(F2/E2,0) | I2: =IFERROR(AVERAGEIFS(交易明細!$L$2:$L$509,交易明細!$B$2:$B$509,$A2,交易明細!$J$2:$J$509,"<>未平倉"),0) | J2: =SUMIFS(交易明細!$L$2:$L$509,交易明細!$B$2:$B$509,$A2,交易明細!$J$2:$J$509,"<>未平倉") | K2: =IFERROR(AVERAGEIFS(交易明細!$K$2:$K$509,交易明細!$B$2:$B$509,$A2,交易明細!$J$2:$J$509,"<>未平倉"),0) | L2: =COUNTIFS(交易明細!$B$2:$B$509,$A2,交易明細!$J$2:$J$509,"未平倉")
A3: USELESS_USDT_PERP | B3: =COUNTIFS(交易明細!$B$2:$B$509,$A3) | C3: =COUNTIFS(交易明細!$B$2:$B$509,$A3,交易明細!$C$2:$C$509,"做多") | D3: =COUNTIFS(交易明細!$B$2:$B$509,$A3,交易明細!$C$2:$C$509,"做空") | E3: =F3+G3+COUNTIFS(交易明細!$B$2:$B$509,$A3,交易明細!$J$2:$J$509,"時間出場") | F3: =COUNTIFS(交易明細!$B$2:$B$509,$A3,交易明細!$J$2:$J$509,"止盈") | G3: =COUNTIFS(交易明細!$B$2:$B$509,$A3,交易明細!$J$2:$J$509,"止損") | H3: =IFERROR(F3/E3,0) | I3: =IFERROR(AVERAGEIFS(交易明細!$L$2:$L$509,交易明細!$B$2:$B$509,$A3,交易明細!$J$2:$J$509,"<>未平倉"),0) | J3: =SUMIFS(交易明細!$L$2:$L$509,交易明細!$B$2:$B$509,$A3,交易明細!$J$2:$J$509,"<>未平倉") | K3: =IFERROR(AVERAGEIFS(交易明細!$K$2:$K$509,交易明細!$B$2:$B$509,$A3,交易明細!$J$2:$J$509,"<>未平倉"),0) | L3: =COUNTIFS(交易明細!$B$2:$B$509,$A3,交易明細!$J$2:$J$509,"未平倉")
A4: PUMP_USDT_PERP | B4: =COUNTIFS(交易明細!$B$2:$B$509,$A4) | C4: =COUNTIFS(交易明細!$B$2:$B$509,$A4,交易明細!$C$2:$C$509,"做多") | D4: =COUNTIFS(交易明細!$B$2:$B$509,$A4,交易明細!$C$2:$C$509,"做空") | E4: =F4+G4+COUNTIFS(交易明細!$B$2:$B$509,$A4,交易明細!$J$2:$J$509,"時間出場") | F4: =COUNTIFS(交易明細!$B$2:$B$509,$A4,交易明細!$J$2:$J$509,"止盈") | G4: =COUNTIFS(交易明細!$B$2:$B$509,$A4,交易明細!$J$2:$J$509,"止損") | H4: =IFERROR(F4/E4,0) | I4: =IFERROR(AVERAGEIFS(交易明細!$L$2:$L$509,交易明細!$B$2:$B$509,$A4,交易明細!$J$2:$J$509,"<>未平倉"),0) | J4: =SUMIFS(交易明細!$L$2:$L$509,交易明細!$B$2:$B$509,$A4,交易明細!$J$2:$J$509,"<>未平倉") | K4: =IFERROR(AVERAGEIFS(交易明細!$K$2:$K$509,交易明細!$B$2:$B$509,$A4,交易明細!$J$2:$J$509,"<>未平倉"),0) | L4: =COUNTIFS(交易明細!$B$2:$B$509,$A4,交易明細!$J$2:$J$509,"未平倉")
A5: AKE_USDT_PERP | B5: =COUNTIFS(交易明細!$B$2:$B$509,$A5) | C5: =COUNTIFS(交易明細!$B$2:$B$509,$A5,交易明細!$C$2:$C$509,"做多") | D5: =COUNTIFS(交易明細!$B$2:$B$509,$A5,交易明細!$C$2:$C$509,"做空") | E5: =F5+G5+COUNTIFS(交易明細!$B$2:$B$509,$A5,交易明細!$J$2:$J$509,"時間出場") | F5: =COUNTIFS(交易明細!$B$2:$B$509,$A5,交易明細!$J$2:$J$509,"止盈") | G5: =COUNTIFS(交易明細!$B$2:$B$509,$A5,交易明細!$J$2:$J$509,"止損") | H5: =IFERROR(F5/E5,0) | I5: =IFERROR(AVERAGEIFS(交易明細!$L$2:$L$509,交易明細!$B$2:$B$509,$A5,交易明細!$J$2:$J$509,"<>未平倉"),0) | J5: =SUMIFS(交易明細!$L$2:$L$509,交易明細!$B$2:$B$509,$A5,交易明細!$J$2:$J$509,"<>未平倉") | K5: =IFERROR(AVERAGEIFS(交易明細!$K$2:$K$509,交易明細!$B$2:$B$509,$A5,交易明細!$J$2:$J$509,"<>未平倉"),0) | L5: =COUNTIFS(交易明細!$B$2:$B$509,$A5,交易明細!$J$2:$J$509,"未平倉")
A6: LIT_USDT_PERP | B6: =COUNTIFS(交易明細!$B$2:$B$509,$A6) | C6: =COUNTIFS(交易明細!$B$2:$B$509,$A6,交易明細!$C$2:$C$509,"做多") | D6: =COUNTIFS(交易明細!$B$2:$B$509,$A6,交易明細!$C$2:$C$509,"做空") | E6: =F6+G6+COUNTIFS(交易明細!$B$2:$B$509,$A6,交易明細!$J$2:$J$509,"時間出場") | F6: =COUNTIFS(交易明細!$B$2:$B$509,$A6,交易明細!$J$2:$J$509,"止盈") | G6: =COUNTIFS(交易明細!$B$2:$B$509,$A6,交易明細!$J$2:$J$509,"止損") | H6: =IFERROR(F6/E6,0) | I6: =IFERROR(AVERAGEIFS(交易明細!$L$2:$L$509,交易明細!$B$2:$B$509,$A6,交易明細!$J$2:$J$509,"<>未平倉"),0) | J6: =SUMIFS(交易明細!$L$2:$L$509,交易明細!$B$2:$B$509,$A6,交易明細!$J$2:$J$509,"<>未平倉") | K6: =IFERROR(AVERAGEIFS(交易明細!$K$2:$K$509,交易明細!$B$2:$B$509,$A6,交易明細!$J$2:$J$509,"<>未平倉"),0) | L6: =COUNTIFS(交易明細!$B$2:$B$509,$A6,交易明細!$J$2:$J$509,"未平倉")
A7: NEAR_USDT_PERP | B7: =COUNTIFS(交易明細!$B$2:$B$509,$A7) | C7: =COUNTIFS(交易明細!$B$2:$B$509,$A7,交易明細!$C$2:$C$509,"做多") | D7: =COUNTIFS(交易明細!$B$2:$B$509,$A7,交易明細!$C$2:$C$509,"做空") | E7: =F7+G7+COUNTIFS(交易明細!$B$2:$B$509,$A7,交易明細!$J$2:$J$509,"時間出場") | F7: =COUNTIFS(交易明細!$B$2:$B$509,$A7,交易明細!$J$2:$J$509,"止盈") | G7: =COUNTIFS(交易明細!$B$2:$B$509,$A7,交易明細!$J$2:$J$509,"止損") | H7: =IFERROR(F7/E7,0) | I7: =IFERROR(AVERAGEIFS(交易明細!$L$2:$L$509,交易明細!$B$2:$B$509,$A7,交易明細!$J$2:$J$509,"<>未平倉"),0) | J7: =SUMIFS(交易明細!$L$2:$L$509,交易明細!$B$2:$B$509,$A7,交易明細!$J$2:$J$509,"<>未平倉") | K7: =IFERROR(AVERAGEIFS(交易明細!$K$2:$K$509,交易明細!$B$2:$B$509,$A7,交易明細!$J$2:$J$509,"<>未平倉"),0) | L7: =COUNTIFS(交易明細!$B$2:$B$509,$A7,交易明細!$J$2:$J$509,"未平倉")
A8: 牛来_USDT_PERP | B8: =COUNTIFS(交易明細!$B$2:$B$509,$A8) | C8: =COUNTIFS(交易明細!$B$2:$B$509,$A8,交易明細!$C$2:$C$509,"做多") | D8: =COUNTIFS(交易明細!$B$2:$B$509,$A8,交易明細!$C$2:$C$509,"做空") | E8: =F8+G8+COUNTIFS(交易明細!$B$2:$B$509,$A8,交易明細!$J$2:$J$509,"時間出場") | F8: =COUNTIFS(交易明細!$B$2:$B$509,$A8,交易明細!$J$2:$J$509,"止盈") | G8: =COUNTIFS(交易明細!$B$2:$B$509,$A8,交易明細!$J$2:$J$509,"止損") | H8: =IFERROR(F8/E8,0) | I8: =IFERROR(AVERAGEIFS(交易明細!$L$2:$L$509,交易明細!$B$2:$B$509,$A8,交易明細!$J$2:$J$509,"<>未平倉"),0) | J8: =SUMIFS(交易明細!$L$2:$L$509,交易明細!$B$2:$B$509,$A8,交易明細!$J$2:$J$509,"<>未平倉") | K8: =IFERROR(AVERAGEIFS(交易明細!$K$2:$K$509,交易明細!$B$2:$B$509,$A8,交易明細!$J$2:$J$509,"<>未平倉"),0) | L8: =COUNTIFS(交易明細!$B$2:$B$509,$A8,交易明細!$J$2:$J$509,"未平倉")
A9: MARSCOIN_USDT_PERP | B9: =COUNTIFS(交易明細!$B$2:$B$509,$A9) | C9: =COUNTIFS(交易明細!$B$2:$B$509,$A9,交易明細!$C$2:$C$509,"做多") | D9: =COUNTIFS(交易明細!$B$2:$B$509,$A9,交易明細!$C$2:$C$509,"做空") | E9: =F9+G9+COUNTIFS(交易明細!$B$2:$B$509,$A9,交易明細!$J$2:$J$509,"時間出場") | F9: =COUNTIFS(交易明細!$B$2:$B$509,$A9,交易明細!$J$2:$J$509,"止盈") | G9: =COUNTIFS(交易明細!$B$2:$B$509,$A9,交易明細!$J$2:$J$509,"止損") | H9: =IFERROR(F9/E9,0) | I9: =IFERROR(AVERAGEIFS(交易明細!$L$2:$L$509,交易明細!$B$2:$B$509,$A9,交易明細!$J$2:$J$509,"<>未平倉"),0) | J9: =SUMIFS(交易明細!$L$2:$L$509,交易明細!$B$2:$B$509,$A9,交易明細!$J$2:$J$509,"<>未平倉") | K9: =IFERROR(AVERAGEIFS(交易明細!$K$2:$K$509,交易明細!$B$2:$B$509,$A9,交易明細!$J$2:$J$509,"<>未平倉"),0) | L9: =COUNTIFS(交易明細!$B$2:$B$509,$A9,交易明細!$J$2:$J$509,"未平倉")
A10: ARB_USDT_PERP | B10: =COUNTIFS(交易明細!$B$2:$B$509,$A10) | C10: =COUNTIFS(交易明細!$B$2:$B$509,$A10,交易明細!$C$2:$C$509,"做多") | D10: =COUNTIFS(交易明細!$B$2:$B$509,$A10,交易明細!$C$2:$C$509,"做空") | E10: =F10+G10+COUNTIFS(交易明細!$B$2:$B$509,$A10,交易明細!$J$2:$J$509,"時間出場") | F10: =COUNTIFS(交易明細!$B$2:$B$509,$A10,交易明細!$J$2:$J$509,"止盈") | G10: =COUNTIFS(交易明細!$B$2:$B$509,$A10,交易明細!$J$2:$J$509,"止損") | H10: =IFERROR(F10/E10,0) | I10: =IFERROR(AVERAGEIFS(交易明細!$L$2:$L$509,交易明細!$B$2:$B$509,$A10,交易明細!$J$2:$J$509,"<>未平倉"),0) | J10: =SUMIFS(交易明細!$L$2:$L$509,交易明細!$B$2:$B$509,$A10,交易明細!$J$2:$J$509,"<>未平倉") | K10: =IFERROR(AVERAGEIFS(交易明細!$K$2:$K$509,交易明細!$B$2:$B$509,$A10,交易明細!$J$2:$J$509,"<>未平倉"),0) | L10: =COUNTIFS(交易明細!$B$2:$B$509,$A10,交易明細!$J$2:$J$509,"未平倉")
A11: ENA_USDT_PERP | B11: =COUNTIFS(交易明細!$B$2:$B$509,$A11) | C11: =COUNTIFS(交易明細!$B$2:$B$509,$A11,交易明細!$C$2:$C$509,"做多") | D11: =COUNTIFS(交易明細!$B$2:$B$509,$A11,交易明細!$C$2:$C$509,"做空") | E11: =F11+G11+COUNTIFS(交易明細!$B$2:$B$509,$A11,交易明細!$J$2:$J$509,"時間出場") | F11: =COUNTIFS(交易明細!$B$2:$B$509,$A11,交易明細!$J$2:$J$509,"止盈") | G11: =COUNTIFS(交易明細!$B$2:$B$509,$A11,交易明細!$J$2:$J$509,"止損") | H11: =IFERROR(F11/E11,0) | I11: =IFERROR(AVERAGEIFS(交易明細!$L$2:$L$509,交易明細!$B$2:$B$509,$A11,交易明細!$J$2:$J$509,"<>未平倉"),0) | J11: =SUMIFS(交易明細!$L$2:$L$509,交易明細!$B$2:$B$509,$A11,交易明細!$J$2:$J$509,"<>未平倉") | K11: =IFERROR(AVERAGEIFS(交易明細!$K$2:$K$509,交易明細!$B$2:$B$509,$A11,交易明細!$J$2:$J$509,"<>未平倉"),0) | L11: =COUNTIFS(交易明細!$B$2:$B$509,$A11,交易明細!$J$2:$J$509,"未平倉")
A12: UNI_USDT_PERP | B12: =COUNTIFS(交易明細!$B$2:$B$509,$A12) | C12: =COUNTIFS(交易明細!$B$2:$B$509,$A12,交易明細!$C$2:$C$509,"做多") | D12: =COUNTIFS(交易明細!$B$2:$B$509,$A12,交易明細!$C$2:$C$509,"做空") | E12: =F12+G12+COUNTIFS(交易明細!$B$2:$B$509,$A12,交易明細!$J$2:$J$509,"時間出場") | F12: =COUNTIFS(交易明細!$B$2:$B$509,$A12,交易明細!$J$2:$J$509,"止盈") | G12: =COUNTIFS(交易明細!$B$2:$B$509,$A12,交易明細!$J$2:$J$509,"止損") | H12: =IFERROR(F12/E12,0) | I12: =IFERROR(AVERAGEIFS(交易明細!$L$2:$L$509,交易明細!$B$2:$B$509,$A12,交易明細!$J$2:$J$509,"<>未平倉"),0) | J12: =SUMIFS(交易明細!$L$2:$L$509,交易明細!$B$2:$B$509,$A12,交易明細!$J$2:$J$509,"<>未平倉") | K12: =IFERROR(AVERAGEIFS(交易明細!$K$2:$K$509,交易明細!$B$2:$B$509,$A12,交易明細!$J$2:$J$509,"<>未平倉"),0) | L12: =COUNTIFS(交易明細!$B$2:$B$509,$A12,交易明細!$J$2:$J$509,"未平倉")
A13: VVV_USDT_PERP | B13: =COUNTIFS(交易明細!$B$2:$B$509,$A13) | C13: =COUNTIFS(交易明細!$B$2:$B$509,$A13,交易明細!$C$2:$C$509,"做多") | D13: =COUNTIFS(交易明細!$B$2:$B$509,$A13,交易明細!$C$2:$C$509,"做空") | E13: =F13+G13+COUNTIFS(交易明細!$B$2:$B$509,$A13,交易明細!$J$2:$J$509,"時間出場") | F13: =COUNTIFS(交易明細!$B$2:$B$509,$A13,交易明細!$J$2:$J$509,"止盈") | G13: =COUNTIFS(交易明細!$B$2:$B$509,$A13,交易明細!$J$2:$J$509,"止損") | H13: =IFERROR(F13/E13,0) | I13: =IFERROR(AVERAGEIFS(交易明細!$L$2:$L$509,交易明細!$B$2:$B$509,$A13,交易明細!$J$2:$J$509,"<>未平倉"),0) | J13: =SUMIFS(交易明細!$L$2:$L$509,交易明細!$B$2:$B$509,$A13,交易明細!$J$2:$J$509,"<>未平倉") | K13: =IFERROR(AVERAGEIFS(交易明細!$K$2:$K$509,交易明細!$B$2:$B$509,$A13,交易明細!$J$2:$J$509,"<>未平倉"),0) | L13: =COUNTIFS(交易明細!$B$2:$B$509,$A13,交易明細!$J$2:$J$509,"未平倉")
... A89: SAGA_USDT_PERP | B89: =COUNTIFS(交易明細!$B$2:$B$509,$A89) | C89: =COUNTIFS(交易明細!$B$2:$B$509,$A89,交易明細!$C$2:$C$509,"做多") | D89: =COUNTIFS(交易明細!$B$2:$B$509,$A89,交易明細!$C$2:$C$509,"做空") | E89: =F89+G89+COUNTIFS(交易明細!$B$2:$B$509,$A89,交易明細!$J$2:$J$509,"時間出場") | F89: =COUNTIFS(交易明細!$B$2:$B$509,$A89,交易明細!$J$2:$J$509,"止盈") | G89: =COUNTIFS(交易明細!$B$2:$B$509,$A89,交易明細!$J$2:$J$509,"止損") | H89: =IFERROR(F89/E89,0) | I89: =IFERROR(AVERAGEIFS(交易明細!$L$2:$L$509,交易明細!$B$2:$B$509,$A89,交易明細!$J$2:$J$509,"<>未平倉"),0) | J89: =SUMIFS(交易明細!$L$2:$L$509,交易明細!$B$2:$B$509,$A89,交易明細!$J$2:$J$509,"<>未平倉") | K89: =IFERROR(AVERAGEIFS(交易明細!$K$2:$K$509,交易明細!$B$2:$B$509,$A89,交易明細!$J$2:$J$509,"<>未平倉"),0) | L89: =COUNTIFS(交易明細!$B$2:$B$509,$A89,交易明細!$J$2:$J$509,"未平倉")

Sheet 掃描清單
A1: 交易對 | B1: 狀態 | C1: 原因/備註 | D1: K棒數 | E1: 期間最低價 | F1: 期間最高價 | G1: 訊號數(多) | H1: 訊號數(空)
A2: 0G_USDT_PERP | B2: 已掃描
A3: 1INCH_USDT_PERP | B3: 已掃描
A4: 2Z_USDT_PERP | B4: 已掃描
A5: 4_USDT_PERP | B5: 已掃描
A6: AAVE_USDT_PERP | B6: 已掃描
A7: AAX_USDT_PERP | B7: 已掃描
A8: ACE_USDT_PERP | B8: 已掃描
A9: ACH_USDT_PERP | B9: 已掃描
A10: ACT_USDT_PERP | B10: 已掃描
A11: ADA_USDT_PERP | B11: 已掃描
A12: AERO_USDT_PERP | B12: 已掃描
A13: AEVO_USDT_PERP | B13: 已掃描
... A20: AIXBT_USDT_PERP | B20: 已掃描
A21: AKE_USDT_PERP | B21: 已掃描 | C21: 持倉中
A22: AKT_USDT_PERP | B22: 已掃描
A23: ALCH_USDT_PERP | B23: 已掃描
A24: ALGO_USDT_PERP | B24: 已掃描
A25: ALLO_USDT_PERP | B25: 已掃描
A26: ALL_USDT_PERP | B26: 已掃描
A27: ALT_USDT_PERP | B27: 已掃描
A28: ANIME_USDT_PERP | B28: 已掃描
A29: ANTHROPIC_USDT_PERP | B29: 已掃描
A30: APE_USDT_PERP | B30: 已掃描
A31: API3_USDT_PERP | B31: 已掃描
A32: APR_USDT_PERP | B32: 已掃描
A33: APT_USDT_PERP | B33: 已掃描
... A89: BTR_USDT_PERP | B89: 已掃描
A90: BTW_USDT_PERP | B90: 已掃描 | C90: 持倉中
A91: BULLA_USDT_PERP | B91: 已掃描
A92: B_USDT_PERP | B92: 已掃描
A93: CAKE_USDT_PERP | B93: 已掃描
A94: CAP_USDT_PERP | B94: 已掃描
A95: CASHCAT_USDT_PERP | B95: 已掃描
A96: CATI_USDT_PERP | B96: 已掃描
A97: CBRS_USDT_PERP | B97: 已掃描
A98: CC_USDT_PERP | B98: 已掃描
A99: CETUS_USDT_PERP | B99: 已掃描
A100: CFG_USDT_PERP | B100: 已掃描
A101: CFX_USDT_PERP | B101: 已掃描
...
