Workbook

Sheet 總覽
A1: 派網 USDT 交易對 動能策略回測總覽
A2: 回測區間：2026-09-01 00:00 ~ 2026-09-14 14:23（Dry Run）（台北時間）；市場：PERP；勝率 = 止盈筆數 ÷ 已平倉筆數；正報酬比例 = 報酬 > 0 的筆數 ÷ 已平倉（含時間出場）
A4: 方向 | B4: 總筆數 | C4: 已平倉 | D4: 止盈 | E4: 止損 | F4: 時間出場 | G4: 未平倉 | H4: 勝率 | I4: 盈虧平衡勝率 | J4: 平均報酬/筆 | K4: 累計報酬(單利加總) | L4: 平均持倉h | M4: 止盈平均持倉h | N4: 止損平均持倉h | O4: 時間出場平均報酬 | P4: 正報酬比例
A5: 全部 | B5: =COUNTIFS(交易明細!$B$2:$B$29,"<>") | C5: =D5+E5+F5 | D5: =COUNTIFS(交易明細!$J$2:$J$29,"止盈") | E5: =COUNTIFS(交易明細!$J$2:$J$29,"止損") | F5: =COUNTIFS(交易明細!$J$2:$J$29,"時間出場") | G5: =COUNTIFS(交易明細!$J$2:$J$29,"未平倉") | H5: =IFERROR(D5/C5,0) | I5: =IFERROR(AVERAGEIFS(交易明細!$AC$2:$AC$29,交易明細!$J$2:$J$29,"<>未平倉"),參數!$B$16) | J5: =IFERROR(AVERAGEIFS(交易明細!$L$2:$L$29,交易明細!$J$2:$J$29,"<>未平倉"),0) | K5: =SUMIFS(交易明細!$L$2:$L$29,交易明細!$J$2:$J$29,"<>未平倉") | L5: =IFERROR(AVERAGEIFS(交易明細!$K$2:$K$29,交易明細!$J$2:$J$29,"<>未平倉"),0) | M5: =IFERROR(AVERAGEIFS(交易明細!$K$2:$K$29,交易明細!$J$2:$J$29,"止盈"),0) | N5: =IFERROR(AVERAGEIFS(交易明細!$K$2:$K$29,交易明細!$J$2:$J$29,"止損"),0) | O5: =IFERROR(AVERAGEIFS(交易明細!$L$2:$L$29,交易明細!$J$2:$J$29,"時間出場"),0) | P5: =IFERROR(COUNTIFS(交易明細!$J$2:$J$29,"<>未平倉",交易明細!$L$2:$L$29,">0")/C5,0)
A6: 做多 | B6: =COUNTIFS(交易明細!$C$2:$C$29,"做多",交易明細!$B$2:$B$29,"<>") | C6: =D6+E6+F6 | D6: =COUNTIFS(交易明細!$C$2:$C$29,"做多",交易明細!$J$2:$J$29,"止盈") | E6: =COUNTIFS(交易明細!$C$2:$C$29,"做多",交易明細!$J$2:$J$29,"止損") | F6: =COUNTIFS(交易明細!$C$2:$C$29,"做多",交易明細!$J$2:$J$29,"時間出場") | G6: =COUNTIFS(交易明細!$C$2:$C$29,"做多",交易明細!$J$2:$J$29,"未平倉") | H6: =IFERROR(D6/C6,0) | I6: =IFERROR(AVERAGEIFS(交易明細!$AC$2:$AC$29,交易明細!$C$2:$C$29,"做多",交易明細!$J$2:$J$29,"<>未平倉"),參數!$B$16) | J6: =IFERROR(AVERAGEIFS(交易明細!$L$2:$L$29,交易明細!$C$2:$C$29,"做多",交易明細!$J$2:$J$29,"<>未平倉"),0) | K6: =SUMIFS(交易明細!$L$2:$L$29,交易明細!$C$2:$C$29,"做多",交易明細!$J$2:$J$29,"<>未平倉") | L6: =IFERROR(AVERAGEIFS(交易明細!$K$2:$K$29,交易明細!$C$2:$C$29,"做多",交易明細!$J$2:$J$29,"<>未平倉"),0) | M6: =IFERROR(AVERAGEIFS(交易明細!$K$2:$K$29,交易明細!$C$2:$C$29,"做多",交易明細!$J$2:$J$29,"止盈"),0) | N6: =IFERROR(AVERAGEIFS(交易明細!$K$2:$K$29,交易明細!$C$2:$C$29,"做多",交易明細!$J$2:$J$29,"止損"),0) | O6: =IFERROR(AVERAGEIFS(交易明細!$L$2:$L$29,交易明細!$C$2:$C$29,"做多",交易明細!$J$2:$J$29,"時間出場"),0) | P6: =IFERROR(COUNTIFS(交易明細!$C$2:$C$29,"做多",交易明細!$J$2:$J$29,"<>未平倉",交易明細!$L$2:$L$29,">0")/C6,0)
A7: 做空 | B7: =COUNTIFS(交易明細!$C$2:$C$29,"做空",交易明細!$B$2:$B$29,"<>") | C7: =D7+E7+F7 | D7: =COUNTIFS(交易明細!$C$2:$C$29,"做空",交易明細!$J$2:$J$29,"止盈") | E7: =COUNTIFS(交易明細!$C$2:$C$29,"做空",交易明細!$J$2:$J$29,"止損") | F7: =COUNTIFS(交易明細!$C$2:$C$29,"做空",交易明細!$J$2:$J$29,"時間出場") | G7: =COUNTIFS(交易明細!$C$2:$C$29,"做空",交易明細!$J$2:$J$29,"未平倉") | H7: =IFERROR(D7/C7,0) | I7: =IFERROR(AVERAGEIFS(交易明細!$AC$2:$AC$29,交易明細!$C$2:$C$29,"做空",交易明細!$J$2:$J$29,"<>未平倉"),參數!$B$16) | J7: =IFERROR(AVERAGEIFS(交易明細!$L$2:$L$29,交易明細!$C$2:$C$29,"做空",交易明細!$J$2:$J$29,"<>未平倉"),0) | K7: =SUMIFS(交易明細!$L$2:$L$29,交易明細!$C$2:$C$29,"做空",交易明細!$J$2:$J$29,"<>未平倉") | L7: =IFERROR(AVERAGEIFS(交易明細!$K$2:$K$29,交易明細!$C$2:$C$29,"做空",交易明細!$J$2:$J$29,"<>未平倉"),0) | M7: =IFERROR(AVERAGEIFS(交易明細!$K$2:$K$29,交易明細!$C$2:$C$29,"做空",交易明細!$J$2:$J$29,"止盈"),0) | N7: =IFERROR(AVERAGEIFS(交易明細!$K$2:$K$29,交易明細!$C$2:$C$29,"做空",交易明細!$J$2:$J$29,"止損"),0) | O7: =IFERROR(AVERAGEIFS(交易明細!$L$2:$L$29,交易明細!$C$2:$C$29,"做空",交易明細!$J$2:$J$29,"時間出場"),0) | P7: =IFERROR(COUNTIFS(交易明細!$C$2:$C$29,"做空",交易明細!$J$2:$J$29,"<>未平倉",交易明細!$L$2:$L$29,">0")/C7,0)
A9: 說明
A10: ・持倉時間以1小時K棒為精度（觸價當根收盤計），5分K判定的交易精度為5分鐘。
A11: ・止盈以止盈價成交；止損若遇開盤跳空穿越，以開盤價成交（較保守）。
A12: ・同一根1h同時碰到止盈與止損時，依參數頁設定判斷（見交易明細『判定說明』）。
A13: ・只含目前仍上架的交易對，已下架幣種不在內（存活者偏差，實際表現可能較差）。
A14: ・可在『參數』頁修改手續費，報酬率欄位會自動重算。

Sheet 運行紀錄
A1: 執行時間(台北) | B1: 最新K棒(開盤時間) | C1: 交易對數 | D1: 新開倉 | E1: 新平倉 | F1: 錯誤數 | G1: 耗時(秒)
A2: 46279.6 | B2: 46279.542 | C2: 442 | D2: 0 | E2: 0 | F2: 0 | G2: 61
A3: 46279.383 | B3: 46279.333 | C3: 442 | D3: 0 | E3: 0 | F3: 0 | G3: 59.9
A4: 46279.269 | B4: 46279.208 | C4: 442 | D4: 0 | E4: 0 | F4: 0 | G4: 61.1
A5: 46279.147 | B5: 46279.083 | C5: 442 | D5: 0 | E5: 0 | F5: 0 | G5: 55.1
A6: 46279.017 | B6: 46278.958 | C6: 442 | D6: 1 | E6: 1 | F6: 0 | G6: 59.7
A7: 46278.837 | B7: 46278.792 | C7: 442 | D7: 0 | E7: 0 | F7: 0 | G7: 65.4
A8: 46278.711 | B8: 46278.667 | C8: 442 | D8: 0 | E8: 1 | F8: 0 | G8: 63.6
A9: 46278.681 | B9: 46278.625 | C9: 442 | D9: 2 | E9: 1 | F9: 0 | G9: 63.6
A10: 46278.074 | B10: 46278 | C10: 442 | D10: 0 | E10: 0 | F10: 0 | G10: 50.2
A11: 46277.944 | B11: 46277.875 | C11: 442 | D11: 25 | E11: 25 | F11: 0 | G11: 63

Sheet ATR區間監控
A1: ATR 區間監控（資料來自觀察組：ATR ≥ 2%，其他條件與主策略相同）
A2: 近 1 個月最佳區間：5%–6%（每筆 +0.65%）
A3: 若最佳區間連續數個月不再是 4–5%，代表市場結構可能改變，需要重新檢查策略。
A5: 月份 | B5: 2%–3% 筆數 | C5: 2%–3% 勝率 | D5: 2%–3% 每筆報酬 | E5: 3%–4% 筆數 | F5: 3%–4% 勝率 | G5: 3%–4% 每筆報酬 | H5: 4%–5% 筆數 | I5: 4%–5% 勝率 | J5: 4%–5% 每筆報酬 | K5: 5%–6% 筆數 | L5: 5%–6% 勝率 | M5: 5%–6% 每筆報酬 | N5: 6%–8% 筆數 | O5: 6%–8% 勝率 | P5: 6%–8% 每筆報酬 | Q5: 8% 以上 筆數 | R5: 8% 以上 勝率 | S5: 8% 以上 每筆報酬
A6: 2026-09 | B6: 64 | C6: 0.5625 | D6: -0.006 | E6: 26 | F6: 0.57692308 | G6: -0.0048461538 | H6: 25 | I6: 0.56 | J6: -0.0062 | K6: 32 | L6: 0.71875 | M6: 0.0065 | N6: 47 | O6: 0.65957447 | P6: 0.0017659574 | Q6: 16 | R6: 0.625 | S6: -0.001

Sheet 資金模擬
A1: 資金模擬：依訊號時間順序下單
A2: 藍字黃底的參數可直接修改，整份模擬會自動重算
A3: 參數 | D3: 績效摘要
A4: 初始本金 | B4: 100 | D4: 最終本金（已實現） | E4: =資金明細!R58
A5: 下單比例 | B5: 0.02 | D5: 總報酬率 | E5: =E4/B4-1
A6: 本金更新級距 | B6: 50 | D6: 最高本金 | E6: =MAX(資金明細!$R$2:$R$58)
A7: 槓桿倍數 | B7: 50 | D7: 最低本金 | E7: =MIN(資金明細!$R$2:$R$58)
A8: 單邊手續費 | B8: =參數!B7 | D8: 最大回撤 | E8: =MIN(資金明細!$X$2:$X$58)
A9: 下單基準模式 | B9: 1 | D9: 已下單筆數 | E9: =COUNTIFS(資金明細!$C$2:$C$58,"進場",資金明細!$N$2:$N$58,"已下單")
A10: 停止交易門檻 | B10: 0 | D10: 資金不足略過 | E10: =COUNTIFS(資金明細!$C$2:$C$58,"進場",資金明細!$N$2:$N$58,"資金不足略過")
D11: 止盈筆數 | E11: =COUNTIFS(資金明細!$C$2:$C$58,"出場",資金明細!$N$2:$N$58,"已下單",資金明細!$K$2:$K$58,"止盈")
A12: 每筆止損約虧本金 | B12: =B5*B7*IFERROR(AVERAGE(交易明細!$AB$2:$AB$29),參數!B6) | D12: 止損筆數 | E12: =COUNTIFS(資金明細!$C$2:$C$58,"出場",資金明細!$N$2:$N$58,"已下單",資金明細!$K$2:$K$58,"止損")
A13: （以全倉、本金=基準本金計；模式1在本金回落時實際比例會更高） | D13: 勝率 | E13: =IFERROR(E11/COUNTIFS(資金明細!$C$2:$C$58,"出場",資金明細!$N$2:$N$58,"已下單"),0)
A14: 下單基準模式：1=不回滾（原規則） 2=即時本金 | D14: 最大同時持倉 | E14: =MAX(資金明細!$U$2:$U$58)
A15: 停止交易門檻：本金 ≤ 此值即停止開新倉 | D15: 最大占用保證金 | E15: =MAX(資金明細!$S$2:$S$58)
D16: 期末下單金額 | E16: =B5*資金明細!V58
D17: 未平倉浮動損益（未計入） | E17: =0
D18: 最大總曝險倍數 | E18: =MAX(資金明細!$Y$2:$Y$58)
D19: 當時全部止損約虧本金 | E19: =E18*參數!B6
D20: 停止交易時間 | E20: =IFERROR(INDEX(資金明細!$B$2:$B$58,MATCH(1,資金明細!$Z$2:$Z$58,0)),"未觸發")
D21: 停止後略過筆數 | E21: =COUNTIFS(資金明細!$C$2:$C$58,"進場",資金明細!$N$2:$N$58,"已停止")
A23: 規則說明
A24: ・下單金額 = 下單基準本金 × 下單比例。模式1：基準本金 = 本金曾達到的最高『級距倍數』（不回滾）；模式2：基準本金 = 當下本金。
A25: ・本金 ≤ 停止交易門檻後不再開新倉（已持有的單照常結算），避免模擬出現本金歸零後又『復活』的情況。
A26: ・剩餘本金 = 已實現本金（只在出場時結算）；可用資金 = 剩餘本金 − 占用保證金，不足下單金額時略過該訊號。
A27: ・同一時間點先處理出場再處理進場；報酬率已含進出場手續費。
A28: ・以全倉模式計算：總曝險倍數 = 所有持倉部位合計 ÷ 本金；未模擬持倉中的浮動虧損與維持保證金。
A29: ・回測結束仍持倉的交易不計入最終本金，浮動損益另列。

Sheet 資金明細
A1: 序號 | B1: 時間 | C1: 種類 | D1: 交易編號 | E1: 交易對 | F1: 方向 | G1: 開倉價 | H1: 止盈價 | I1: 止損價 | J1: 出場價 | K1: 結果 | L1: 持倉小時 | M1: 下單金額 | N1: 狀態 | O1: 部位大小 | P1: 報酬率(含費) | Q1: 損益 | R1: 剩餘本金 | S1: 占用保證金 | T1: 可用資金 | U1: 持倉數 | V1: 下單基準本金 | W1: 最高本金 | X1: 回撤 | Y1: 總曝險倍數 | Z1: 已停止
A2: 0 | C2: 起始 | Q2: 0 | R2: =資金模擬!$B$4 | S2: 0 | T2: =R2-S2 | U2: 0 | V2: =資金模擬!$B$4 | W2: =R2 | X2: 0 | Y2: 0 | Z2: 0
A3: 1 | B3: 46266.75 | C3: 進場 | D3: 1 | E3: USELESS_USDT_PERP | F3: 做多 | G3: 0.09113 | H3: 0.0938639 | I3: 0.0865735 | M3: =資金模擬!$B$5*V2 | N3: =IF(Z2=1,"已停止",IF(T2>=M3,"已下單","資金不足略過")) | O3: =IF(N3="已下單",M3*資金模擬!$B$7,0) | Q3: 0 | R3: =R2+Q3 | S3: =S2+IF(N3="已下單",M3,0) | T3: =R3-S3 | U3: =U2+IF(N3="已下單",1,0) | V3: =IF(資金模擬!$B$9=2,MAX(R3,0),MAX(V2,FLOOR(MAX(R3,0),資金模擬!$B$6))) | W3: =MAX(W2,R3) | X3: =IF(W3>0,R3/W3-1,-1) | Y3: =IF(R3>0,S3*資金模擬!$B$7/R3,0) | Z3: =IF(OR(Z2=1,R3<=資金模擬!$B$10),1,0)
A4: 2 | B4: 46266.792 | C4: 出場 | D4: 1 | E4: USELESS_USDT_PERP | F4: 做多 | G4: 0.09113 | H4: 0.0938639 | I4: 0.0865735 | J4: 0.0938639 | K4: 止盈 | L4: =交易明細!K2 | M4: =M3 | N4: =N3 | O4: =O3 | P4: =交易明細!L2 | Q4: =IF(N4="已下單",O4*P4,0) | R4: =R3+Q4 | S4: =S3-IF(N4="已下單",M4,0) | T4: =R4-S4 | U4: =U3-IF(N4="已下單",1,0) | V4: =IF(資金模擬!$B$9=2,MAX(R4,0),MAX(V3,FLOOR(MAX(R4,0),資金模擬!$B$6))) | W4: =MAX(W3,R4) | X4: =IF(W4>0,R4/W4-1,-1) | Y4: =IF(R4>0,S4*資金模擬!$B$7/R4,0) | Z4: =IF(OR(Z3=1,R4<=資金模擬!$B$10),1,0)
A5: 3 | B5: 46267.833 | C5: 進場 | D5: 2 | E5: ACE_USDT_PERP | F5: 做空 | G5: 0.19257 | H5: 0.1867929 | I5: 0.2021985 | M5: =資金模擬!$B$5*V4 | N5: =IF(Z4=1,"已停止",IF(T4>=M5,"已下單","資金不足略過")) | O5: =IF(N5="已下單",M5*資金模擬!$B$7,0) | Q5: 0 | R5: =R4+Q5 | S5: =S4+IF(N5="已下單",M5,0) | T5: =R5-S5 | U5: =U4+IF(N5="已下單",1,0) | V5: =IF(資金模擬!$B$9=2,MAX(R5,0),MAX(V4,FLOOR(MAX(R5,0),資金模擬!$B$6))) | W5: =MAX(W4,R5) | X5: =IF(W5>0,R5/W5-1,-1) | Y5: =IF(R5>0,S5*資金模擬!$B$7/R5,0) | Z5: =IF(OR(Z4=1,R5<=資金模擬!$B$10),1,0)
A6: 4 | B6: 46267.875 | C6: 出場 | D6: 2 | E6: ACE_USDT_PERP | F6: 做空 | G6: 0.19257 | H6: 0.1867929 | I6: 0.2021985 | J6: 0.1867929 | K6: 止盈 | L6: =交易明細!K3 | M6: =M5 | N6: =N5 | O6: =O5 | P6: =交易明細!L3 | Q6: =IF(N6="已下單",O6*P6,0) | R6: =R5+Q6 | S6: =S5-IF(N6="已下單",M6,0) | T6: =R6-S6 | U6: =U5-IF(N6="已下單",1,0) | V6: =IF(資金模擬!$B$9=2,MAX(R6,0),MAX(V5,FLOOR(MAX(R6,0),資金模擬!$B$6))) | W6: =MAX(W5,R6) | X6: =IF(W6>0,R6/W6-1,-1) | Y6: =IF(R6>0,S6*資金模擬!$B$7/R6,0) | Z6: =IF(OR(Z5=1,R6<=資金模擬!$B$10),1,0)
A7: 5 | B7: 46271.5 | C7: 進場 | D7: 3 | E7: HEMI_USDT_PERP | F7: 做空 | G7: 0.01166 | H7: 0.0113102 | I7: 0.012243 | M7: =資金模擬!$B$5*V6 | N7: =IF(Z6=1,"已停止",IF(T6>=M7,"已下單","資金不足略過")) | O7: =IF(N7="已下單",M7*資金模擬!$B$7,0) | Q7: 0 | R7: =R6+Q7 | S7: =S6+IF(N7="已下單",M7,0) | T7: =R7-S7 | U7: =U6+IF(N7="已下單",1,0) | V7: =IF(資金模擬!$B$9=2,MAX(R7,0),MAX(V6,FLOOR(MAX(R7,0),資金模擬!$B$6))) | W7: =MAX(W6,R7) | X7: =IF(W7>0,R7/W7-1,-1) | Y7: =IF(R7>0,S7*資金模擬!$B$7/R7,0) | Z7: =IF(OR(Z6=1,R7<=資金模擬!$B$10),1,0)
A8: 6 | B8: 46271.542 | C8: 出場 | D8: 3 | E8: HEMI_USDT_PERP | F8: 做空 | G8: 0.01166 | H8: 0.0113102 | I8: 0.012243 | J8: 0.0113102 | K8: 止盈 | L8: =交易明細!K4 | M8: =M7 | N8: =N7 | O8: =O7 | P8: =交易明細!L4 | Q8: =IF(N8="已下單",O8*P8,0) | R8: =R7+Q8 | S8: =S7-IF(N8="已下單",M8,0) | T8: =R8-S8 | U8: =U7-IF(N8="已下單",1,0) | V8: =IF(資金模擬!$B$9=2,MAX(R8,0),MAX(V7,FLOOR(MAX(R8,0),資金模擬!$B$6))) | W8: =MAX(W7,R8) | X8: =IF(W8>0,R8/W8-1,-1) | Y8: =IF(R8>0,S8*資金模擬!$B$7/R8,0) | Z8: =IF(OR(Z7=1,R8<=資金模擬!$B$10),1,0)
A9: 7 | B9: 46271.583 | C9: 進場 | D9: 4 | E9: HEMI_USDT_PERP | F9: 做空 | G9: 0.01128 | H9: 0.0109416 | I9: 0.011844 | M9: =資金模擬!$B$5*V8 | N9: =IF(Z8=1,"已停止",IF(T8>=M9,"已下單","資金不足略過")) | O9: =IF(N9="已下單",M9*資金模擬!$B$7,0) | Q9: 0 | R9: =R8+Q9 | S9: =S8+IF(N9="已下單",M9,0) | T9: =R9-S9 | U9: =U8+IF(N9="已下單",1,0) | V9: =IF(資金模擬!$B$9=2,MAX(R9,0),MAX(V8,FLOOR(MAX(R9,0),資金模擬!$B$6))) | W9: =MAX(W8,R9) | X9: =IF(W9>0,R9/W9-1,-1) | Y9: =IF(R9>0,S9*資金模擬!$B$7/R9,0) | Z9: =IF(OR(Z8=1,R9<=資金模擬!$B$10),1,0)
A10: 8 | B10: 46271.75 | C10: 出場 | D10: 4 | E10: HEMI_USDT_PERP | F10: 做空 | G10: 0.01128 | H10: 0.0109416 | I10: 0.011844 | J10: 0.011844 | K10: 止損 | L10: =交易明細!K5 | M10: =M9 | N10: =N9 | O10: =O9 | P10: =交易明細!L5 | Q10: =IF(N10="已下單",O10*P10,0) | R10: =R9+Q10 | S10: =S9-IF(N10="已下單",M10,0) | T10: =R10-S10 | U10: =U9-IF(N10="已下單",1,0) | V10: =IF(資金模擬!$B$9=2,MAX(R10,0),MAX(V9,FLOOR(MAX(R10,0),資金模擬!$B$6))) | W10: =MAX(W9,R10) | X10: =IF(W10>0,R10/W10-1,-1) | Y10: =IF(R10>0,S10*資金模擬!$B$7/R10,0) | Z10: =IF(OR(Z9=1,R10<=資金模擬!$B$10),1,0)
A11: 9 | B11: 46271.958 | C11: 進場 | D11: 5 | E11: ARB_USDT_PERP | F11: 做空 | G11: 0.1862 | H11: 0.180614 | I11: 0.19551 | M11: =資金模擬!$B$5*V10 | N11: =IF(Z10=1,"已停止",IF(T10>=M11,"已下單","資金不足略過")) | O11: =IF(N11="已下單",M11*資金模擬!$B$7,0) | Q11: 0 | R11: =R10+Q11 | S11: =S10+IF(N11="已下單",M11,0) | T11: =R11-S11 | U11: =U10+IF(N11="已下單",1,0) | V11: =IF(資金模擬!$B$9=2,MAX(R11,0),MAX(V10,FLOOR(MAX(R11,0),資金模擬!$B$6))) | W11: =MAX(W10,R11) | X11: =IF(W11>0,R11/W11-1,-1) | Y11: =IF(R11>0,S11*資金模擬!$B$7/R11,0) | Z11: =IF(OR(Z10=1,R11<=資金模擬!$B$10),1,0)
A12: 10 | B12: 46271.958 | C12: 進場 | D12: 6 | E12: DASH_USDT_PERP | F12: 做空 | G12: 67.53 | H12: 65.5041 | I12: 70.9065 | M12: =資金模擬!$B$5*V11 | N12: =IF(Z11=1,"已停止",IF(T11>=M12,"已下單","資金不足略過")) | O12: =IF(N12="已下單",M12*資金模擬!$B$7,0) | Q12: 0 | R12: =R11+Q12 | S12: =S11+IF(N12="已下單",M12,0) | T12: =R12-S12 | U12: =U11+IF(N12="已下單",1,0) | V12: =IF(資金模擬!$B$9=2,MAX(R12,0),MAX(V11,FLOOR(MAX(R12,0),資金模擬!$B$6))) | W12: =MAX(W11,R12) | X12: =IF(W12>0,R12/W12-1,-1) | Y12: =IF(R12>0,S12*資金模擬!$B$7/R12,0) | Z12: =IF(OR(Z11=1,R12<=資金模擬!$B$10),1,0)
A13: 11 | B13: 46272.125 | C13: 出場 | D13: 6 | E13: DASH_USDT_PERP | F13: 做空 | G13: 67.53 | H13: 65.5041 | I13: 70.9065 | J13: 70.9065 | K13: 止損 | L13: =交易明細!K7 | M13: =M12 | N13: =N12 | O13: =O12 | P13: =交易明細!L7 | Q13: =IF(N13="已下單",O13*P13,0) | R13: =R12+Q13 | S13: =S12-IF(N13="已下單",M13,0) | T13: =R13-S13 | U13: =U12-IF(N13="已下單",1,0) | V13: =IF(資金模擬!$B$9=2,MAX(R13,0),MAX(V12,FLOOR(MAX(R13,0),資金模擬!$B$6))) | W13: =MAX(W12,R13) | X13: =IF(W13>0,R13/W13-1,-1) | Y13: =IF(R13>0,S13*資金模擬!$B$7/R13,0) | Z13: =IF(OR(Z12=1,R13<=資金模擬!$B$10),1,0)
A14: 12 | B14: 46272.5 | C14: 出場 | D14: 5 | E14: ARB_USDT_PERP | F14: 做空 | G14: 0.1862 | H14: 0.180614 | I14: 0.19551 | J14: 0.180614 | K14: 止盈 | L14: =交易明細!K6 | M14: =M11 | N14: =N11 | O14: =O11 | P14: =交易明細!L6 | Q14: =IF(N14="已下單",O14*P14,0) | R14: =R13+Q14 | S14: =S13-IF(N14="已下單",M14,0) | T14: =R14-S14 | U14: =U13-IF(N14="已下單",1,0) | V14: =IF(資金模擬!$B$9=2,MAX(R14,0),MAX(V13,FLOOR(MAX(R14,0),資金模擬!$B$6))) | W14: =MAX(W13,R14) | X14: =IF(W14>0,R14/W14-1,-1) | Y14: =IF(R14>0,S14*資金模擬!$B$7/R14,0) | Z14: =IF(OR(Z13=1,R14<=資金模擬!$B$10),1,0)
A15: 13 | B15: 46272.917 | C15: 進場 | D15: 7 | E15: RAY_USDT_PERP | F15: 做空 | G15: 1.177 | H15: 1.14169 | I15: 1.23585 | M15: =資金模擬!$B$5*V14 | N15: =IF(Z14=1,"已停止",IF(T14>=M15,"已下單","資金不足略過")) | O15: =IF(N15="已下單",M15*資金模擬!$B$7,0) | Q15: 0 | R15: =R14+Q15 | S15: =S14+IF(N15="已下單",M15,0) | T15: =R15-S15 | U15: =U14+IF(N15="已下單",1,0) | V15: =IF(資金模擬!$B$9=2,MAX(R15,0),MAX(V14,FLOOR(MAX(R15,0),資金模擬!$B$6))) | W15: =MAX(W14,R15) | X15: =IF(W15>0,R15/W15-1,-1) | Y15: =IF(R15>0,S15*資金模擬!$B$7/R15,0) | Z15: =IF(OR(Z14=1,R15<=資金模擬!$B$10),1,0)
A16: 14 | B16: 46273.417 | C16: 進場 | D16: 8 | E16: IOST_USDT_PERP | F16: 做多 | G16: 0.000941 | H16: 0.00096923 | I16: 0.00089395 | M16: =資金模擬!$B$5*V15 | N16: =IF(Z15=1,"已停止",IF(T15>=M16,"已下單","資金不足略過")) | O16: =IF(N16="已下單",M16*資金模擬!$B$7,0) | Q16: 0 | R16: =R15+Q16 | S16: =S15+IF(N16="已下單",M16,0) | T16: =R16-S16 | U16: =U15+IF(N16="已下單",1,0) | V16: =IF(資金模擬!$B$9=2,MAX(R16,0),MAX(V15,FLOOR(MAX(R16,0),資金模擬!$B$6))) | W16: =MAX(W15,R16) | X16: =IF(W16>0,R16/W16-1,-1) | Y16: =IF(R16>0,S16*資金模擬!$B$7/R16,0) | Z16: =IF(OR(Z15=1,R16<=資金模擬!$B$10),1,0)
A17: 15 | B17: 46273.5 | C17: 出場 | D17: 7 | E17: RAY_USDT_PERP | F17: 做空 | G17: 1.177 | H17: 1.14169 | I17: 1.23585 | J17: 1.23585 | K17: 止損 | L17: =交易明細!K8 | M17: =M15 | N17: =N15 | O17: =O15 | P17: =交易明細!L8 | Q17: =IF(N17="已下單",O17*P17,0) | R17: =R16+Q17 | S17: =S16-IF(N17="已下單",M17,0) | T17: =R17-S17 | U17: =U16-IF(N17="已下單",1,0) | V17: =IF(資金模擬!$B$9=2,MAX(R17,0),MAX(V16,FLOOR(MAX(R17,0),資金模擬!$B$6))) | W17: =MAX(W16,R17) | X17: =IF(W17>0,R17/W17-1,-1) | Y17: =IF(R17>0,S17*資金模擬!$B$7/R17,0) | Z17: =IF(OR(Z16=1,R17<=資金模擬!$B$10),1,0)
A18: 16 | B18: 46273.5 | C18: 出場 | D18: 8 | E18: IOST_USDT_PERP | F18: 做多 | G18: 0.000941 | H18: 0.00096923 | I18: 0.00089395 | J18: 0.00096923 | K18: 止盈 | L18: =交易明細!K9 | M18: =M16 | N18: =N16 | O18: =O16 | P18: =交易明細!L9 | Q18: =IF(N18="已下單",O18*P18,0) | R18: =R17+Q18 | S18: =S17-IF(N18="已下單",M18,0) | T18: =R18-S18 | U18: =U17-IF(N18="已下單",1,0) | V18: =IF(資金模擬!$B$9=2,MAX(R18,0),MAX(V17,FLOOR(MAX(R18,0),資金模擬!$B$6))) | W18: =MAX(W17,R18) | X18: =IF(W18>0,R18/W18-1,-1) | Y18: =IF(R18>0,S18*資金模擬!$B$7/R18,0) | Z18: =IF(OR(Z17=1,R18<=資金模擬!$B$10),1,0)
A19: 17 | B19: 46273.583 | C19: 進場 | D19: 9 | E19: BULLA_USDT_PERP | F19: 做空 | G19: 0.07796 | H19: 0.0756212 | I19: 0.081858 | M19: =資金模擬!$B$5*V18 | N19: =IF(Z18=1,"已停止",IF(T18>=M19,"已下單","資金不足略過")) | O19: =IF(N19="已下單",M19*資金模擬!$B$7,0) | Q19: 0 | R19: =R18+Q19 | S19: =S18+IF(N19="已下單",M19,0) | T19: =R19-S19 | U19: =U18+IF(N19="已下單",1,0) | V19: =IF(資金模擬!$B$9=2,MAX(R19,0),MAX(V18,FLOOR(MAX(R19,0),資金模擬!$B$6))) | W19: =MAX(W18,R19) | X19: =IF(W19>0,R19/W19-1,-1) | Y19: =IF(R19>0,S19*資金模擬!$B$7/R19,0) | Z19: =IF(OR(Z18=1,R19<=資金模擬!$B$10),1,0)
A20: 18 | B20: 46273.583 | C20: 進場 | D20: 10 | E20: USELESS_USDT_PERP | F20: 做多 | G20: 0.24093 | H20: 0.2481579 | I20: 0.2288835 | M20: =資金模擬!$B$5*V19 | N20: =IF(Z19=1,"已停止",IF(T19>=M20,"已下單","資金不足略過")) | O20: =IF(N20="已下單",M20*資金模擬!$B$7,0) | Q20: 0 | R20: =R19+Q20 | S20: =S19+IF(N20="已下單",M20,0) | T20: =R20-S20 | U20: =U19+IF(N20="已下單",1,0) | V20: =IF(資金模擬!$B$9=2,MAX(R20,0),MAX(V19,FLOOR(MAX(R20,0),資金模擬!$B$6))) | W20: =MAX(W19,R20) | X20: =IF(W20>0,R20/W20-1,-1) | Y20: =IF(R20>0,S20*資金模擬!$B$7/R20,0) | Z20: =IF(OR(Z19=1,R20<=資金模擬!$B$10),1,0)
A21: 19 | B21: 46273.625 | C21: 出場 | D21: 10 | E21: USELESS_USDT_PERP | F21: 做多 | G21: 0.24093 | H21: 0.2481579 | I21: 0.2288835 | J21: 0.2481579 | K21: 止盈 | L21: =交易明細!K11 | M21: =M20 | N21: =N20 | O21: =O20 | P21: =交易明細!L11 | Q21: =IF(N21="已下單",O21*P21,0) | R21: =R20+Q21 | S21: =S20-IF(N21="已下單",M21,0) | T21: =R21-S21 | U21: =U20-IF(N21="已下單",1,0) | V21: =IF(資金模擬!$B$9=2,MAX(R21,0),MAX(V20,FLOOR(MAX(R21,0),資金模擬!$B$6))) | W21: =MAX(W20,R21) | X21: =IF(W21>0,R21/W21-1,-1) | Y21: =IF(R21>0,S21*資金模擬!$B$7/R21,0) | Z21: =IF(OR(Z20=1,R21<=資金模擬!$B$10),1,0)
A22: 20 | B22: 46273.75 | C22: 進場 | D22: 11 | E22: UAI_USDT_PERP | F22: 做多 | G22: 0.7283 | H22: 0.750149 | I22: 0.691885 | M22: =資金模擬!$B$5*V21 | N22: =IF(Z21=1,"已停止",IF(T21>=M22,"已下單","資金不足略過")) | O22: =IF(N22="已下單",M22*資金模擬!$B$7,0) | Q22: 0 | R22: =R21+Q22 | S22: =S21+IF(N22="已下單",M22,0) | T22: =R22-S22 | U22: =U21+IF(N22="已下單",1,0) | V22: =IF(資金模擬!$B$9=2,MAX(R22,0),MAX(V21,FLOOR(MAX(R22,0),資金模擬!$B$6))) | W22: =MAX(W21,R22) | X22: =IF(W22>0,R22/W22-1,-1) | Y22: =IF(R22>0,S22*資金模擬!$B$7/R22,0) | Z22: =IF(OR(Z21=1,R22<=資金模擬!$B$10),1,0)
A23: 21 | B23: 46273.792 | C23: 進場 | D23: 12 | E23: CASHCAT_USDT_PERP | F23: 做空 | G23: 0.1787 | H23: 0.173339 | I23: 0.187635 | M23: =資金模擬!$B$5*V22 | N23: =IF(Z22=1,"已停止",IF(T22>=M23,"已下單","資金不足略過")) | O23: =IF(N23="已下單",M23*資金模擬!$B$7,0) | Q23: 0 | R23: =R22+Q23 | S23: =S22+IF(N23="已下單",M23,0) | T23: =R23-S23 | U23: =U22+IF(N23="已下單",1,0) | V23: =IF(資金模擬!$B$9=2,MAX(R23,0),MAX(V22,FLOOR(MAX(R23,0),資金模擬!$B$6))) | W23: =MAX(W22,R23) | X23: =IF(W23>0,R23/W23-1,-1) | Y23: =IF(R23>0,S23*資金模擬!$B$7/R23,0) | Z23: =IF(OR(Z22=1,R23<=資金模擬!$B$10),1,0)
A24: 22 | B24: 46273.833 | C24: 出場 | D24: 9 | E24: BULLA_USDT_PERP | F24: 做空 | G24: 0.07796 | H24: 0.0756212 | I24: 0.081858 | J24: 0.081858 | K24: 止損 | L24: =交易明細!K10 | M24: =M19 | N24: =N19 | O24: =O19 | P24: =交易明細!L10 | Q24: =IF(N24="已下單",O24*P24,0) | R24: =R23+Q24 | S24: =S23-IF(N24="已下單",M24,0) | T24: =R24-S24 | U24: =U23-IF(N24="已下單",1,0) | V24: =IF(資金模擬!$B$9=2,MAX(R24,0),MAX(V23,FLOOR(MAX(R24,0),資金模擬!$B$6))) | W24: =MAX(W23,R24) | X24: =IF(W24>0,R24/W24-1,-1) | Y24: =IF(R24>0,S24*資金模擬!$B$7/R24,0) | Z24: =IF(OR(Z23=1,R24<=資金模擬!$B$10),1,0)
A25: 23 | B25: 46273.833 | C25: 出場 | D25: 11 | E25: UAI_USDT_PERP | F25: 做多 | G25: 0.7283 | H25: 0.750149 | I25: 0.691885 | J25: 0.750149 | K25: 止盈 | L25: =交易明細!K12 | M25: =M22 | N25: =N22 | O25: =O22 | P25: =交易明細!L12 | Q25: =IF(N25="已下單",O25*P25,0) | R25: =R24+Q25 | S25: =S24-IF(N25="已下單",M25,0) | T25: =R25-S25 | U25: =U24-IF(N25="已下單",1,0) | V25: =IF(資金模擬!$B$9=2,MAX(R25,0),MAX(V24,FLOOR(MAX(R25,0),資金模擬!$B$6))) | W25: =MAX(W24,R25) | X25: =IF(W25>0,R25/W25-1,-1) | Y25: =IF(R25>0,S25*資金模擬!$B$7/R25,0) | Z25: =IF(OR(Z24=1,R25<=資金模擬!$B$10),1,0)
A26: 24 | B26: 46273.875 | C26: 出場 | D26: 12 | E26: CASHCAT_USDT_PERP | F26: 做空 | G26: 0.1787 | H26: 0.173339 | I26: 0.187635 | J26: 0.173339 | K26: 止盈 | L26: =交易明細!K13 | M26: =M23 | N26: =N23 | O26: =O23 | P26: =交易明細!L13 | Q26: =IF(N26="已下單",O26*P26,0) | R26: =R25+Q26 | S26: =S25-IF(N26="已下單",M26,0) | T26: =R26-S26 | U26: =U25-IF(N26="已下單",1,0) | V26: =IF(資金模擬!$B$9=2,MAX(R26,0),MAX(V25,FLOOR(MAX(R26,0),資金模擬!$B$6))) | W26: =MAX(W25,R26) | X26: =IF(W26>0,R26/W26-1,-1) | Y26: =IF(R26>0,S26*資金模擬!$B$7/R26,0) | Z26: =IF(OR(Z25=1,R26<=資金模擬!$B$10),1,0)
A27: 25 | B27: 46274.083 | C27: 進場 | D27: 13 | E27: UAI_USDT_PERP | F27: 做多 | G27: 0.7446 | H27: 0.766938 | I27: 0.70737 | M27: =資金模擬!$B$5*V26 | N27: =IF(Z26=1,"已停止",IF(T26>=M27,"已下單","資金不足略過")) | O27: =IF(N27="已下單",M27*資金模擬!$B$7,0) | Q27: 0 | R27: =R26+Q27 | S27: =S26+IF(N27="已下單",M27,0) | T27: =R27-S27 | U27: =U26+IF(N27="已下單",1,0) | V27: =IF(資金模擬!$B$9=2,MAX(R27,0),MAX(V26,FLOOR(MAX(R27,0),資金模擬!$B$6))) | W27: =MAX(W26,R27) | X27: =IF(W27>0,R27/W27-1,-1) | Y27: =IF(R27>0,S27*資金模擬!$B$7/R27,0) | Z27: =IF(OR(Z26=1,R27<=資金模擬!$B$10),1,0)
A28: 26 | B28: 46274.208 | C28: 出場 | D28: 13 | E28: UAI_USDT_PERP | F28: 做多 | G28: 0.7446 | H28: 0.766938 | I28: 0.70737 | J28: 0.70737 | K28: 止損 | L28: =交易明細!K14 | M28: =M27 | N28: =N27 | O28: =O27 | P28: =交易明細!L14 | Q28: =IF(N28="已下單",O28*P28,0) | R28: =R27+Q28 | S28: =S27-IF(N28="已下單",M28,0) | T28: =R28-S28 | U28: =U27-IF(N28="已下單",1,0) | V28: =IF(資金模擬!$B$9=2,MAX(R28,0),MAX(V27,FLOOR(MAX(R28,0),資金模擬!$B$6))) | W28: =MAX(W27,R28) | X28: =IF(W28>0,R28/W28-1,-1) | Y28: =IF(R28>0,S28*資金模擬!$B$7/R28,0) | Z28: =IF(OR(Z27=1,R28<=資金模擬!$B$10),1,0)
A29: 27 | B29: 46274.542 | C29: 進場 | D29: 14 | E29: PONS_USDT_PERP | F29: 做多 | G29: 0.8091 | H29: 0.833373 | I29: 0.768645 | M29: =資金模擬!$B$5*V28 | N29: =IF(Z28=1,"已停止",IF(T28>=M29,"已下單","資金不足略過")) | O29: =IF(N29="已下單",M29*資金模擬!$B$7,0) | Q29: 0 | R29: =R28+Q29 | S29: =S28+IF(N29="已下單",M29,0) | T29: =R29-S29 | U29: =U28+IF(N29="已下單",1,0) | V29: =IF(資金模擬!$B$9=2,MAX(R29,0),MAX(V28,FLOOR(MAX(R29,0),資金模擬!$B$6))) | W29: =MAX(W28,R29) | X29: =IF(W29>0,R29/W29-1,-1) | Y29: =IF(R29>0,S29*資金模擬!$B$7/R29,0) | Z29: =IF(OR(Z28=1,R29<=資金模擬!$B$10),1,0)
A30: 28 | B30: 46274.708 | C30: 出場 | D30: 14 | E30: PONS_USDT_PERP | F30: 做多 | G30: 0.8091 | H30: 0.833373 | I30: 0.768645 | J30: 0.833373 | K30: 止盈 | L30: =交易明細!K15 | M30: =M29 | N30: =N29 | O30: =O29 | P30: =交易明細!L15 | Q30: =IF(N30="已下單",O30*P30,0) | R30: =R29+Q30 | S30: =S29-IF(N30="已下單",M30,0) | T30: =R30-S30 | U30: =U29-IF(N30="已下單",1,0) | V30: =IF(資金模擬!$B$9=2,MAX(R30,0),MAX(V29,FLOOR(MAX(R30,0),資金模擬!$B$6))) | W30: =MAX(W29,R30) | X30: =IF(W30>0,R30/W30-1,-1) | Y30: =IF(R30>0,S30*資金模擬!$B$7/R30,0) | Z30: =IF(OR(Z29=1,R30<=資金模擬!$B$10),1,0)
A31: 29 | B31: 46274.875 | C31: 進場 | D31: 15 | E31: PONS_USDT_PERP | F31: 做多 | G31: 0.8066 | H31: 0.830798 | I31: 0.76627 | M31: =資金模擬!$B$5*V30 | N31: =IF(Z30=1,"已停止",IF(T30>=M31,"已下單","資金不足略過")) | O31: =IF(N31="已下單",M31*資金模擬!$B$7,0) | Q31: 0 | R31: =R30+Q31 | S31: =S30+IF(N31="已下單",M31,0) | T31: =R31-S31 | U31: =U30+IF(N31="已下單",1,0) | V31: =IF(資金模擬!$B$9=2,MAX(R31,0),MAX(V30,FLOOR(MAX(R31,0),資金模擬!$B$6))) | W31: =MAX(W30,R31) | X31: =IF(W31>0,R31/W31-1,-1) | Y31: =IF(R31>0,S31*資金模擬!$B$7/R31,0) | Z31: =IF(OR(Z30=1,R31<=資金模擬!$B$10),1,0)
A32: 30 | B32: 46274.958 | C32: 出場 | D32: 15 | E32: PONS_USDT_PERP | F32: 做多 | G32: 0.8066 | H32: 0.830798 | I32: 0.76627 | J32: 0.76627 | K32: 止損 | L32: =交易明細!K16 | M32: =M31 | N32: =N31 | O32: =O31 | P32: =交易明細!L16 | Q32: =IF(N32="已下單",O32*P32,0) | R32: =R31+Q32 | S32: =S31-IF(N32="已下單",M32,0) | T32: =R32-S32 | U32: =U31-IF(N32="已下單",1,0) | V32: =IF(資金模擬!$B$9=2,MAX(R32,0),MAX(V31,FLOOR(MAX(R32,0),資金模擬!$B$6))) | W32: =MAX(W31,R32) | X32: =IF(W32>0,R32/W32-1,-1) | Y32: =IF(R32>0,S32*資金模擬!$B$7/R32,0) | Z32: =IF(OR(Z31=1,R32<=資金模擬!$B$10),1,0)
A33: 31 | B33: 46275.042 | C33: 進場 | D33: 16 | E33: AKE_USDT_PERP | F33: 做空 | G33: 0.0151607 | H33: 0.014705879 | I33: 0.015918735 | M33: =資金模擬!$B$5*V32 | N33: =IF(Z32=1,"已停止",IF(T32>=M33,"已下單","資金不足略過")) | O33: =IF(N33="已下單",M33*資金模擬!$B$7,0) | Q33: 0 | R33: =R32+Q33 | S33: =S32+IF(N33="已下單",M33,0) | T33: =R33-S33 | U33: =U32+IF(N33="已下單",1,0) | V33: =IF(資金模擬!$B$9=2,MAX(R33,0),MAX(V32,FLOOR(MAX(R33,0),資金模擬!$B$6))) | W33: =MAX(W32,R33) | X33: =IF(W33>0,R33/W33-1,-1) | Y33: =IF(R33>0,S33*資金模擬!$B$7/R33,0) | Z33: =IF(OR(Z32=1,R33<=資金模擬!$B$10),1,0)
A34: 32 | B34: 46275.083 | C34: 進場 | D34: 17 | E34: RAY_USDT_PERP | F34: 做多 | G34: 1.365 | H34: 1.40595 | I34: 1.29675 | M34: =資金模擬!$B$5*V33 | N34: =IF(Z33=1,"已停止",IF(T33>=M34,"已下單","資金不足略過")) | O34: =IF(N34="已下單",M34*資金模擬!$B$7,0) | Q34: 0 | R34: =R33+Q34 | S34: =S33+IF(N34="已下單",M34,0) | T34: =R34-S34 | U34: =U33+IF(N34="已下單",1,0) | V34: =IF(資金模擬!$B$9=2,MAX(R34,0),MAX(V33,FLOOR(MAX(R34,0),資金模擬!$B$6))) | W34: =MAX(W33,R34) | X34: =IF(W34>0,R34/W34-1,-1) | Y34: =IF(R34>0,S34*資金模擬!$B$7/R34,0) | Z34: =IF(OR(Z33=1,R34<=資金模擬!$B$10),1,0)
A35: 33 | B35: 46275.167 | C35: 出場 | D35: 17 | E35: RAY_USDT_PERP | F35: 做多 | G35: 1.365 | H35: 1.40595 | I35: 1.29675 | J35: 1.29675 | K35: 止損 | L35: =交易明細!K18 | M35: =M34 | N35: =N34 | O35: =O34 | P35: =交易明細!L18 | Q35: =IF(N35="已下單",O35*P35,0) | R35: =R34+Q35 | S35: =S34-IF(N35="已下單",M35,0) | T35: =R35-S35 | U35: =U34-IF(N35="已下單",1,0) | V35: =IF(資金模擬!$B$9=2,MAX(R35,0),MAX(V34,FLOOR(MAX(R35,0),資金模擬!$B$6))) | W35: =MAX(W34,R35) | X35: =IF(W35>0,R35/W35-1,-1) | Y35: =IF(R35>0,S35*資金模擬!$B$7/R35,0) | Z35: =IF(OR(Z34=1,R35<=資金模擬!$B$10),1,0)
A36: 34 | B36: 46275.292 | C36: 出場 | D36: 16 | E36: AKE_USDT_PERP | F36: 做空 | G36: 0.0151607 | H36: 0.014705879 | I36: 0.015918735 | J36: 0.014705879 | K36: 止盈 | L36: =交易明細!K17 | M36: =M33 | N36: =N33 | O36: =O33 | P36: =交易明細!L17 | Q36: =IF(N36="已下單",O36*P36,0) | R36: =R35+Q36 | S36: =S35-IF(N36="已下單",M36,0) | T36: =R36-S36 | U36: =U35-IF(N36="已下單",1,0) | V36: =IF(資金模擬!$B$9=2,MAX(R36,0),MAX(V35,FLOOR(MAX(R36,0),資金模擬!$B$6))) | W36: =MAX(W35,R36) | X36: =IF(W36>0,R36/W36-1,-1) | Y36: =IF(R36>0,S36*資金模擬!$B$7/R36,0) | Z36: =IF(OR(Z35=1,R36<=資金模擬!$B$10),1,0)
A37: 35 | B37: 46275.542 | C37: 進場 | D37: 18 | E37: RAY_USDT_PERP | F37: 做多 | G37: 1.33 | H37: 1.3699 | I37: 1.2635 | M37: =資金模擬!$B$5*V36 | N37: =IF(Z36=1,"已停止",IF(T36>=M37,"已下單","資金不足略過")) | O37: =IF(N37="已下單",M37*資金模擬!$B$7,0) | Q37: 0 | R37: =R36+Q37 | S37: =S36+IF(N37="已下單",M37,0) | T37: =R37-S37 | U37: =U36+IF(N37="已下單",1,0) | V37: =IF(資金模擬!$B$9=2,MAX(R37,0),MAX(V36,FLOOR(MAX(R37,0),資金模擬!$B$6))) | W37: =MAX(W36,R37) | X37: =IF(W37>0,R37/W37-1,-1) | Y37: =IF(R37>0,S37*資金模擬!$B$7/R37,0) | Z37: =IF(OR(Z36=1,R37<=資金模擬!$B$10),1,0)
A38: 36 | B38: 46275.583 | C38: 出場 | D38: 18 | E38: RAY_USDT_PERP | F38: 做多 | G38: 1.33 | H38: 1.3699 | I38: 1.2635 | J38: 1.3699 | K38: 止盈 | L38: =交易明細!K19 | M38: =M37 | N38: =N37 | O38: =O37 | P38: =交易明細!L19 | Q38: =IF(N38="已下單",O38*P38,0) | R38: =R37+Q38 | S38: =S37-IF(N38="已下單",M38,0) | T38: =R38-S38 | U38: =U37-IF(N38="已下單",1,0) | V38: =IF(資金模擬!$B$9=2,MAX(R38,0),MAX(V37,FLOOR(MAX(R38,0),資金模擬!$B$6))) | W38: =MAX(W37,R38) | X38: =IF(W38>0,R38/W38-1,-1) | Y38: =IF(R38>0,S38*資金模擬!$B$7/R38,0) | Z38: =IF(OR(Z37=1,R38<=資金模擬!$B$10),1,0)
A39: 37 | B39: 46275.875 | C39: 進場 | D39: 19 | E39: RAY_USDT_PERP | F39: 做空 | G39: 1.286 | H39: 1.24742 | I39: 1.3503 | M39: =資金模擬!$B$5*V38 | N39: =IF(Z38=1,"已停止",IF(T38>=M39,"已下單","資金不足略過")) | O39: =IF(N39="已下單",M39*資金模擬!$B$7,0) | Q39: 0 | R39: =R38+Q39 | S39: =S38+IF(N39="已下單",M39,0) | T39: =R39-S39 | U39: =U38+IF(N39="已下單",1,0) | V39: =IF(資金模擬!$B$9=2,MAX(R39,0),MAX(V38,FLOOR(MAX(R39,0),資金模擬!$B$6))) | W39: =MAX(W38,R39) | X39: =IF(W39>0,R39/W39-1,-1) | Y39: =IF(R39>0,S39*資金模擬!$B$7/R39,0) | Z39: =IF(OR(Z38=1,R39<=資金模擬!$B$10),1,0)
A40: 38 | B40: 46275.875 | C40: 進場 | D40: 20 | E40: VVV_USDT_PERP | F40: 做空 | G40: 23.292 | H40: 22.59324 | I40: 24.4566 | M40: =資金模擬!$B$5*V39 | N40: =IF(Z39=1,"已停止",IF(T39>=M40,"已下單","資金不足略過")) | O40: =IF(N40="已下單",M40*資金模擬!$B$7,0) | Q40: 0 | R40: =R39+Q40 | S40: =S39+IF(N40="已下單",M40,0) | T40: =R40-S40 | U40: =U39+IF(N40="已下單",1,0) | V40: =IF(資金模擬!$B$9=2,MAX(R40,0),MAX(V39,FLOOR(MAX(R40,0),資金模擬!$B$6))) | W40: =MAX(W39,R40) | X40: =IF(W40>0,R40/W40-1,-1) | Y40: =IF(R40>0,S40*資金模擬!$B$7/R40,0) | Z40: =IF(OR(Z39=1,R40<=資金模擬!$B$10),1,0)
...

Sheet 參數
A1: 項目 | B1: 數值 | C1: 說明
A2: 市場 | B2: PERP | C2: PERP=永續合約 / SPOT=現貨
A3: 回測區間 | B3: 2026-09-01 00:00 ~ 2026-09-14 14:23（Dry Run） | C3: 台北時間
A4: K棒週期 | B4: 1小時 | C4: 訊號於K棒收盤判斷、以收盤價進場
A5: 止盈 | B5: 0.03 | C5: 同方向
A6: 止損 | B6: 0.05 | C6: 反方向
A7: 單邊手續費 | B7: 0.0005 | C7: 進場、出場各扣一次（可直接改此格，報酬率會重算）
A8: 流動性門檻 (USDT) | B8: 50000 | C8: 近24h平均每小時成交額
A9: 動能門檻 | B9: 0.02 | C9: 收盤 vs 1小時前收盤
A10: ATR 門檻 | B10: 0.04 | C10: ATR(14) ÷ 收盤，上限 5.0%
A11: 均線 | B11: MA20 | C11: 做多站上 / 做空跌破
A12: OBV 比較 | B12: 20小時前 | C12: 做多 OBV 上升 / 做空 OBV 下降
A13: 價格上限 | B13: 不限 | C13: 訊號當下收盤價須低於此值
A14: 時間停損 | B14: 無 | C14: 小時
A15: 同K棒雙觸發 | B15: 1M/5M/15M 依序判斷
A16: 盈虧平衡勝率 | B16: =IFERROR(AVERAGE(交易明細!$AC$2:$AC$29),(B6+2*B7)/(B5+B6)) | C16: 含手續費，各筆平均；勝率低於此值 = 長期虧損
A17: MA20乖離上限 | B17: 0.06 | C17: 超過不進場
A18: 1h漲跌幅上限 | B18: 0.1 | C18: 超過不進場
A19: 出場後冷卻 | B19: 1 | C19: K棒數
A20: 量比下限 | B20: 0.35 | C20: 訊號K量 ÷ 前20根均量
A21: 收盤強度下限 | B21: 不限 | C21: 1=收在順勢端極值
A22: 長週期趨勢過濾 | B22: 關閉 | C22: 1h K棒
A23: BTC 趨勢過濾 | B23: 關閉 | C23: BTC 收盤 vs 自身 MA20
A24: 24h盤整排除 | B24: 關閉 | C24: |24h漲跌| 低於此值不進場
A25: BTC同向乖離上限 | B25: 關閉 | C25: BTC 已同向偏離MA20超過此值不進場

Sheet 交易明細
A1: 編號 | B1: 交易對 | C1: 方向 | D1: 進場時間 | E1: 進場價 | F1: 止盈價 | G1: 止損價 | H1: 出場時間 | I1: 出場價 | J1: 結果 | K1: 持倉小時 | L1: 報酬率(含費) | M1: 判定說明 | N1: 1h漲跌幅 | O1: ATR% | P1: 價格vsMA20 | Q1: OBV 20h變化 | R1: 24h成交額(USDT) | S1: 最大有利(MFE) | T1: 最大不利(MAE) | U1: 量比 | V1: 收盤強度 | W1: 長週期趨勢(順勢) | X1: 24h漲跌(順勢) | Y1: BTC 1h漲跌(順勢) | Z1: BTC vs MA20(順勢) | AA1: 止盈% | AB1: 止損% | AC1: 盈虧平衡勝率
A2: 1 | B2: USELESS_USDT_PERP | C2: 做多 | D2: 46266.75 | E2: 0.09113 | F2: 0.0938639 | G2: 0.0865735 | H2: 46266.792 | I2: 0.0938639 | J2: 止盈 | K2: =(H2-D2)*24 | L2: =IF(C2="做多",I2/E2-1,1-I2/E2)-2*參數!$B$7 | N2: 0.031349027 | O2: 0.041740657 | P2: 0.016939696 | Q2: 4835282 | R2: 3907392.9 | S2: 0.03 | T2: 0 | U2: 0.835276 | V2: 0.69976359 | W2: 0.32083375 | X2: 0.31652702 | Y2: 0.00032498353 | Z2: -0.0093626988 | AA2: 0.03 | AB2: 0.05 | AC2: =(AB2+2*參數!$B$7)/(AA2+AB2)
A3: 2 | B3: ACE_USDT_PERP | C3: 做空 | D3: 46267.833 | E3: 0.19257 | F3: 0.1867929 | G3: 0.2021985 | H3: 46267.875 | I3: 0.1867929 | J3: 止盈 | K3: =(H3-D3)*24 | L3: =IF(C3="做多",I3/E3-1,1-I3/E3)-2*參數!$B$7 | N3: -0.050256461 | O3: 0.049316066 | P3: -0.051907067 | Q3: -1654553.7 | R3: 2513068 | S3: 0.03 | T3: 0 | U3: 1.5816156 | V3: 0.6308204 | W3: -0.04647144 | X3: -0.084412659 | Y3: -0.0019480892 | Z3: 0.0056958336 | AA3: 0.03 | AB3: 0.05 | AC3: =(AB3+2*參數!$B$7)/(AA3+AB3)
A4: 3 | B4: HEMI_USDT_PERP | C4: 做空 | D4: 46271.5 | E4: 0.01166 | F4: 0.0113102 | G4: 0.012243 | H4: 46271.542 | I4: 0.0113102 | J4: 止盈 | K4: =(H4-D4)*24 | L4: =IF(C4="做多",I4/E4-1,1-I4/E4)-2*參數!$B$7 | N4: -0.025083612 | O4: 0.046749403 | P4: -0.041433739 | Q4: -60572711 | R4: 1222480.4 | S4: 0.03 | T4: 0 | U4: 0.72483675 | V4: 0.5125 | W4: 0.21186928 | X4: 0.16773733 | Y4: -0.0014886299 | Z4: -0.0027099405 | AA4: 0.03 | AB4: 0.05 | AC4: =(AB4+2*參數!$B$7)/(AA4+AB4)
A5: 4 | B5: HEMI_USDT_PERP | C5: 做空 | D5: 46271.583 | E5: 0.01128 | F5: 0.0109416 | G5: 0.011844 | H5: 46271.75 | I5: 0.011844 | J5: 止損 | K5: =(H5-D5)*24 | L5: =IF(C5="做多",I5/E5-1,1-I5/E5)-2*參數!$B$7 | N5: -0.023376623 | O5: 0.047113171 | P5: -0.051582797 | Q5: -65936388 | R5: 1231916.4 | S5: 0.0026595745 | T5: 0.05 | U5: 0.35021521 | V5: 0.91489362 | W5: 0.23384139 | X5: 0.19543509 | Y5: -0.0016273301 | Z5: -0.0018895881 | AA5: 0.03 | AB5: 0.05 | AC5: =(AB5+2*參數!$B$7)/(AA5+AB5)
A6: 5 | B6: ARB_USDT_PERP | C6: 做空 | D6: 46271.958 | E6: 0.1862 | F6: 0.180614 | G6: 0.19551 | H6: 46272.5 | I6: 0.180614 | J6: 止盈 | K6: =(H6-D6)*24 | L6: =IF(C6="做多",I6/E6-1,1-I6/E6)-2*參數!$B$7 | N6: -0.036730471 | O6: 0.0424716 | P6: -0.0050495605 | Q6: -2146168.2 | R6: 6861448.9 | S6: 0.03 | T6: 0.030612245 | U6: 2.5194222 | V6: 0.73195876 | W6: -0.30350167 | X6: -0.38541667 | Y6: 0.0035979969 | Z6: 0.0039380298 | AA6: 0.03 | AB6: 0.05 | AC6: =(AB6+2*參數!$B$7)/(AA6+AB6)
A7: 6 | B7: DASH_USDT_PERP | C7: 做空 | D7: 46271.958 | E7: 67.53 | F7: 65.5041 | G7: 70.9065 | H7: 46272.125 | I7: 70.9065 | J7: 止損 | K7: =(H7-D7)*24 | L7: =IF(C7="做多",I7/E7-1,1-I7/E7)-2*參數!$B$7 | N7: -0.021020586 | O7: 0.04320473 | P7: -0.022600465 | Q7: -405.601 | R7: 3888972.2 | S7: 0.015548645 | T7: 0.05 | U7: 0.61723892 | V7: 0.58267717 | W7: -0.2163053 | X7: 0.011273792 | Y7: 0.0035979969 | Z7: 0.0039380298 | AA7: 0.03 | AB7: 0.05 | AC7: =(AB7+2*參數!$B$7)/(AA7+AB7)
A8: 7 | B8: RAY_USDT_PERP | C8: 做空 | D8: 46272.917 | E8: 1.177 | F8: 1.14169 | G8: 1.23585 | H8: 46273.5 | I8: 1.23585 | J8: 止損 | K8: =(H8-D8)*24 | L8: =IF(C8="做多",I8/E8-1,1-I8/E8)-2*參數!$B$7 | N8: -0.022425249 | O8: 0.042912919 | P8: -0.040671611 | Q8: -480078.1 | R8: 3560306.6 | S8: 0.026338148 | T8: 0.05 | U8: 0.45337706 | V8: 0.82051282 | W8: -0.20730331 | X8: 0.14087591 | Y8: 0.0031784374 | Z8: 0.0047397974 | AA8: 0.03 | AB8: 0.05 | AC8: =(AB8+2*參數!$B$7)/(AA8+AB8)
A9: 8 | B9: IOST_USDT_PERP | C9: 做多 | D9: 46273.417 | E9: 0.000941 | F9: 0.00096923 | G9: 0.00089395 | H9: 46273.5 | I9: 0.00096923 | J9: 止盈 | K9: =(H9-D9)*24 | L9: =IF(C9="做多",I9/E9-1,1-I9/E9)-2*參數!$B$7 | N9: 0.026172301 | O9: 0.049661851 | P9: 0.028359106 | Q9: 225683598 | R9: 2501561.8 | S9: 0.03 | T9: 0.012752391 | U9: 0.6087334 | V9: 0.81395349 | W9: 0.31430088 | X9: 0.33854908 | Y9: 0.001539977 | Z9: 0.0021244144 | AA9: 0.03 | AB9: 0.05 | AC9: =(AB9+2*參數!$B$7)/(AA9+AB9)
A10: 9 | B10: BULLA_USDT_PERP | C10: 做空 | D10: 46273.583 | E10: 0.07796 | F10: 0.0756212 | G10: 0.081858 | H10: 46273.833 | I10: 0.081858 | J10: 止損 | K10: =(H10-D10)*24 | L10: =IF(C10="做多",I10/E10-1,1-I10/E10)-2*參數!$B$7 | N10: -0.028656865 | O10: 0.048921979 | P10: -0.0079342356 | Q10: -107361 | R10: 3529147.2 | S10: 0.019240636 | T10: 0.05 | U10: 0.55347344 | V10: 0.73235294 | W10: -0.19259782 | X10: 0.0061193269 | Y10: 0.0012345836 | Z10: 0.0070102112 | AA10: 0.03 | AB10: 0.05 | AC10: =(AB10+2*參數!$B$7)/(AA10+AB10)
A11: 10 | B11: USELESS_USDT_PERP | C11: 做多 | D11: 46273.583 | E11: 0.24093 | F11: 0.2481579 | G11: 0.2288835 | H11: 46273.625 | I11: 0.2481579 | J11: 止盈 | K11: =(H11-D11)*24 | L11: =IF(C11="做多",I11/E11-1,1-I11/E11)-2*參數!$B$7 | N11: 0.086493799 | O11: 0.04862484 | P11: 0.053273528 | Q11: 679513 | R11: 4215211.5 | S11: 0.03 | T11: 0 | U11: 0.80528858 | V11: 0.86211513 | W11: 0.013648685 | X11: 0.09260351 | Y11: -0.0012345836 | Z11: -0.0070102112 | AA11: 0.03 | AB11: 0.05 | AC11: =(AB11+2*參數!$B$7)/(AA11+AB11)
A12: 11 | B12: UAI_USDT_PERP | C12: 做多 | D12: 46273.75 | E12: 0.7283 | F12: 0.750149 | G12: 0.691885 | H12: 46273.833 | I12: 0.750149 | J12: 止盈 | K12: =(H12-D12)*24 | L12: =IF(C12="做多",I12/E12-1,1-I12/E12)-2*參數!$B$7 | N12: 0.022318922 | O12: 0.046648015 | P12: 0.018295198 | Q12: 1249843 | R12: 5140456.2 | S12: 0.03 | T12: 0.0064533846 | U12: 1.0686469 | V12: 0.87387387 | W12: 0.29264825 | X12: 0.14656801 | Y12: 0.0042489521 | Z12: -0.0024366077 | AA12: 0.03 | AB12: 0.05 | AC12: =(AB12+2*參數!$B$7)/(AA12+AB12)
A13: 12 | B13: CASHCAT_USDT_PERP | C13: 做空 | D13: 46273.792 | E13: 0.1787 | F13: 0.173339 | G13: 0.187635 | H13: 46273.875 | I13: 0.173339 | J13: 止盈 | K13: =(H13-D13)*24 | L13: =IF(C13="做多",I13/E13-1,1-I13/E13)-2*參數!$B$7 | N13: -0.025627045 | O13: 0.047430663 | P13: -0.059646907 | Q13: -608095 | R13: 1922965.1 | S13: 0.03 | T13: 0.0067151651 | U13: 2.6787334 | V13: 0.86138614 | W13: 0.22180513 | X13: 0.17038069 | Y13: 0.0025340123 | Z13: 0.0045713001 | AA13: 0.03 | AB13: 0.05 | AC13: =(AB13+2*參數!$B$7)/(AA13+AB13)
... A29: 28 | B29: LAB_USDT_PERP | C29: 做多 | D29: 46278.958 | E29: 0.06897 | F29: 0.0710391 | G29: 0.0655215 | H29: 46279 | I29: 0.0710391 | J29: 止盈 | K29: =(H29-D29)*24 | L29: =IF(C29="做多",I29/E29-1,1-I29/E29)-2*參數!$B$7 | N29: 0.040114613 | O29: 0.049848356 | P29: 0.020122912 | Q29: 1513283 | R29: 2656323.8 | S29: 0.03 | T29: 0 | U29: 2.2282711 | V29: 0.62358277 | W29: 0.11888906 | X29: -0.040083507 | Y29: 0.0047048899 | Z29: 0.0015570672 | AA29: 0.03 | AB29: 0.05 | AC29: =(AB29+2*參數!$B$7)/(AA29+AB29)

Sheet 幣種統計
A1: 交易對 | B1: 總筆數 | C1: 做多 | D1: 做空 | E1: 已平倉 | F1: 止盈 | G1: 止損 | H1: 勝率 | I1: 平均報酬/筆 | J1: 累計報酬 | K1: 平均持倉h | L1: 未平倉
A2: RAY_USDT_PERP | B2: =COUNTIFS(交易明細!$B$2:$B$29,$A2) | C2: =COUNTIFS(交易明細!$B$2:$B$29,$A2,交易明細!$C$2:$C$29,"做多") | D2: =COUNTIFS(交易明細!$B$2:$B$29,$A2,交易明細!$C$2:$C$29,"做空") | E2: =F2+G2+COUNTIFS(交易明細!$B$2:$B$29,$A2,交易明細!$J$2:$J$29,"時間出場") | F2: =COUNTIFS(交易明細!$B$2:$B$29,$A2,交易明細!$J$2:$J$29,"止盈") | G2: =COUNTIFS(交易明細!$B$2:$B$29,$A2,交易明細!$J$2:$J$29,"止損") | H2: =IFERROR(F2/E2,0) | I2: =IFERROR(AVERAGEIFS(交易明細!$L$2:$L$29,交易明細!$B$2:$B$29,$A2,交易明細!$J$2:$J$29,"<>未平倉"),0) | J2: =SUMIFS(交易明細!$L$2:$L$29,交易明細!$B$2:$B$29,$A2,交易明細!$J$2:$J$29,"<>未平倉") | K2: =IFERROR(AVERAGEIFS(交易明細!$K$2:$K$29,交易明細!$B$2:$B$29,$A2,交易明細!$J$2:$J$29,"<>未平倉"),0) | L2: =COUNTIFS(交易明細!$B$2:$B$29,$A2,交易明細!$J$2:$J$29,"未平倉")
A3: UAI_USDT_PERP | B3: =COUNTIFS(交易明細!$B$2:$B$29,$A3) | C3: =COUNTIFS(交易明細!$B$2:$B$29,$A3,交易明細!$C$2:$C$29,"做多") | D3: =COUNTIFS(交易明細!$B$2:$B$29,$A3,交易明細!$C$2:$C$29,"做空") | E3: =F3+G3+COUNTIFS(交易明細!$B$2:$B$29,$A3,交易明細!$J$2:$J$29,"時間出場") | F3: =COUNTIFS(交易明細!$B$2:$B$29,$A3,交易明細!$J$2:$J$29,"止盈") | G3: =COUNTIFS(交易明細!$B$2:$B$29,$A3,交易明細!$J$2:$J$29,"止損") | H3: =IFERROR(F3/E3,0) | I3: =IFERROR(AVERAGEIFS(交易明細!$L$2:$L$29,交易明細!$B$2:$B$29,$A3,交易明細!$J$2:$J$29,"<>未平倉"),0) | J3: =SUMIFS(交易明細!$L$2:$L$29,交易明細!$B$2:$B$29,$A3,交易明細!$J$2:$J$29,"<>未平倉") | K3: =IFERROR(AVERAGEIFS(交易明細!$K$2:$K$29,交易明細!$B$2:$B$29,$A3,交易明細!$J$2:$J$29,"<>未平倉"),0) | L3: =COUNTIFS(交易明細!$B$2:$B$29,$A3,交易明細!$J$2:$J$29,"未平倉")
A4: VVV_USDT_PERP | B4: =COUNTIFS(交易明細!$B$2:$B$29,$A4) | C4: =COUNTIFS(交易明細!$B$2:$B$29,$A4,交易明細!$C$2:$C$29,"做多") | D4: =COUNTIFS(交易明細!$B$2:$B$29,$A4,交易明細!$C$2:$C$29,"做空") | E4: =F4+G4+COUNTIFS(交易明細!$B$2:$B$29,$A4,交易明細!$J$2:$J$29,"時間出場") | F4: =COUNTIFS(交易明細!$B$2:$B$29,$A4,交易明細!$J$2:$J$29,"止盈") | G4: =COUNTIFS(交易明細!$B$2:$B$29,$A4,交易明細!$J$2:$J$29,"止損") | H4: =IFERROR(F4/E4,0) | I4: =IFERROR(AVERAGEIFS(交易明細!$L$2:$L$29,交易明細!$B$2:$B$29,$A4,交易明細!$J$2:$J$29,"<>未平倉"),0) | J4: =SUMIFS(交易明細!$L$2:$L$29,交易明細!$B$2:$B$29,$A4,交易明細!$J$2:$J$29,"<>未平倉") | K4: =IFERROR(AVERAGEIFS(交易明細!$K$2:$K$29,交易明細!$B$2:$B$29,$A4,交易明細!$J$2:$J$29,"<>未平倉"),0) | L4: =COUNTIFS(交易明細!$B$2:$B$29,$A4,交易明細!$J$2:$J$29,"未平倉")
A5: USELESS_USDT_PERP | B5: =COUNTIFS(交易明細!$B$2:$B$29,$A5) | C5: =COUNTIFS(交易明細!$B$2:$B$29,$A5,交易明細!$C$2:$C$29,"做多") | D5: =COUNTIFS(交易明細!$B$2:$B$29,$A5,交易明細!$C$2:$C$29,"做空") | E5: =F5+G5+COUNTIFS(交易明細!$B$2:$B$29,$A5,交易明細!$J$2:$J$29,"時間出場") | F5: =COUNTIFS(交易明細!$B$2:$B$29,$A5,交易明細!$J$2:$J$29,"止盈") | G5: =COUNTIFS(交易明細!$B$2:$B$29,$A5,交易明細!$J$2:$J$29,"止損") | H5: =IFERROR(F5/E5,0) | I5: =IFERROR(AVERAGEIFS(交易明細!$L$2:$L$29,交易明細!$B$2:$B$29,$A5,交易明細!$J$2:$J$29,"<>未平倉"),0) | J5: =SUMIFS(交易明細!$L$2:$L$29,交易明細!$B$2:$B$29,$A5,交易明細!$J$2:$J$29,"<>未平倉") | K5: =IFERROR(AVERAGEIFS(交易明細!$K$2:$K$29,交易明細!$B$2:$B$29,$A5,交易明細!$J$2:$J$29,"<>未平倉"),0) | L5: =COUNTIFS(交易明細!$B$2:$B$29,$A5,交易明細!$J$2:$J$29,"未平倉")
A6: HEMI_USDT_PERP | B6: =COUNTIFS(交易明細!$B$2:$B$29,$A6) | C6: =COUNTIFS(交易明細!$B$2:$B$29,$A6,交易明細!$C$2:$C$29,"做多") | D6: =COUNTIFS(交易明細!$B$2:$B$29,$A6,交易明細!$C$2:$C$29,"做空") | E6: =F6+G6+COUNTIFS(交易明細!$B$2:$B$29,$A6,交易明細!$J$2:$J$29,"時間出場") | F6: =COUNTIFS(交易明細!$B$2:$B$29,$A6,交易明細!$J$2:$J$29,"止盈") | G6: =COUNTIFS(交易明細!$B$2:$B$29,$A6,交易明細!$J$2:$J$29,"止損") | H6: =IFERROR(F6/E6,0) | I6: =IFERROR(AVERAGEIFS(交易明細!$L$2:$L$29,交易明細!$B$2:$B$29,$A6,交易明細!$J$2:$J$29,"<>未平倉"),0) | J6: =SUMIFS(交易明細!$L$2:$L$29,交易明細!$B$2:$B$29,$A6,交易明細!$J$2:$J$29,"<>未平倉") | K6: =IFERROR(AVERAGEIFS(交易明細!$K$2:$K$29,交易明細!$B$2:$B$29,$A6,交易明細!$J$2:$J$29,"<>未平倉"),0) | L6: =COUNTIFS(交易明細!$B$2:$B$29,$A6,交易明細!$J$2:$J$29,"未平倉")
A7: BULLA_USDT_PERP | B7: =COUNTIFS(交易明細!$B$2:$B$29,$A7) | C7: =COUNTIFS(交易明細!$B$2:$B$29,$A7,交易明細!$C$2:$C$29,"做多") | D7: =COUNTIFS(交易明細!$B$2:$B$29,$A7,交易明細!$C$2:$C$29,"做空") | E7: =F7+G7+COUNTIFS(交易明細!$B$2:$B$29,$A7,交易明細!$J$2:$J$29,"時間出場") | F7: =COUNTIFS(交易明細!$B$2:$B$29,$A7,交易明細!$J$2:$J$29,"止盈") | G7: =COUNTIFS(交易明細!$B$2:$B$29,$A7,交易明細!$J$2:$J$29,"止損") | H7: =IFERROR(F7/E7,0) | I7: =IFERROR(AVERAGEIFS(交易明細!$L$2:$L$29,交易明細!$B$2:$B$29,$A7,交易明細!$J$2:$J$29,"<>未平倉"),0) | J7: =SUMIFS(交易明細!$L$2:$L$29,交易明細!$B$2:$B$29,$A7,交易明細!$J$2:$J$29,"<>未平倉") | K7: =IFERROR(AVERAGEIFS(交易明細!$K$2:$K$29,交易明細!$B$2:$B$29,$A7,交易明細!$J$2:$J$29,"<>未平倉"),0) | L7: =COUNTIFS(交易明細!$B$2:$B$29,$A7,交易明細!$J$2:$J$29,"未平倉")
A8: PONS_USDT_PERP | B8: =COUNTIFS(交易明細!$B$2:$B$29,$A8) | C8: =COUNTIFS(交易明細!$B$2:$B$29,$A8,交易明細!$C$2:$C$29,"做多") | D8: =COUNTIFS(交易明細!$B$2:$B$29,$A8,交易明細!$C$2:$C$29,"做空") | E8: =F8+G8+COUNTIFS(交易明細!$B$2:$B$29,$A8,交易明細!$J$2:$J$29,"時間出場") | F8: =COUNTIFS(交易明細!$B$2:$B$29,$A8,交易明細!$J$2:$J$29,"止盈") | G8: =COUNTIFS(交易明細!$B$2:$B$29,$A8,交易明細!$J$2:$J$29,"止損") | H8: =IFERROR(F8/E8,0) | I8: =IFERROR(AVERAGEIFS(交易明細!$L$2:$L$29,交易明細!$B$2:$B$29,$A8,交易明細!$J$2:$J$29,"<>未平倉"),0) | J8: =SUMIFS(交易明細!$L$2:$L$29,交易明細!$B$2:$B$29,$A8,交易明細!$J$2:$J$29,"<>未平倉") | K8: =IFERROR(AVERAGEIFS(交易明細!$K$2:$K$29,交易明細!$B$2:$B$29,$A8,交易明細!$J$2:$J$29,"<>未平倉"),0) | L8: =COUNTIFS(交易明細!$B$2:$B$29,$A8,交易明細!$J$2:$J$29,"未平倉")
A9: RIVER_USDT_PERP | B9: =COUNTIFS(交易明細!$B$2:$B$29,$A9) | C9: =COUNTIFS(交易明細!$B$2:$B$29,$A9,交易明細!$C$2:$C$29,"做多") | D9: =COUNTIFS(交易明細!$B$2:$B$29,$A9,交易明細!$C$2:$C$29,"做空") | E9: =F9+G9+COUNTIFS(交易明細!$B$2:$B$29,$A9,交易明細!$J$2:$J$29,"時間出場") | F9: =COUNTIFS(交易明細!$B$2:$B$29,$A9,交易明細!$J$2:$J$29,"止盈") | G9: =COUNTIFS(交易明細!$B$2:$B$29,$A9,交易明細!$J$2:$J$29,"止損") | H9: =IFERROR(F9/E9,0) | I9: =IFERROR(AVERAGEIFS(交易明細!$L$2:$L$29,交易明細!$B$2:$B$29,$A9,交易明細!$J$2:$J$29,"<>未平倉"),0) | J9: =SUMIFS(交易明細!$L$2:$L$29,交易明細!$B$2:$B$29,$A9,交易明細!$J$2:$J$29,"<>未平倉") | K9: =IFERROR(AVERAGEIFS(交易明細!$K$2:$K$29,交易明細!$B$2:$B$29,$A9,交易明細!$J$2:$J$29,"<>未平倉"),0) | L9: =COUNTIFS(交易明細!$B$2:$B$29,$A9,交易明細!$J$2:$J$29,"未平倉")
A10: ACE_USDT_PERP | B10: =COUNTIFS(交易明細!$B$2:$B$29,$A10) | C10: =COUNTIFS(交易明細!$B$2:$B$29,$A10,交易明細!$C$2:$C$29,"做多") | D10: =COUNTIFS(交易明細!$B$2:$B$29,$A10,交易明細!$C$2:$C$29,"做空") | E10: =F10+G10+COUNTIFS(交易明細!$B$2:$B$29,$A10,交易明細!$J$2:$J$29,"時間出場") | F10: =COUNTIFS(交易明細!$B$2:$B$29,$A10,交易明細!$J$2:$J$29,"止盈") | G10: =COUNTIFS(交易明細!$B$2:$B$29,$A10,交易明細!$J$2:$J$29,"止損") | H10: =IFERROR(F10/E10,0) | I10: =IFERROR(AVERAGEIFS(交易明細!$L$2:$L$29,交易明細!$B$2:$B$29,$A10,交易明細!$J$2:$J$29,"<>未平倉"),0) | J10: =SUMIFS(交易明細!$L$2:$L$29,交易明細!$B$2:$B$29,$A10,交易明細!$J$2:$J$29,"<>未平倉") | K10: =IFERROR(AVERAGEIFS(交易明細!$K$2:$K$29,交易明細!$B$2:$B$29,$A10,交易明細!$J$2:$J$29,"<>未平倉"),0) | L10: =COUNTIFS(交易明細!$B$2:$B$29,$A10,交易明細!$J$2:$J$29,"未平倉")
A11: ARB_USDT_PERP | B11: =COUNTIFS(交易明細!$B$2:$B$29,$A11) | C11: =COUNTIFS(交易明細!$B$2:$B$29,$A11,交易明細!$C$2:$C$29,"做多") | D11: =COUNTIFS(交易明細!$B$2:$B$29,$A11,交易明細!$C$2:$C$29,"做空") | E11: =F11+G11+COUNTIFS(交易明細!$B$2:$B$29,$A11,交易明細!$J$2:$J$29,"時間出場") | F11: =COUNTIFS(交易明細!$B$2:$B$29,$A11,交易明細!$J$2:$J$29,"止盈") | G11: =COUNTIFS(交易明細!$B$2:$B$29,$A11,交易明細!$J$2:$J$29,"止損") | H11: =IFERROR(F11/E11,0) | I11: =IFERROR(AVERAGEIFS(交易明細!$L$2:$L$29,交易明細!$B$2:$B$29,$A11,交易明細!$J$2:$J$29,"<>未平倉"),0) | J11: =SUMIFS(交易明細!$L$2:$L$29,交易明細!$B$2:$B$29,$A11,交易明細!$J$2:$J$29,"<>未平倉") | K11: =IFERROR(AVERAGEIFS(交易明細!$K$2:$K$29,交易明細!$B$2:$B$29,$A11,交易明細!$J$2:$J$29,"<>未平倉"),0) | L11: =COUNTIFS(交易明細!$B$2:$B$29,$A11,交易明細!$J$2:$J$29,"未平倉")
A12: DASH_USDT_PERP | B12: =COUNTIFS(交易明細!$B$2:$B$29,$A12) | C12: =COUNTIFS(交易明細!$B$2:$B$29,$A12,交易明細!$C$2:$C$29,"做多") | D12: =COUNTIFS(交易明細!$B$2:$B$29,$A12,交易明細!$C$2:$C$29,"做空") | E12: =F12+G12+COUNTIFS(交易明細!$B$2:$B$29,$A12,交易明細!$J$2:$J$29,"時間出場") | F12: =COUNTIFS(交易明細!$B$2:$B$29,$A12,交易明細!$J$2:$J$29,"止盈") | G12: =COUNTIFS(交易明細!$B$2:$B$29,$A12,交易明細!$J$2:$J$29,"止損") | H12: =IFERROR(F12/E12,0) | I12: =IFERROR(AVERAGEIFS(交易明細!$L$2:$L$29,交易明細!$B$2:$B$29,$A12,交易明細!$J$2:$J$29,"<>未平倉"),0) | J12: =SUMIFS(交易明細!$L$2:$L$29,交易明細!$B$2:$B$29,$A12,交易明細!$J$2:$J$29,"<>未平倉") | K12: =IFERROR(AVERAGEIFS(交易明細!$K$2:$K$29,交易明細!$B$2:$B$29,$A12,交易明細!$J$2:$J$29,"<>未平倉"),0) | L12: =COUNTIFS(交易明細!$B$2:$B$29,$A12,交易明細!$J$2:$J$29,"未平倉")
A13: IOST_USDT_PERP | B13: =COUNTIFS(交易明細!$B$2:$B$29,$A13) | C13: =COUNTIFS(交易明細!$B$2:$B$29,$A13,交易明細!$C$2:$C$29,"做多") | D13: =COUNTIFS(交易明細!$B$2:$B$29,$A13,交易明細!$C$2:$C$29,"做空") | E13: =F13+G13+COUNTIFS(交易明細!$B$2:$B$29,$A13,交易明細!$J$2:$J$29,"時間出場") | F13: =COUNTIFS(交易明細!$B$2:$B$29,$A13,交易明細!$J$2:$J$29,"止盈") | G13: =COUNTIFS(交易明細!$B$2:$B$29,$A13,交易明細!$J$2:$J$29,"止損") | H13: =IFERROR(F13/E13,0) | I13: =IFERROR(AVERAGEIFS(交易明細!$L$2:$L$29,交易明細!$B$2:$B$29,$A13,交易明細!$J$2:$J$29,"<>未平倉"),0) | J13: =SUMIFS(交易明細!$L$2:$L$29,交易明細!$B$2:$B$29,$A13,交易明細!$J$2:$J$29,"<>未平倉") | K13: =IFERROR(AVERAGEIFS(交易明細!$K$2:$K$29,交易明細!$B$2:$B$29,$A13,交易明細!$J$2:$J$29,"<>未平倉"),0) | L13: =COUNTIFS(交易明細!$B$2:$B$29,$A13,交易明細!$J$2:$J$29,"未平倉")
... A16: LAB_USDT_PERP | B16: =COUNTIFS(交易明細!$B$2:$B$29,$A16) | C16: =COUNTIFS(交易明細!$B$2:$B$29,$A16,交易明細!$C$2:$C$29,"做多") | D16: =COUNTIFS(交易明細!$B$2:$B$29,$A16,交易明細!$C$2:$C$29,"做空") | E16: =F16+G16+COUNTIFS(交易明細!$B$2:$B$29,$A16,交易明細!$J$2:$J$29,"時間出場") | F16: =COUNTIFS(交易明細!$B$2:$B$29,$A16,交易明細!$J$2:$J$29,"止盈") | G16: =COUNTIFS(交易明細!$B$2:$B$29,$A16,交易明細!$J$2:$J$29,"止損") | H16: =IFERROR(F16/E16,0) | I16: =IFERROR(AVERAGEIFS(交易明細!$L$2:$L$29,交易明細!$B$2:$B$29,$A16,交易明細!$J$2:$J$29,"<>未平倉"),0) | J16: =SUMIFS(交易明細!$L$2:$L$29,交易明細!$B$2:$B$29,$A16,交易明細!$J$2:$J$29,"<>未平倉") | K16: =IFERROR(AVERAGEIFS(交易明細!$K$2:$K$29,交易明細!$B$2:$B$29,$A16,交易明細!$J$2:$J$29,"<>未平倉"),0) | L16: =COUNTIFS(交易明細!$B$2:$B$29,$A16,交易明細!$J$2:$J$29,"未平倉")

Sheet 掃描清單
A1: 交易對 | B1: 狀態 | C1: 原因/備註 | D1: K棒數 | E1: 期間最低價 | F1: 期間最高價 | G1: 訊號數(多) | H1: 訊號數(空)
A2: 0G_USDT_PERP | B2: 已掃描
A3: 1INCH_USDT_PERP | B3: 已掃描
A4: 2Z_USDT_PERP | B4: 已掃描
A5: 4_USDT_PERP | B5: 已掃描
A6: AAVE_USDT_PERP | B6: 已掃描
A7: AAX_USDT_PERP | B7: 已掃描
A8: ACE_USDT_PERP | B8: 已掃描
A9: ACH_USDT_PERP | B9: 已掃描
A10: ACT_USDT_PERP | B10: 已掃描
A11: ADA_USDT_PERP | B11: 已掃描
A12: AERO_USDT_PERP | B12: 已掃描
A13: AEVO_USDT_PERP | B13: 已掃描
... A443: 牛来_USDT_PERP | B443: 已掃描
