Workbook

Sheet 總覽
A1: 派網 USDT 交易對 動能策略回測總覽
A2: 回測區間：2026-09-01 00:00 ~ 2026-10-07 22:02（Dry Run）（台北時間）；市場：PERP；勝率 = 止盈筆數 ÷ 已平倉筆數；正報酬比例 = 報酬 > 0 的筆數 ÷ 已平倉（含時間出場）
A4: 方向 | B4: 總筆數 | C4: 已平倉 | D4: 止盈 | E4: 止損 | F4: 時間出場 | G4: 未平倉 | H4: 勝率 | I4: 盈虧平衡勝率 | J4: 平均報酬/筆 | K4: 累計報酬(單利加總) | L4: 平均持倉h | M4: 止盈平均持倉h | N4: 止損平均持倉h | O4: 時間出場平均報酬 | P4: 正報酬比例
A5: 全部 | B5: =COUNTIFS(交易明細!$B$2:$B$73,"<>") | C5: =D5+E5+F5 | D5: =COUNTIFS(交易明細!$J$2:$J$73,"止盈") | E5: =COUNTIFS(交易明細!$J$2:$J$73,"止損") | F5: =COUNTIFS(交易明細!$J$2:$J$73,"時間出場") | G5: =COUNTIFS(交易明細!$J$2:$J$73,"未平倉") | H5: =IFERROR(D5/C5,0) | I5: =IFERROR(AVERAGEIFS(交易明細!$AC$2:$AC$73,交易明細!$J$2:$J$73,"<>未平倉"),參數!$B$16) | J5: =IFERROR(AVERAGEIFS(交易明細!$L$2:$L$73,交易明細!$J$2:$J$73,"<>未平倉"),0) | K5: =SUMIFS(交易明細!$L$2:$L$73,交易明細!$J$2:$J$73,"<>未平倉") | L5: =IFERROR(AVERAGEIFS(交易明細!$K$2:$K$73,交易明細!$J$2:$J$73,"<>未平倉"),0) | M5: =IFERROR(AVERAGEIFS(交易明細!$K$2:$K$73,交易明細!$J$2:$J$73,"止盈"),0) | N5: =IFERROR(AVERAGEIFS(交易明細!$K$2:$K$73,交易明細!$J$2:$J$73,"止損"),0) | O5: =IFERROR(AVERAGEIFS(交易明細!$L$2:$L$73,交易明細!$J$2:$J$73,"時間出場"),0) | P5: =IFERROR(COUNTIFS(交易明細!$J$2:$J$73,"<>未平倉",交易明細!$L$2:$L$73,">0")/C5,0)
A6: 做多 | B6: =COUNTIFS(交易明細!$C$2:$C$73,"做多",交易明細!$B$2:$B$73,"<>") | C6: =D6+E6+F6 | D6: =COUNTIFS(交易明細!$C$2:$C$73,"做多",交易明細!$J$2:$J$73,"止盈") | E6: =COUNTIFS(交易明細!$C$2:$C$73,"做多",交易明細!$J$2:$J$73,"止損") | F6: =COUNTIFS(交易明細!$C$2:$C$73,"做多",交易明細!$J$2:$J$73,"時間出場") | G6: =COUNTIFS(交易明細!$C$2:$C$73,"做多",交易明細!$J$2:$J$73,"未平倉") | H6: =IFERROR(D6/C6,0) | I6: =IFERROR(AVERAGEIFS(交易明細!$AC$2:$AC$73,交易明細!$C$2:$C$73,"做多",交易明細!$J$2:$J$73,"<>未平倉"),參數!$B$16) | J6: =IFERROR(AVERAGEIFS(交易明細!$L$2:$L$73,交易明細!$C$2:$C$73,"做多",交易明細!$J$2:$J$73,"<>未平倉"),0) | K6: =SUMIFS(交易明細!$L$2:$L$73,交易明細!$C$2:$C$73,"做多",交易明細!$J$2:$J$73,"<>未平倉") | L6: =IFERROR(AVERAGEIFS(交易明細!$K$2:$K$73,交易明細!$C$2:$C$73,"做多",交易明細!$J$2:$J$73,"<>未平倉"),0) | M6: =IFERROR(AVERAGEIFS(交易明細!$K$2:$K$73,交易明細!$C$2:$C$73,"做多",交易明細!$J$2:$J$73,"止盈"),0) | N6: =IFERROR(AVERAGEIFS(交易明細!$K$2:$K$73,交易明細!$C$2:$C$73,"做多",交易明細!$J$2:$J$73,"止損"),0) | O6: =IFERROR(AVERAGEIFS(交易明細!$L$2:$L$73,交易明細!$C$2:$C$73,"做多",交易明細!$J$2:$J$73,"時間出場"),0) | P6: =IFERROR(COUNTIFS(交易明細!$C$2:$C$73,"做多",交易明細!$J$2:$J$73,"<>未平倉",交易明細!$L$2:$L$73,">0")/C6,0)
A7: 做空 | B7: =COUNTIFS(交易明細!$C$2:$C$73,"做空",交易明細!$B$2:$B$73,"<>") | C7: =D7+E7+F7 | D7: =COUNTIFS(交易明細!$C$2:$C$73,"做空",交易明細!$J$2:$J$73,"止盈") | E7: =COUNTIFS(交易明細!$C$2:$C$73,"做空",交易明細!$J$2:$J$73,"止損") | F7: =COUNTIFS(交易明細!$C$2:$C$73,"做空",交易明細!$J$2:$J$73,"時間出場") | G7: =COUNTIFS(交易明細!$C$2:$C$73,"做空",交易明細!$J$2:$J$73,"未平倉") | H7: =IFERROR(D7/C7,0) | I7: =IFERROR(AVERAGEIFS(交易明細!$AC$2:$AC$73,交易明細!$C$2:$C$73,"做空",交易明細!$J$2:$J$73,"<>未平倉"),參數!$B$16) | J7: =IFERROR(AVERAGEIFS(交易明細!$L$2:$L$73,交易明細!$C$2:$C$73,"做空",交易明細!$J$2:$J$73,"<>未平倉"),0) | K7: =SUMIFS(交易明細!$L$2:$L$73,交易明細!$C$2:$C$73,"做空",交易明細!$J$2:$J$73,"<>未平倉") | L7: =IFERROR(AVERAGEIFS(交易明細!$K$2:$K$73,交易明細!$C$2:$C$73,"做空",交易明細!$J$2:$J$73,"<>未平倉"),0) | M7: =IFERROR(AVERAGEIFS(交易明細!$K$2:$K$73,交易明細!$C$2:$C$73,"做空",交易明細!$J$2:$J$73,"止盈"),0) | N7: =IFERROR(AVERAGEIFS(交易明細!$K$2:$K$73,交易明細!$C$2:$C$73,"做空",交易明細!$J$2:$J$73,"止損"),0) | O7: =IFERROR(AVERAGEIFS(交易明細!$L$2:$L$73,交易明細!$C$2:$C$73,"做空",交易明細!$J$2:$J$73,"時間出場"),0) | P7: =IFERROR(COUNTIFS(交易明細!$C$2:$C$73,"做空",交易明細!$J$2:$J$73,"<>未平倉",交易明細!$L$2:$L$73,">0")/C7,0)
A9: 說明
A10: ・持倉時間以主K棒為精度（觸價當根收盤計）；同根雙觸發時改用更小週期K棒判定。
A11: ・止盈以止盈價成交；止損若遇開盤跳空穿越，以開盤價成交（較保守）。
A12: ・同一根1h同時碰到止盈與止損時，依參數頁設定判斷（見交易明細『判定說明』）。
A13: ・只含目前仍上架的交易對，已下架幣種不在內（存活者偏差，實際表現可能較差）。
A14: ・可在『參數』頁修改手續費，報酬率欄位會自動重算。

Sheet 運行紀錄
A1: 執行時間(台北) | B1: 最新K棒(開盤時間) | C1: 交易對數 | D1: 新開倉 | E1: 新平倉 | F1: 錯誤數 | G1: 耗時(秒)
A2: 46302.919 | B2: 46302.917 | C2: 434 | D2: 0 | E2: 0 | F2: 0 | G2: 195.1
A3: 46302.637 | B3: 46302.636 | C3: 434 | D3: 0 | E3: 0 | F3: 0 | G3: 149.8
A4: 46302.366 | B4: 46302.365 | C4: 434 | D4: 1 | E4: 1 | F4: 0 | G4: 187.2
A5: 46302.183 | B5: 46302.183 | C5: 434 | D5: 1 | E5: 1 | F5: 0 | G5: 143.5
A6: 46301.97 | B6: 46301.969 | C6: 434 | D6: 0 | E6: 0 | F6: 0 | G6: 153.4
A7: 46301.811 | B7: 46301.81 | C7: 434 | D7: 3 | E7: 4 | F7: 0 | G7: 163.5
A8: 46301.651 | B8: 46301.65 | C8: 434 | D8: 3 | E8: 3 | F8: 0 | G8: 163.9
A9: 46301.369 | B9: 46301.368 | C9: 434 | D9: 0 | E9: 0 | F9: 0 | G9: 163.9
A10: 46301.106 | B10: 46301.105 | C10: 434 | D10: 2 | E10: 1 | F10: 0 | G10: 185.1
A11: 46300.943 | B11: 46300.942 | C11: 434 | D11: 1 | E11: 2 | F11: 0 | G11: 178.3
A12: 46300.716 | B12: 46300.715 | C12: 434 | D12: 1 | E12: 0 | F12: 0 | G12: 191.4
A13: 46300.421 | B13: 46300.42 | C13: 435 | D13: 0 | E13: 1 | F13: 0 | G13: 186
... A201: 46280.3 | B201: 46280.25 | C201: 442 | D201: 0 | E201: 0 | F201: 0 | G201: 51.6

Sheet 資金模擬
A1: 資金模擬：依訊號時間順序下單
A2: 藍字黃底的參數可直接修改，整份模擬會自動重算
A3: 參數 | D3: 績效摘要
A4: 初始本金 | B4: 100 | D4: 最終本金（已實現） | E4: =資金明細!R146
A5: 下單比例 | B5: 0.02 | D5: 總報酬率 | E5: =E4/B4-1
A6: 本金更新級距 | B6: 50 | D6: 最高本金 | E6: =MAX(資金明細!$R$2:$R$146)
A7: 槓桿倍數 | B7: 50 | D7: 最低本金 | E7: =MIN(資金明細!$R$2:$R$146)
A8: 單邊手續費 | B8: =參數!B7 | D8: 最大回撤 | E8: =MIN(資金明細!$X$2:$X$146)
A9: 下單基準模式 | B9: 2 | D9: 已下單筆數 | E9: =COUNTIFS(資金明細!$C$2:$C$146,"進場",資金明細!$N$2:$N$146,"已下單")
A10: 停止交易門檻 | B10: 0 | D10: 資金不足略過 | E10: =COUNTIFS(資金明細!$C$2:$C$146,"進場",資金明細!$N$2:$N$146,"資金不足略過")
D11: 止盈筆數 | E11: =COUNTIFS(資金明細!$C$2:$C$146,"出場",資金明細!$N$2:$N$146,"已下單",資金明細!$K$2:$K$146,"止盈")
A12: 每筆止損約虧本金 | B12: =B5*B7*IFERROR(AVERAGE(交易明細!$AB$2:$AB$73),參數!B6) | D12: 止損筆數 | E12: =COUNTIFS(資金明細!$C$2:$C$146,"出場",資金明細!$N$2:$N$146,"已下單",資金明細!$K$2:$K$146,"止損")
A13: （以全倉、本金=基準本金計；模式1在本金回落時實際比例會更高） | D13: 勝率 | E13: =IFERROR(E11/COUNTIFS(資金明細!$C$2:$C$146,"出場",資金明細!$N$2:$N$146,"已下單"),0)
A14: 下單基準模式：1=不回滾（原規則） 2=即時本金 | D14: 最大同時持倉 | E14: =MAX(資金明細!$U$2:$U$146)
A15: 停止交易門檻：本金 ≤ 此值即停止開新倉 | D15: 最大占用保證金 | E15: =MAX(資金明細!$S$2:$S$146)
D16: 期末下單金額 | E16: =B5*資金明細!V146
D17: 未平倉浮動損益（未計入） | E17: =0
D18: 最大總曝險倍數 | E18: =MAX(資金明細!$Y$2:$Y$146)
D19: 當時全部止損約虧本金 | E19: =E18*參數!B6
D20: 停止交易時間 | E20: =IFERROR(INDEX(資金明細!$B$2:$B$146,MATCH(1,資金明細!$Z$2:$Z$146,0)),"未觸發")
D21: 停止後略過筆數 | E21: =COUNTIFS(資金明細!$C$2:$C$146,"進場",資金明細!$N$2:$N$146,"已停止")
A23: 規則說明
A24: ・下單金額 = 下單基準本金 × 下單比例。模式1：基準本金 = 本金曾達到的最高『級距倍數』（不回滾）；模式2：基準本金 = 當下本金。
A25: ・本金 ≤ 停止交易門檻後不再開新倉（已持有的單照常結算），避免模擬出現本金歸零後又『復活』的情況。
A26: ・剩餘本金 = 已實現本金（只在出場時結算）；可用資金 = 剩餘本金 − 占用保證金，不足下單金額時略過該訊號。
A27: ・同一時間點先處理出場再處理進場；報酬率已含進出場手續費。
A28: ・以全倉模式計算：總曝險倍數 = 所有持倉部位合計 ÷ 本金；未模擬持倉中的浮動虧損與維持保證金。
A29: ・回測結束仍持倉的交易不計入最終本金，浮動損益另列。

Sheet 資金明細
A1: 序號 | B1: 時間 | C1: 種類 | D1: 交易編號 | E1: 交易對 | F1: 方向 | G1: 開倉價 | H1: 止盈價 | I1: 止損價 | J1: 出場價 | K1: 結果 | L1: 持倉小時 | M1: 下單金額 | N1: 狀態 | O1: 部位大小 | P1: 報酬率(含費) | Q1: 損益 | R1: 剩餘本金 | S1: 占用保證金 | T1: 可用資金 | U1: 持倉數 | V1: 下單基準本金 | W1: 最高本金 | X1: 回撤 | Y1: 總曝險倍數 | Z1: 已停止
A2: 0 | C2: 起始 | Q2: 0 | R2: =資金模擬!$B$4 | S2: 0 | T2: =R2-S2 | U2: 0 | V2: =資金模擬!$B$4 | W2: =R2 | X2: 0 | Y2: 0 | Z2: 0
A3: 1 | B3: 46289.595 | C3: 進場 | D3: 1 | E3: NOM_USDT_PERP | F3: 做空 | G3: 0.002779 | H3: 0.00269563 | I3: 0.00291795 | M3: =資金模擬!$B$5*V2 | N3: =IF(Z2=1,"已停止",IF(T2>=M3,"已下單","資金不足略過")) | O3: =IF(N3="已下單",M3*資金模擬!$B$7,0) | Q3: 0 | R3: =R2+Q3 | S3: =S2+IF(N3="已下單",M3,0) | T3: =R3-S3 | U3: =U2+IF(N3="已下單",1,0) | V3: =IF(資金模擬!$B$9=2,MAX(R3,0),MAX(V2,FLOOR(MAX(R3,0),資金模擬!$B$6))) | W3: =MAX(W2,R3) | X3: =IF(W3>0,R3/W3-1,-1) | Y3: =IF(R3>0,S3*資金模擬!$B$7/R3,0) | Z3: =IF(OR(Z2=1,R3<=資金模擬!$B$10),1,0)
A4: 2 | B4: 46289.6 | C4: 出場 | D4: 1 | E4: NOM_USDT_PERP | F4: 做空 | G4: 0.002779 | H4: 0.00269563 | I4: 0.00291795 | J4: 0.00269563 | K4: 止盈 | L4: =交易明細!K2 | M4: =M3 | N4: =N3 | O4: =O3 | P4: =交易明細!L2 | Q4: =IF(N4="已下單",O4*P4,0) | R4: =R3+Q4 | S4: =S3-IF(N4="已下單",M4,0) | T4: =R4-S4 | U4: =U3-IF(N4="已下單",1,0) | V4: =IF(資金模擬!$B$9=2,MAX(R4,0),MAX(V3,FLOOR(MAX(R4,0),資金模擬!$B$6))) | W4: =MAX(W3,R4) | X4: =IF(W4>0,R4/W4-1,-1) | Y4: =IF(R4>0,S4*資金模擬!$B$7/R4,0) | Z4: =IF(OR(Z3=1,R4<=資金模擬!$B$10),1,0)
A5: 3 | B5: 46289.8 | C5: 進場 | D5: 2 | E5: BROCCOLI_USDT_PERP | F5: 做空 | G5: 0.02867 | H5: 0.0278099 | I5: 0.0301035 | M5: =資金模擬!$B$5*V4 | N5: =IF(Z4=1,"已停止",IF(T4>=M5,"已下單","資金不足略過")) | O5: =IF(N5="已下單",M5*資金模擬!$B$7,0) | Q5: 0 | R5: =R4+Q5 | S5: =S4+IF(N5="已下單",M5,0) | T5: =R5-S5 | U5: =U4+IF(N5="已下單",1,0) | V5: =IF(資金模擬!$B$9=2,MAX(R5,0),MAX(V4,FLOOR(MAX(R5,0),資金模擬!$B$6))) | W5: =MAX(W4,R5) | X5: =IF(W5>0,R5/W5-1,-1) | Y5: =IF(R5>0,S5*資金模擬!$B$7/R5,0) | Z5: =IF(OR(Z4=1,R5<=資金模擬!$B$10),1,0)
A6: 4 | B6: 46289.81 | C6: 進場 | D6: 3 | E6: AGT_USDT_PERP | F6: 做空 | G6: 0.019584 | H6: 0.01899648 | I6: 0.0205632 | M6: =資金模擬!$B$5*V5 | N6: =IF(Z5=1,"已停止",IF(T5>=M6,"已下單","資金不足略過")) | O6: =IF(N6="已下單",M6*資金模擬!$B$7,0) | Q6: 0 | R6: =R5+Q6 | S6: =S5+IF(N6="已下單",M6,0) | T6: =R6-S6 | U6: =U5+IF(N6="已下單",1,0) | V6: =IF(資金模擬!$B$9=2,MAX(R6,0),MAX(V5,FLOOR(MAX(R6,0),資金模擬!$B$6))) | W6: =MAX(W5,R6) | X6: =IF(W6>0,R6/W6-1,-1) | Y6: =IF(R6>0,S6*資金模擬!$B$7/R6,0) | Z6: =IF(OR(Z5=1,R6<=資金模擬!$B$10),1,0)
A7: 5 | B7: 46289.835 | C7: 進場 | D7: 4 | E7: PHA_USDT_PERP | F7: 做空 | G7: 0.05098 | H7: 0.0494506 | I7: 0.053529 | M7: =資金模擬!$B$5*V6 | N7: =IF(Z6=1,"已停止",IF(T6>=M7,"已下單","資金不足略過")) | O7: =IF(N7="已下單",M7*資金模擬!$B$7,0) | Q7: 0 | R7: =R6+Q7 | S7: =S6+IF(N7="已下單",M7,0) | T7: =R7-S7 | U7: =U6+IF(N7="已下單",1,0) | V7: =IF(資金模擬!$B$9=2,MAX(R7,0),MAX(V6,FLOOR(MAX(R7,0),資金模擬!$B$6))) | W7: =MAX(W6,R7) | X7: =IF(W7>0,R7/W7-1,-1) | Y7: =IF(R7>0,S7*資金模擬!$B$7/R7,0) | Z7: =IF(OR(Z6=1,R7<=資金模擬!$B$10),1,0)
A8: 6 | B8: 46289.847 | C8: 出場 | D8: 4 | E8: PHA_USDT_PERP | F8: 做空 | G8: 0.05098 | H8: 0.0494506 | I8: 0.053529 | J8: 0.053529 | K8: 止損 | L8: =交易明細!K5 | M8: =M7 | N8: =N7 | O8: =O7 | P8: =交易明細!L5 | Q8: =IF(N8="已下單",O8*P8,0) | R8: =R7+Q8 | S8: =S7-IF(N8="已下單",M8,0) | T8: =R8-S8 | U8: =U7-IF(N8="已下單",1,0) | V8: =IF(資金模擬!$B$9=2,MAX(R8,0),MAX(V7,FLOOR(MAX(R8,0),資金模擬!$B$6))) | W8: =MAX(W7,R8) | X8: =IF(W8>0,R8/W8-1,-1) | Y8: =IF(R8>0,S8*資金模擬!$B$7/R8,0) | Z8: =IF(OR(Z7=1,R8<=資金模擬!$B$10),1,0)
A9: 7 | B9: 46289.853 | C9: 出場 | D9: 2 | E9: BROCCOLI_USDT_PERP | F9: 做空 | G9: 0.02867 | H9: 0.0278099 | I9: 0.0301035 | J9: 0.0301035 | K9: 止損 | L9: =交易明細!K3 | M9: =M5 | N9: =N5 | O9: =O5 | P9: =交易明細!L3 | Q9: =IF(N9="已下單",O9*P9,0) | R9: =R8+Q9 | S9: =S8-IF(N9="已下單",M9,0) | T9: =R9-S9 | U9: =U8-IF(N9="已下單",1,0) | V9: =IF(資金模擬!$B$9=2,MAX(R9,0),MAX(V8,FLOOR(MAX(R9,0),資金模擬!$B$6))) | W9: =MAX(W8,R9) | X9: =IF(W9>0,R9/W9-1,-1) | Y9: =IF(R9>0,S9*資金模擬!$B$7/R9,0) | Z9: =IF(OR(Z8=1,R9<=資金模擬!$B$10),1,0)
A10: 8 | B10: 46289.942 | C10: 進場 | D10: 5 | E10: BB_USDT_PERP | F10: 做空 | G10: 0.01095 | H10: 0.0106215 | I10: 0.0114975 | M10: =資金模擬!$B$5*V9 | N10: =IF(Z9=1,"已停止",IF(T9>=M10,"已下單","資金不足略過")) | O10: =IF(N10="已下單",M10*資金模擬!$B$7,0) | Q10: 0 | R10: =R9+Q10 | S10: =S9+IF(N10="已下單",M10,0) | T10: =R10-S10 | U10: =U9+IF(N10="已下單",1,0) | V10: =IF(資金模擬!$B$9=2,MAX(R10,0),MAX(V9,FLOOR(MAX(R10,0),資金模擬!$B$6))) | W10: =MAX(W9,R10) | X10: =IF(W10>0,R10/W10-1,-1) | Y10: =IF(R10>0,S10*資金模擬!$B$7/R10,0) | Z10: =IF(OR(Z9=1,R10<=資金模擬!$B$10),1,0)
A11: 9 | B11: 46289.974 | C11: 出場 | D11: 3 | E11: AGT_USDT_PERP | F11: 做空 | G11: 0.019584 | H11: 0.01899648 | I11: 0.0205632 | J11: 0.01899648 | K11: 止盈 | L11: =交易明細!K4 | M11: =M6 | N11: =N6 | O11: =O6 | P11: =交易明細!L4 | Q11: =IF(N11="已下單",O11*P11,0) | R11: =R10+Q11 | S11: =S10-IF(N11="已下單",M11,0) | T11: =R11-S11 | U11: =U10-IF(N11="已下單",1,0) | V11: =IF(資金模擬!$B$9=2,MAX(R11,0),MAX(V10,FLOOR(MAX(R11,0),資金模擬!$B$6))) | W11: =MAX(W10,R11) | X11: =IF(W11>0,R11/W11-1,-1) | Y11: =IF(R11>0,S11*資金模擬!$B$7/R11,0) | Z11: =IF(OR(Z10=1,R11<=資金模擬!$B$10),1,0)
A12: 10 | B12: 46289.992 | C12: 出場 | D12: 5 | E12: BB_USDT_PERP | F12: 做空 | G12: 0.01095 | H12: 0.0106215 | I12: 0.0114975 | J12: 0.0106215 | K12: 止盈 | L12: =交易明細!K6 | M12: =M10 | N12: =N10 | O12: =O10 | P12: =交易明細!L6 | Q12: =IF(N12="已下單",O12*P12,0) | R12: =R11+Q12 | S12: =S11-IF(N12="已下單",M12,0) | T12: =R12-S12 | U12: =U11-IF(N12="已下單",1,0) | V12: =IF(資金模擬!$B$9=2,MAX(R12,0),MAX(V11,FLOOR(MAX(R12,0),資金模擬!$B$6))) | W12: =MAX(W11,R12) | X12: =IF(W12>0,R12/W12-1,-1) | Y12: =IF(R12>0,S12*資金模擬!$B$7/R12,0) | Z12: =IF(OR(Z11=1,R12<=資金模擬!$B$10),1,0)
A13: 11 | B13: 46290.011 | C13: 進場 | D13: 6 | E13: RIVER_USDT_PERP | F13: 做空 | G13: 1.278 | H13: 1.23966 | I13: 1.3419 | M13: =資金模擬!$B$5*V12 | N13: =IF(Z12=1,"已停止",IF(T12>=M13,"已下單","資金不足略過")) | O13: =IF(N13="已下單",M13*資金模擬!$B$7,0) | Q13: 0 | R13: =R12+Q13 | S13: =S12+IF(N13="已下單",M13,0) | T13: =R13-S13 | U13: =U12+IF(N13="已下單",1,0) | V13: =IF(資金模擬!$B$9=2,MAX(R13,0),MAX(V12,FLOOR(MAX(R13,0),資金模擬!$B$6))) | W13: =MAX(W12,R13) | X13: =IF(W13>0,R13/W13-1,-1) | Y13: =IF(R13>0,S13*資金模擬!$B$7/R13,0) | Z13: =IF(OR(Z12=1,R13<=資金模擬!$B$10),1,0)
A14: 12 | B14: 46290.015 | C14: 進場 | D14: 7 | E14: LAB_USDT_PERP | F14: 做空 | G14: 0.06094 | H14: 0.0591118 | I14: 0.063987 | M14: =資金模擬!$B$5*V13 | N14: =IF(Z13=1,"已停止",IF(T13>=M14,"已下單","資金不足略過")) | O14: =IF(N14="已下單",M14*資金模擬!$B$7,0) | Q14: 0 | R14: =R13+Q14 | S14: =S13+IF(N14="已下單",M14,0) | T14: =R14-S14 | U14: =U13+IF(N14="已下單",1,0) | V14: =IF(資金模擬!$B$9=2,MAX(R14,0),MAX(V13,FLOOR(MAX(R14,0),資金模擬!$B$6))) | W14: =MAX(W13,R14) | X14: =IF(W14>0,R14/W14-1,-1) | Y14: =IF(R14>0,S14*資金模擬!$B$7/R14,0) | Z14: =IF(OR(Z13=1,R14<=資金模擬!$B$10),1,0)
A15: 13 | B15: 46290.264 | C15: 出場 | D15: 7 | E15: LAB_USDT_PERP | F15: 做空 | G15: 0.06094 | H15: 0.0591118 | I15: 0.063987 | J15: 0.0591118 | K15: 止盈 | L15: =交易明細!K8 | M15: =M14 | N15: =N14 | O15: =O14 | P15: =交易明細!L8 | Q15: =IF(N15="已下單",O15*P15,0) | R15: =R14+Q15 | S15: =S14-IF(N15="已下單",M15,0) | T15: =R15-S15 | U15: =U14-IF(N15="已下單",1,0) | V15: =IF(資金模擬!$B$9=2,MAX(R15,0),MAX(V14,FLOOR(MAX(R15,0),資金模擬!$B$6))) | W15: =MAX(W14,R15) | X15: =IF(W15>0,R15/W15-1,-1) | Y15: =IF(R15>0,S15*資金模擬!$B$7/R15,0) | Z15: =IF(OR(Z14=1,R15<=資金模擬!$B$10),1,0)
A16: 14 | B16: 46290.338 | C16: 進場 | D16: 8 | E16: SAGA_USDT_PERP | F16: 做空 | G16: 0.07862 | H16: 0.0762614 | I16: 0.082551 | M16: =資金模擬!$B$5*V15 | N16: =IF(Z15=1,"已停止",IF(T15>=M16,"已下單","資金不足略過")) | O16: =IF(N16="已下單",M16*資金模擬!$B$7,0) | Q16: 0 | R16: =R15+Q16 | S16: =S15+IF(N16="已下單",M16,0) | T16: =R16-S16 | U16: =U15+IF(N16="已下單",1,0) | V16: =IF(資金模擬!$B$9=2,MAX(R16,0),MAX(V15,FLOOR(MAX(R16,0),資金模擬!$B$6))) | W16: =MAX(W15,R16) | X16: =IF(W16>0,R16/W16-1,-1) | Y16: =IF(R16>0,S16*資金模擬!$B$7/R16,0) | Z16: =IF(OR(Z15=1,R16<=資金模擬!$B$10),1,0)
A17: 15 | B17: 46290.338 | C17: 出場 | D17: 8 | E17: SAGA_USDT_PERP | F17: 做空 | G17: 0.07862 | H17: 0.0762614 | I17: 0.082551 | J17: 0.0762614 | K17: 止盈 | L17: =交易明細!K9 | M17: =M16 | N17: =N16 | O17: =O16 | P17: =交易明細!L9 | Q17: =IF(N17="已下單",O17*P17,0) | R17: =R16+Q17 | S17: =S16-IF(N17="已下單",M17,0) | T17: =R17-S17 | U17: =U16-IF(N17="已下單",1,0) | V17: =IF(資金模擬!$B$9=2,MAX(R17,0),MAX(V16,FLOOR(MAX(R17,0),資金模擬!$B$6))) | W17: =MAX(W16,R17) | X17: =IF(W17>0,R17/W17-1,-1) | Y17: =IF(R17>0,S17*資金模擬!$B$7/R17,0) | Z17: =IF(OR(Z16=1,R17<=資金模擬!$B$10),1,0)
A18: 16 | B18: 46290.449 | C18: 出場 | D18: 6 | E18: RIVER_USDT_PERP | F18: 做空 | G18: 1.278 | H18: 1.23966 | I18: 1.3419 | J18: 1.23966 | K18: 止盈 | L18: =交易明細!K7 | M18: =M13 | N18: =N13 | O18: =O13 | P18: =交易明細!L7 | Q18: =IF(N18="已下單",O18*P18,0) | R18: =R17+Q18 | S18: =S17-IF(N18="已下單",M18,0) | T18: =R18-S18 | U18: =U17-IF(N18="已下單",1,0) | V18: =IF(資金模擬!$B$9=2,MAX(R18,0),MAX(V17,FLOOR(MAX(R18,0),資金模擬!$B$6))) | W18: =MAX(W17,R18) | X18: =IF(W18>0,R18/W18-1,-1) | Y18: =IF(R18>0,S18*資金模擬!$B$7/R18,0) | Z18: =IF(OR(Z17=1,R18<=資金模擬!$B$10),1,0)
A19: 17 | B19: 46290.456 | C19: 進場 | D19: 9 | E19: PLAY_USDT_PERP | F19: 做空 | G19: 0.04057 | H19: 0.0393529 | I19: 0.0425985 | M19: =資金模擬!$B$5*V18 | N19: =IF(Z18=1,"已停止",IF(T18>=M19,"已下單","資金不足略過")) | O19: =IF(N19="已下單",M19*資金模擬!$B$7,0) | Q19: 0 | R19: =R18+Q19 | S19: =S18+IF(N19="已下單",M19,0) | T19: =R19-S19 | U19: =U18+IF(N19="已下單",1,0) | V19: =IF(資金模擬!$B$9=2,MAX(R19,0),MAX(V18,FLOOR(MAX(R19,0),資金模擬!$B$6))) | W19: =MAX(W18,R19) | X19: =IF(W19>0,R19/W19-1,-1) | Y19: =IF(R19>0,S19*資金模擬!$B$7/R19,0) | Z19: =IF(OR(Z18=1,R19<=資金模擬!$B$10),1,0)
A20: 18 | B20: 46290.483 | C20: 出場 | D20: 9 | E20: PLAY_USDT_PERP | F20: 做空 | G20: 0.04057 | H20: 0.0393529 | I20: 0.0425985 | J20: 0.0393529 | K20: 止盈 | L20: =交易明細!K10 | M20: =M19 | N20: =N19 | O20: =O19 | P20: =交易明細!L10 | Q20: =IF(N20="已下單",O20*P20,0) | R20: =R19+Q20 | S20: =S19-IF(N20="已下單",M20,0) | T20: =R20-S20 | U20: =U19-IF(N20="已下單",1,0) | V20: =IF(資金模擬!$B$9=2,MAX(R20,0),MAX(V19,FLOOR(MAX(R20,0),資金模擬!$B$6))) | W20: =MAX(W19,R20) | X20: =IF(W20>0,R20/W20-1,-1) | Y20: =IF(R20>0,S20*資金模擬!$B$7/R20,0) | Z20: =IF(OR(Z19=1,R20<=資金模擬!$B$10),1,0)
A21: 19 | B21: 46290.544 | C21: 進場 | D21: 10 | E21: MOVR_USDT_PERP | F21: 做空 | G21: 0.974 | H21: 0.94478 | I21: 1.0227 | M21: =資金模擬!$B$5*V20 | N21: =IF(Z20=1,"已停止",IF(T20>=M21,"已下單","資金不足略過")) | O21: =IF(N21="已下單",M21*資金模擬!$B$7,0) | Q21: 0 | R21: =R20+Q21 | S21: =S20+IF(N21="已下單",M21,0) | T21: =R21-S21 | U21: =U20+IF(N21="已下單",1,0) | V21: =IF(資金模擬!$B$9=2,MAX(R21,0),MAX(V20,FLOOR(MAX(R21,0),資金模擬!$B$6))) | W21: =MAX(W20,R21) | X21: =IF(W21>0,R21/W21-1,-1) | Y21: =IF(R21>0,S21*資金模擬!$B$7/R21,0) | Z21: =IF(OR(Z20=1,R21<=資金模擬!$B$10),1,0)
A22: 20 | B22: 46290.558 | C22: 出場 | D22: 10 | E22: MOVR_USDT_PERP | F22: 做空 | G22: 0.974 | H22: 0.94478 | I22: 1.0227 | J22: 0.94478 | K22: 止盈 | L22: =交易明細!K11 | M22: =M21 | N22: =N21 | O22: =O21 | P22: =交易明細!L11 | Q22: =IF(N22="已下單",O22*P22,0) | R22: =R21+Q22 | S22: =S21-IF(N22="已下單",M22,0) | T22: =R22-S22 | U22: =U21-IF(N22="已下單",1,0) | V22: =IF(資金模擬!$B$9=2,MAX(R22,0),MAX(V21,FLOOR(MAX(R22,0),資金模擬!$B$6))) | W22: =MAX(W21,R22) | X22: =IF(W22>0,R22/W22-1,-1) | Y22: =IF(R22>0,S22*資金模擬!$B$7/R22,0) | Z22: =IF(OR(Z21=1,R22<=資金模擬!$B$10),1,0)
A23: 21 | B23: 46290.643 | C23: 進場 | D23: 11 | E23: PHA_USDT_PERP | F23: 做空 | G23: 0.05717 | H23: 0.0554549 | I23: 0.0600285 | M23: =資金模擬!$B$5*V22 | N23: =IF(Z22=1,"已停止",IF(T22>=M23,"已下單","資金不足略過")) | O23: =IF(N23="已下單",M23*資金模擬!$B$7,0) | Q23: 0 | R23: =R22+Q23 | S23: =S22+IF(N23="已下單",M23,0) | T23: =R23-S23 | U23: =U22+IF(N23="已下單",1,0) | V23: =IF(資金模擬!$B$9=2,MAX(R23,0),MAX(V22,FLOOR(MAX(R23,0),資金模擬!$B$6))) | W23: =MAX(W22,R23) | X23: =IF(W23>0,R23/W23-1,-1) | Y23: =IF(R23>0,S23*資金模擬!$B$7/R23,0) | Z23: =IF(OR(Z22=1,R23<=資金模擬!$B$10),1,0)
A24: 22 | B24: 46290.665 | C24: 出場 | D24: 11 | E24: PHA_USDT_PERP | F24: 做空 | G24: 0.05717 | H24: 0.0554549 | I24: 0.0600285 | J24: 0.0554549 | K24: 止盈 | L24: =交易明細!K12 | M24: =M23 | N24: =N23 | O24: =O23 | P24: =交易明細!L12 | Q24: =IF(N24="已下單",O24*P24,0) | R24: =R23+Q24 | S24: =S23-IF(N24="已下單",M24,0) | T24: =R24-S24 | U24: =U23-IF(N24="已下單",1,0) | V24: =IF(資金模擬!$B$9=2,MAX(R24,0),MAX(V23,FLOOR(MAX(R24,0),資金模擬!$B$6))) | W24: =MAX(W23,R24) | X24: =IF(W24>0,R24/W24-1,-1) | Y24: =IF(R24>0,S24*資金模擬!$B$7/R24,0) | Z24: =IF(OR(Z23=1,R24<=資金模擬!$B$10),1,0)
A25: 23 | B25: 46290.677 | C25: 進場 | D25: 12 | E25: CASHCAT_USDT_PERP | F25: 做空 | G25: 0.1726 | H25: 0.167422 | I25: 0.18123 | M25: =資金模擬!$B$5*V24 | N25: =IF(Z24=1,"已停止",IF(T24>=M25,"已下單","資金不足略過")) | O25: =IF(N25="已下單",M25*資金模擬!$B$7,0) | Q25: 0 | R25: =R24+Q25 | S25: =S24+IF(N25="已下單",M25,0) | T25: =R25-S25 | U25: =U24+IF(N25="已下單",1,0) | V25: =IF(資金模擬!$B$9=2,MAX(R25,0),MAX(V24,FLOOR(MAX(R25,0),資金模擬!$B$6))) | W25: =MAX(W24,R25) | X25: =IF(W25>0,R25/W25-1,-1) | Y25: =IF(R25>0,S25*資金模擬!$B$7/R25,0) | Z25: =IF(OR(Z24=1,R25<=資金模擬!$B$10),1,0)
A26: 24 | B26: 46290.76 | C26: 出場 | D26: 12 | E26: CASHCAT_USDT_PERP | F26: 做空 | G26: 0.1726 | H26: 0.167422 | I26: 0.18123 | J26: 0.18123 | K26: 止損 | L26: =交易明細!K13 | M26: =M25 | N26: =N25 | O26: =O25 | P26: =交易明細!L13 | Q26: =IF(N26="已下單",O26*P26,0) | R26: =R25+Q26 | S26: =S25-IF(N26="已下單",M26,0) | T26: =R26-S26 | U26: =U25-IF(N26="已下單",1,0) | V26: =IF(資金模擬!$B$9=2,MAX(R26,0),MAX(V25,FLOOR(MAX(R26,0),資金模擬!$B$6))) | W26: =MAX(W25,R26) | X26: =IF(W26>0,R26/W26-1,-1) | Y26: =IF(R26>0,S26*資金模擬!$B$7/R26,0) | Z26: =IF(OR(Z25=1,R26<=資金模擬!$B$10),1,0)
A27: 25 | B27: 46290.842 | C27: 進場 | D27: 13 | E27: MUBARAK_USDT_PERP | F27: 做空 | G27: 0.04613 | H27: 0.0447461 | I27: 0.0484365 | M27: =資金模擬!$B$5*V26 | N27: =IF(Z26=1,"已停止",IF(T26>=M27,"已下單","資金不足略過")) | O27: =IF(N27="已下單",M27*資金模擬!$B$7,0) | Q27: 0 | R27: =R26+Q27 | S27: =S26+IF(N27="已下單",M27,0) | T27: =R27-S27 | U27: =U26+IF(N27="已下單",1,0) | V27: =IF(資金模擬!$B$9=2,MAX(R27,0),MAX(V26,FLOOR(MAX(R27,0),資金模擬!$B$6))) | W27: =MAX(W26,R27) | X27: =IF(W27>0,R27/W27-1,-1) | Y27: =IF(R27>0,S27*資金模擬!$B$7/R27,0) | Z27: =IF(OR(Z26=1,R27<=資金模擬!$B$10),1,0)
A28: 26 | B28: 46290.869 | C28: 出場 | D28: 13 | E28: MUBARAK_USDT_PERP | F28: 做空 | G28: 0.04613 | H28: 0.0447461 | I28: 0.0484365 | J28: 0.0447461 | K28: 止盈 | L28: =交易明細!K14 | M28: =M27 | N28: =N27 | O28: =O27 | P28: =交易明細!L14 | Q28: =IF(N28="已下單",O28*P28,0) | R28: =R27+Q28 | S28: =S27-IF(N28="已下單",M28,0) | T28: =R28-S28 | U28: =U27-IF(N28="已下單",1,0) | V28: =IF(資金模擬!$B$9=2,MAX(R28,0),MAX(V27,FLOOR(MAX(R28,0),資金模擬!$B$6))) | W28: =MAX(W27,R28) | X28: =IF(W28>0,R28/W28-1,-1) | Y28: =IF(R28>0,S28*資金模擬!$B$7/R28,0) | Z28: =IF(OR(Z27=1,R28<=資金模擬!$B$10),1,0)
A29: 27 | B29: 46290.969 | C29: 進場 | D29: 14 | E29: MOVR_USDT_PERP | F29: 做空 | G29: 1.119 | H29: 1.08543 | I29: 1.17495 | M29: =資金模擬!$B$5*V28 | N29: =IF(Z28=1,"已停止",IF(T28>=M29,"已下單","資金不足略過")) | O29: =IF(N29="已下單",M29*資金模擬!$B$7,0) | Q29: 0 | R29: =R28+Q29 | S29: =S28+IF(N29="已下單",M29,0) | T29: =R29-S29 | U29: =U28+IF(N29="已下單",1,0) | V29: =IF(資金模擬!$B$9=2,MAX(R29,0),MAX(V28,FLOOR(MAX(R29,0),資金模擬!$B$6))) | W29: =MAX(W28,R29) | X29: =IF(W29>0,R29/W29-1,-1) | Y29: =IF(R29>0,S29*資金模擬!$B$7/R29,0) | Z29: =IF(OR(Z28=1,R29<=資金模擬!$B$10),1,0)
A30: 28 | B30: 46290.974 | C30: 出場 | D30: 14 | E30: MOVR_USDT_PERP | F30: 做空 | G30: 1.119 | H30: 1.08543 | I30: 1.17495 | J30: 1.08543 | K30: 止盈 | L30: =交易明細!K15 | M30: =M29 | N30: =N29 | O30: =O29 | P30: =交易明細!L15 | Q30: =IF(N30="已下單",O30*P30,0) | R30: =R29+Q30 | S30: =S29-IF(N30="已下單",M30,0) | T30: =R30-S30 | U30: =U29-IF(N30="已下單",1,0) | V30: =IF(資金模擬!$B$9=2,MAX(R30,0),MAX(V29,FLOOR(MAX(R30,0),資金模擬!$B$6))) | W30: =MAX(W29,R30) | X30: =IF(W30>0,R30/W30-1,-1) | Y30: =IF(R30>0,S30*資金模擬!$B$7/R30,0) | Z30: =IF(OR(Z29=1,R30<=資金模擬!$B$10),1,0)
A31: 29 | B31: 46291.007 | C31: 進場 | D31: 15 | E31: LYN_USDT_PERP | F31: 做空 | G31: 0.04478 | H31: 0.0434366 | I31: 0.047019 | M31: =資金模擬!$B$5*V30 | N31: =IF(Z30=1,"已停止",IF(T30>=M31,"已下單","資金不足略過")) | O31: =IF(N31="已下單",M31*資金模擬!$B$7,0) | Q31: 0 | R31: =R30+Q31 | S31: =S30+IF(N31="已下單",M31,0) | T31: =R31-S31 | U31: =U30+IF(N31="已下單",1,0) | V31: =IF(資金模擬!$B$9=2,MAX(R31,0),MAX(V30,FLOOR(MAX(R31,0),資金模擬!$B$6))) | W31: =MAX(W30,R31) | X31: =IF(W31>0,R31/W31-1,-1) | Y31: =IF(R31>0,S31*資金模擬!$B$7/R31,0) | Z31: =IF(OR(Z30=1,R31<=資金模擬!$B$10),1,0)
A32: 30 | B32: 46291.008 | C32: 出場 | D32: 15 | E32: LYN_USDT_PERP | F32: 做空 | G32: 0.04478 | H32: 0.0434366 | I32: 0.047019 | J32: 0.0434366 | K32: 止盈 | L32: =交易明細!K16 | M32: =M31 | N32: =N31 | O32: =O31 | P32: =交易明細!L16 | Q32: =IF(N32="已下單",O32*P32,0) | R32: =R31+Q32 | S32: =S31-IF(N32="已下單",M32,0) | T32: =R32-S32 | U32: =U31-IF(N32="已下單",1,0) | V32: =IF(資金模擬!$B$9=2,MAX(R32,0),MAX(V31,FLOOR(MAX(R32,0),資金模擬!$B$6))) | W32: =MAX(W31,R32) | X32: =IF(W32>0,R32/W32-1,-1) | Y32: =IF(R32>0,S32*資金模擬!$B$7/R32,0) | Z32: =IF(OR(Z31=1,R32<=資金模擬!$B$10),1,0)
A33: 31 | B33: 46291.008 | C33: 進場 | D33: 16 | E33: SPK_USDT_PERP | F33: 做空 | G33: 0.0245 | H33: 0.023765 | I33: 0.025725 | M33: =資金模擬!$B$5*V32 | N33: =IF(Z32=1,"已停止",IF(T32>=M33,"已下單","資金不足略過")) | O33: =IF(N33="已下單",M33*資金模擬!$B$7,0) | Q33: 0 | R33: =R32+Q33 | S33: =S32+IF(N33="已下單",M33,0) | T33: =R33-S33 | U33: =U32+IF(N33="已下單",1,0) | V33: =IF(資金模擬!$B$9=2,MAX(R33,0),MAX(V32,FLOOR(MAX(R33,0),資金模擬!$B$6))) | W33: =MAX(W32,R33) | X33: =IF(W33>0,R33/W33-1,-1) | Y33: =IF(R33>0,S33*資金模擬!$B$7/R33,0) | Z33: =IF(OR(Z32=1,R33<=資金模擬!$B$10),1,0)
A34: 32 | B34: 46291.018 | C34: 出場 | D34: 16 | E34: SPK_USDT_PERP | F34: 做空 | G34: 0.0245 | H34: 0.023765 | I34: 0.025725 | J34: 0.025725 | K34: 止損 | L34: =交易明細!K17 | M34: =M33 | N34: =N33 | O34: =O33 | P34: =交易明細!L17 | Q34: =IF(N34="已下單",O34*P34,0) | R34: =R33+Q34 | S34: =S33-IF(N34="已下單",M34,0) | T34: =R34-S34 | U34: =U33-IF(N34="已下單",1,0) | V34: =IF(資金模擬!$B$9=2,MAX(R34,0),MAX(V33,FLOOR(MAX(R34,0),資金模擬!$B$6))) | W34: =MAX(W33,R34) | X34: =IF(W34>0,R34/W34-1,-1) | Y34: =IF(R34>0,S34*資金模擬!$B$7/R34,0) | Z34: =IF(OR(Z33=1,R34<=資金模擬!$B$10),1,0)
A35: 33 | B35: 46291.05 | C35: 進場 | D35: 17 | E35: LYN_USDT_PERP | F35: 做空 | G35: 0.07316 | H35: 0.0709652 | I35: 0.076818 | M35: =資金模擬!$B$5*V34 | N35: =IF(Z34=1,"已停止",IF(T34>=M35,"已下單","資金不足略過")) | O35: =IF(N35="已下單",M35*資金模擬!$B$7,0) | Q35: 0 | R35: =R34+Q35 | S35: =S34+IF(N35="已下單",M35,0) | T35: =R35-S35 | U35: =U34+IF(N35="已下單",1,0) | V35: =IF(資金模擬!$B$9=2,MAX(R35,0),MAX(V34,FLOOR(MAX(R35,0),資金模擬!$B$6))) | W35: =MAX(W34,R35) | X35: =IF(W35>0,R35/W35-1,-1) | Y35: =IF(R35>0,S35*資金模擬!$B$7/R35,0) | Z35: =IF(OR(Z34=1,R35<=資金模擬!$B$10),1,0)
A36: 34 | B36: 46291.051 | C36: 出場 | D36: 17 | E36: LYN_USDT_PERP | F36: 做空 | G36: 0.07316 | H36: 0.0709652 | I36: 0.076818 | J36: 0.0709652 | K36: 止盈 | L36: =交易明細!K18 | M36: =M35 | N36: =N35 | O36: =O35 | P36: =交易明細!L18 | Q36: =IF(N36="已下單",O36*P36,0) | R36: =R35+Q36 | S36: =S35-IF(N36="已下單",M36,0) | T36: =R36-S36 | U36: =U35-IF(N36="已下單",1,0) | V36: =IF(資金模擬!$B$9=2,MAX(R36,0),MAX(V35,FLOOR(MAX(R36,0),資金模擬!$B$6))) | W36: =MAX(W35,R36) | X36: =IF(W36>0,R36/W36-1,-1) | Y36: =IF(R36>0,S36*資金模擬!$B$7/R36,0) | Z36: =IF(OR(Z35=1,R36<=資金模擬!$B$10),1,0)
A37: 35 | B37: 46291.592 | C37: 進場 | D37: 18 | E37: 2Z_USDT_PERP | F37: 做空 | G37: 0.06309 | H37: 0.0611973 | I37: 0.0662445 | M37: =資金模擬!$B$5*V36 | N37: =IF(Z36=1,"已停止",IF(T36>=M37,"已下單","資金不足略過")) | O37: =IF(N37="已下單",M37*資金模擬!$B$7,0) | Q37: 0 | R37: =R36+Q37 | S37: =S36+IF(N37="已下單",M37,0) | T37: =R37-S37 | U37: =U36+IF(N37="已下單",1,0) | V37: =IF(資金模擬!$B$9=2,MAX(R37,0),MAX(V36,FLOOR(MAX(R37,0),資金模擬!$B$6))) | W37: =MAX(W36,R37) | X37: =IF(W37>0,R37/W37-1,-1) | Y37: =IF(R37>0,S37*資金模擬!$B$7/R37,0) | Z37: =IF(OR(Z36=1,R37<=資金模擬!$B$10),1,0)
A38: 36 | B38: 46291.595 | C38: 出場 | D38: 18 | E38: 2Z_USDT_PERP | F38: 做空 | G38: 0.06309 | H38: 0.0611973 | I38: 0.0662445 | J38: 0.0662445 | K38: 止損 | L38: =交易明細!K19 | M38: =M37 | N38: =N37 | O38: =O37 | P38: =交易明細!L19 | Q38: =IF(N38="已下單",O38*P38,0) | R38: =R37+Q38 | S38: =S37-IF(N38="已下單",M38,0) | T38: =R38-S38 | U38: =U37-IF(N38="已下單",1,0) | V38: =IF(資金模擬!$B$9=2,MAX(R38,0),MAX(V37,FLOOR(MAX(R38,0),資金模擬!$B$6))) | W38: =MAX(W37,R38) | X38: =IF(W38>0,R38/W38-1,-1) | Y38: =IF(R38>0,S38*資金模擬!$B$7/R38,0) | Z38: =IF(OR(Z37=1,R38<=資金模擬!$B$10),1,0)
A39: 37 | B39: 46291.628 | C39: 進場 | D39: 19 | E39: Q_USDT_PERP | F39: 做空 | G39: 0.03002 | H39: 0.0291194 | I39: 0.031521 | M39: =資金模擬!$B$5*V38 | N39: =IF(Z38=1,"已停止",IF(T38>=M39,"已下單","資金不足略過")) | O39: =IF(N39="已下單",M39*資金模擬!$B$7,0) | Q39: 0 | R39: =R38+Q39 | S39: =S38+IF(N39="已下單",M39,0) | T39: =R39-S39 | U39: =U38+IF(N39="已下單",1,0) | V39: =IF(資金模擬!$B$9=2,MAX(R39,0),MAX(V38,FLOOR(MAX(R39,0),資金模擬!$B$6))) | W39: =MAX(W38,R39) | X39: =IF(W39>0,R39/W39-1,-1) | Y39: =IF(R39>0,S39*資金模擬!$B$7/R39,0) | Z39: =IF(OR(Z38=1,R39<=資金模擬!$B$10),1,0)
A40: 38 | B40: 46291.642 | C40: 出場 | D40: 19 | E40: Q_USDT_PERP | F40: 做空 | G40: 0.03002 | H40: 0.0291194 | I40: 0.031521 | J40: 0.031521 | K40: 止損 | L40: =交易明細!K20 | M40: =M39 | N40: =N39 | O40: =O39 | P40: =交易明細!L20 | Q40: =IF(N40="已下單",O40*P40,0) | R40: =R39+Q40 | S40: =S39-IF(N40="已下單",M40,0) | T40: =R40-S40 | U40: =U39-IF(N40="已下單",1,0) | V40: =IF(資金模擬!$B$9=2,MAX(R40,0),MAX(V39,FLOOR(MAX(R40,0),資金模擬!$B$6))) | W40: =MAX(W39,R40) | X40: =IF(W40>0,R40/W40-1,-1) | Y40: =IF(R40>0,S40*資金模擬!$B$7/R40,0) | Z40: =IF(OR(Z39=1,R40<=資金模擬!$B$10),1,0)
...

Sheet 參數
A1: 項目 | B1: 數值 | C1: 說明
A2: 市場 | B2: PERP | C2: PERP=永續合約 / SPOT=現貨
A3: 回測區間 | B3: 2026-09-01 00:00 ~ 2026-10-07 22:02（Dry Run） | C3: 台北時間
A4: K棒週期 | B4: 條件看 1 小時K（整點切）；進出場用 1 分K | C4: 每根 1 分K 收盤檢查一次 ≈ 每分鐘掃描
A5: 止盈 | B5: 0.03 | C5: 做空：價格下跌此比例
A6: 止損 | B6: 0.05 | C6: 做空：價格上漲此比例（= 群組第 1 次加倉點）
A7: 單邊手續費 | B7: 0.0005 | C7: 進場、出場各扣一次（可直接改此格，報酬率會重算）
A8: 策略 | B8: 策略5 — 群組訊號複製（只做空） | C8: 目標是複製群組訊號，不是追求勝率
A9: ① 前根收盤比開盤漲 | B9: 0.06 | C9: 前一根 1h K：收盤 ÷ 開盤 − 1
A10: ②A 當根量 ÷ 前一根量 | B10: 2 倍 | C10: 本小時到目前為止的累計量，不限時；A 與限時分支符合任一即可
A11: ② 限時分支 | B11: 30 分內 ≥ 1 倍、15 分內 ≥ 0.5 倍 | C11: 開盤 N 分內（1 分K 收盤 ≤ 第 N 分）累計量曾達門檻，成立後本小時都算（黏著）
A12: ③ 現價 > 前高 × | B12: 1 | C12: 現價 = 那根 1 分K 收盤價
A13: 進場時機 | B13: 三條件第一次同時成立 | C13: 以那根 1 分K 收盤價進場；同幣每小時最多一次；持倉中不重複進場（與群組機器人一致）
A14: 出場後冷卻 | B14: 1 根 | C14: 出場的下一根 1 分K 起可再進場（須不同小時）
A15: 同根雙觸發 | B15: 保守計止損 | C15: 1 分K 已是最小週期
A16: 盈虧平衡勝率 | B16: =IFERROR(AVERAGE(交易明細!$AC$2:$AC$73),(B6+2*B7)/(B5+B6)) | C16: 含手續費，各筆平均；勝率低於此值 = 長期虧損

Sheet 交易明細
A1: 編號 | B1: 交易對 | C1: 方向 | D1: 進場時間 | E1: 進場價 | F1: 止盈價 | G1: 止損價 | H1: 出場時間 | I1: 出場價 | J1: 結果 | K1: 持倉小時 | L1: 報酬率(含費) | M1: 判定說明 | N1: 前一根漲跌幅 | O1: ATR% | P1: 價格vsMA20 | Q1: OBV 20h變化 | R1: 24h成交額(USDT) | S1: 最大有利(MFE) | T1: 最大不利(MAE) | U1: 量比 | V1: 收盤強度 | W1: 長週期趨勢(順勢) | X1: 24h漲跌(順勢) | Y1: BTC 1h漲跌(順勢) | Z1: BTC vs MA20(順勢) | AA1: 止盈% | AB1: 止損% | AC1: 盈虧平衡勝率 | AD1: ① 前根收盤比開盤 | AE1: ② 觸發時量倍數 | AF1: ② 爆量分支 | AG1: ③ 進場價vs前高 | AH1: 觸發於第幾分鐘
A2: 1 | B2: NOM_USDT_PERP | C2: 做空 | D2: 46289.595 | E2: 0.002779 | F2: 0.00269563 | G2: 0.00291795 | H2: 46289.6 | I2: 0.00269563 | J2: 止盈 | K2: =(H2-D2)*24 | L2: =IF(C2="做多",I2/E2-1,1-I2/E2)-2*參數!$B$7 | S2: 0.03 | T2: 0.011874775 | AA2: 0.03 | AB2: 0.05 | AC2: =(AB2+2*參數!$B$7)/(AA2+AB2) | AD2: 0.15956989 | AE2: 0.79010932 | AF2: 15分0.5倍 | AG2: 0.0076142132 | AH2: 17
A3: 2 | B3: BROCCOLI_USDT_PERP | C3: 做空 | D3: 46289.8 | E3: 0.02867 | F3: 0.0278099 | G3: 0.0301035 | H3: 46289.853 | I3: 0.0301035 | J3: 止損 | K3: =(H3-D3)*24 | L3: =IF(C3="做多",I3/E3-1,1-I3/E3)-2*參數!$B$7 | S3: 0.027903732 | T3: 0.05 | AA3: 0.03 | AB3: 0.05 | AC3: =(AB3+2*參數!$B$7)/(AA3+AB3) | AD3: 0.12033694 | AE3: 0.62192962 | AF3: 15分0.5倍 | AG3: 0.0073787772 | AH3: 12
A4: 3 | B4: AGT_USDT_PERP | C4: 做空 | D4: 46289.81 | E4: 0.019584 | F4: 0.01899648 | G4: 0.0205632 | H4: 46289.974 | I4: 0.01899648 | J4: 止盈 | K4: =(H4-D4)*24 | L4: =IF(C4="做多",I4/E4-1,1-I4/E4)-2*參數!$B$7 | S4: 0.03 | T4: 0.017105801 | AA4: 0.03 | AB4: 0.05 | AC4: =(AB4+2*參數!$B$7)/(AA4+AB4) | AD4: 0.060287975 | AE4: 1.0190972 | AF4: 30分1倍 | AG4: 0.01329746 | AH4: 27
A5: 4 | B5: PHA_USDT_PERP | C5: 做空 | D5: 46289.835 | E5: 0.05098 | F5: 0.0494506 | G5: 0.053529 | H5: 46289.847 | I5: 0.053529 | J5: 止損 | K5: =(H5-D5)*24 | L5: =IF(C5="做多",I5/E5-1,1-I5/E5)-2*參數!$B$7 | S5: 0.0029423303 | T5: 0.05 | AA5: 0.03 | AB5: 0.05 | AC5: =(AB5+2*參數!$B$7)/(AA5+AB5) | AD5: 0.06299707 | AE5: 0.73042979 | AF5: 15分0.5倍 | AG5: 0.00019619384 | AH5: 3
A6: 5 | B6: BB_USDT_PERP | C6: 做空 | D6: 46289.942 | E6: 0.01095 | F6: 0.0106215 | G6: 0.0114975 | H6: 46289.992 | I6: 0.0106215 | J6: 止盈 | K6: =(H6-D6)*24 | L6: =IF(C6="做多",I6/E6-1,1-I6/E6)-2*參數!$B$7 | S6: 0.03 | T6: 0.039269406 | AA6: 0.03 | AB6: 0.05 | AC6: =(AB6+2*參數!$B$7)/(AA6+AB6) | AD6: 0.071570577 | AE6: 2.437114 | AF6: 2倍 | AG6: 0.013888889 | AH6: 37
A7: 6 | B7: RIVER_USDT_PERP | C7: 做空 | D7: 46290.011 | E7: 1.278 | F7: 1.23966 | G7: 1.3419 | H7: 46290.449 | I7: 1.23966 | J7: 止盈 | K7: =(H7-D7)*24 | L7: =IF(C7="做多",I7/E7-1,1-I7/E7)-2*參數!$B$7 | S7: 0.03 | T7: 0.044600939 | AA7: 0.03 | AB7: 0.05 | AC7: =(AB7+2*參數!$B$7)/(AA7+AB7) | AD7: 0.066889632 | AE7: 1.9126298 | AF7: 30分1倍+15分0.5倍 | AG7: 0.0015673981 | AH7: 16
A8: 7 | B8: LAB_USDT_PERP | C8: 做空 | D8: 46290.015 | E8: 0.06094 | F8: 0.0591118 | G8: 0.063987 | H8: 46290.264 | I8: 0.0591118 | J8: 止盈 | K8: =(H8-D8)*24 | L8: =IF(C8="做多",I8/E8-1,1-I8/E8)-2*參數!$B$7 | S8: 0.03 | T8: 0.038070233 | AA8: 0.03 | AB8: 0.05 | AC8: =(AB8+2*參數!$B$7)/(AA8+AB8) | AD8: 0.065639769 | AE8: 0.66446947 | AF8: 15分0.5倍 | AG8: 0.00032829941 | AH8: 21
A9: 8 | B9: SAGA_USDT_PERP | C9: 做空 | D9: 46290.338 | E9: 0.07862 | F9: 0.0762614 | G9: 0.082551 | H9: 46290.338 | I9: 0.0762614 | J9: 止盈 | K9: =(H9-D9)*24 | L9: =IF(C9="做多",I9/E9-1,1-I9/E9)-2*參數!$B$7 | S9: 0.03 | T9: 0 | AA9: 0.03 | AB9: 0.05 | AC9: =(AB9+2*參數!$B$7)/(AA9+AB9) | AD9: 0.07787302 | AE9: 0.55429073 | AF9: 15分0.5倍 | AG9: 0.032707211 | AH9: 6
A10: 9 | B10: PLAY_USDT_PERP | C10: 做空 | D10: 46290.456 | E10: 0.04057 | F10: 0.0393529 | G10: 0.0425985 | H10: 46290.483 | I10: 0.0393529 | J10: 止盈 | K10: =(H10-D10)*24 | L10: =IF(C10="做多",I10/E10-1,1-I10/E10)-2*參數!$B$7 | S10: 0.03 | T10: 0.019472517 | AA10: 0.03 | AB10: 0.05 | AC10: =(AB10+2*參數!$B$7)/(AA10+AB10) | AD10: 0.064447403 | AE10: 2.466725 | AF10: 2倍 | AG10: 0.00024654832 | AH10: 56
A11: 10 | B11: MOVR_USDT_PERP | C11: 做空 | D11: 46290.544 | E11: 0.974 | F11: 0.94478 | G11: 1.0227 | H11: 46290.558 | I11: 0.94478 | J11: 止盈 | K11: =(H11-D11)*24 | L11: =IF(C11="做多",I11/E11-1,1-I11/E11)-2*參數!$B$7 | S11: 0.03 | T11: 0.016427105 | AA11: 0.03 | AB11: 0.05 | AC11: =(AB11+2*參數!$B$7)/(AA11+AB11) | AD11: 0.072302558 | AE11: 0.69748874 | AF11: 15分0.5倍 | AG11: 0.0072388831 | AH11: 3
A12: 11 | B12: PHA_USDT_PERP | C12: 做空 | D12: 46290.643 | E12: 0.05717 | F12: 0.0554549 | G12: 0.0600285 | H12: 46290.665 | I12: 0.0554549 | J12: 止盈 | K12: =(H12-D12)*24 | L12: =IF(C12="做多",I12/E12-1,1-I12/E12)-2*參數!$B$7 | S12: 0.03 | T12: 0.027811789 | AA12: 0.03 | AB12: 0.05 | AC12: =(AB12+2*參數!$B$7)/(AA12+AB12) | AD12: 0.060475566 | AE12: 1.0173326 | AF12: 30分1倍 | AG12: 0.0014012962 | AH12: 26
A13: 12 | B13: CASHCAT_USDT_PERP | C13: 做空 | D13: 46290.677 | E13: 0.1726 | F13: 0.167422 | G13: 0.18123 | H13: 46290.76 | I13: 0.18123 | J13: 止損 | K13: =(H13-D13)*24 | L13: =IF(C13="做多",I13/E13-1,1-I13/E13)-2*參數!$B$7 | S13: 0.0086906141 | T13: 0.05 | AA13: 0.03 | AB13: 0.05 | AC13: =(AB13+2*參數!$B$7)/(AA13+AB13) | AD13: 0.065748278 | AE13: 0.51287376 | AF13: 15分0.5倍 | AG13: 0.0093567251 | AH13: 15
... A73: 72 | B73: MAGIC_USDT_PERP | C73: 做空 | D73: 46302.256 | E73: 0.0727 | F73: 0.070519 | G73: 0.076335 | H73: 46302.258 | I73: 0.070519 | J73: 止盈 | K73: =(H73-D73)*24 | L73: =IF(C73="做多",I73/E73-1,1-I73/E73)-2*參數!$B$7 | S73: 0.03 | T73: 0 | AA73: 0.03 | AB73: 0.05 | AC73: =(AB73+2*參數!$B$7)/(AA73+AB73) | AD73: 0.061011905 | AE73: 0.51641819 | AF73: 15分0.5倍 | AG73: 0.018207283 | AH73: 9

Sheet 幣種統計
A1: 交易對 | B1: 總筆數 | C1: 做多 | D1: 做空 | E1: 已平倉 | F1: 止盈 | G1: 止損 | H1: 勝率 | I1: 平均報酬/筆 | J1: 累計報酬 | K1: 平均持倉h | L1: 未平倉
A2: US_USDT_PERP | B2: =COUNTIFS(交易明細!$B$2:$B$73,$A2) | C2: =COUNTIFS(交易明細!$B$2:$B$73,$A2,交易明細!$C$2:$C$73,"做多") | D2: =COUNTIFS(交易明細!$B$2:$B$73,$A2,交易明細!$C$2:$C$73,"做空") | E2: =F2+G2+COUNTIFS(交易明細!$B$2:$B$73,$A2,交易明細!$J$2:$J$73,"時間出場") | F2: =COUNTIFS(交易明細!$B$2:$B$73,$A2,交易明細!$J$2:$J$73,"止盈") | G2: =COUNTIFS(交易明細!$B$2:$B$73,$A2,交易明細!$J$2:$J$73,"止損") | H2: =IFERROR(F2/E2,0) | I2: =IFERROR(AVERAGEIFS(交易明細!$L$2:$L$73,交易明細!$B$2:$B$73,$A2,交易明細!$J$2:$J$73,"<>未平倉"),0) | J2: =SUMIFS(交易明細!$L$2:$L$73,交易明細!$B$2:$B$73,$A2,交易明細!$J$2:$J$73,"<>未平倉") | K2: =IFERROR(AVERAGEIFS(交易明細!$K$2:$K$73,交易明細!$B$2:$B$73,$A2,交易明細!$J$2:$J$73,"<>未平倉"),0) | L2: =COUNTIFS(交易明細!$B$2:$B$73,$A2,交易明細!$J$2:$J$73,"未平倉")
A3: NOM_USDT_PERP | B3: =COUNTIFS(交易明細!$B$2:$B$73,$A3) | C3: =COUNTIFS(交易明細!$B$2:$B$73,$A3,交易明細!$C$2:$C$73,"做多") | D3: =COUNTIFS(交易明細!$B$2:$B$73,$A3,交易明細!$C$2:$C$73,"做空") | E3: =F3+G3+COUNTIFS(交易明細!$B$2:$B$73,$A3,交易明細!$J$2:$J$73,"時間出場") | F3: =COUNTIFS(交易明細!$B$2:$B$73,$A3,交易明細!$J$2:$J$73,"止盈") | G3: =COUNTIFS(交易明細!$B$2:$B$73,$A3,交易明細!$J$2:$J$73,"止損") | H3: =IFERROR(F3/E3,0) | I3: =IFERROR(AVERAGEIFS(交易明細!$L$2:$L$73,交易明細!$B$2:$B$73,$A3,交易明細!$J$2:$J$73,"<>未平倉"),0) | J3: =SUMIFS(交易明細!$L$2:$L$73,交易明細!$B$2:$B$73,$A3,交易明細!$J$2:$J$73,"<>未平倉") | K3: =IFERROR(AVERAGEIFS(交易明細!$K$2:$K$73,交易明細!$B$2:$B$73,$A3,交易明細!$J$2:$J$73,"<>未平倉"),0) | L3: =COUNTIFS(交易明細!$B$2:$B$73,$A3,交易明細!$J$2:$J$73,"未平倉")
A4: MOVR_USDT_PERP | B4: =COUNTIFS(交易明細!$B$2:$B$73,$A4) | C4: =COUNTIFS(交易明細!$B$2:$B$73,$A4,交易明細!$C$2:$C$73,"做多") | D4: =COUNTIFS(交易明細!$B$2:$B$73,$A4,交易明細!$C$2:$C$73,"做空") | E4: =F4+G4+COUNTIFS(交易明細!$B$2:$B$73,$A4,交易明細!$J$2:$J$73,"時間出場") | F4: =COUNTIFS(交易明細!$B$2:$B$73,$A4,交易明細!$J$2:$J$73,"止盈") | G4: =COUNTIFS(交易明細!$B$2:$B$73,$A4,交易明細!$J$2:$J$73,"止損") | H4: =IFERROR(F4/E4,0) | I4: =IFERROR(AVERAGEIFS(交易明細!$L$2:$L$73,交易明細!$B$2:$B$73,$A4,交易明細!$J$2:$J$73,"<>未平倉"),0) | J4: =SUMIFS(交易明細!$L$2:$L$73,交易明細!$B$2:$B$73,$A4,交易明細!$J$2:$J$73,"<>未平倉") | K4: =IFERROR(AVERAGEIFS(交易明細!$K$2:$K$73,交易明細!$B$2:$B$73,$A4,交易明細!$J$2:$J$73,"<>未平倉"),0) | L4: =COUNTIFS(交易明細!$B$2:$B$73,$A4,交易明細!$J$2:$J$73,"未平倉")
A5: BR_USDT_PERP | B5: =COUNTIFS(交易明細!$B$2:$B$73,$A5) | C5: =COUNTIFS(交易明細!$B$2:$B$73,$A5,交易明細!$C$2:$C$73,"做多") | D5: =COUNTIFS(交易明細!$B$2:$B$73,$A5,交易明細!$C$2:$C$73,"做空") | E5: =F5+G5+COUNTIFS(交易明細!$B$2:$B$73,$A5,交易明細!$J$2:$J$73,"時間出場") | F5: =COUNTIFS(交易明細!$B$2:$B$73,$A5,交易明細!$J$2:$J$73,"止盈") | G5: =COUNTIFS(交易明細!$B$2:$B$73,$A5,交易明細!$J$2:$J$73,"止損") | H5: =IFERROR(F5/E5,0) | I5: =IFERROR(AVERAGEIFS(交易明細!$L$2:$L$73,交易明細!$B$2:$B$73,$A5,交易明細!$J$2:$J$73,"<>未平倉"),0) | J5: =SUMIFS(交易明細!$L$2:$L$73,交易明細!$B$2:$B$73,$A5,交易明細!$J$2:$J$73,"<>未平倉") | K5: =IFERROR(AVERAGEIFS(交易明細!$K$2:$K$73,交易明細!$B$2:$B$73,$A5,交易明細!$J$2:$J$73,"<>未平倉"),0) | L5: =COUNTIFS(交易明細!$B$2:$B$73,$A5,交易明細!$J$2:$J$73,"未平倉")
A6: LYN_USDT_PERP | B6: =COUNTIFS(交易明細!$B$2:$B$73,$A6) | C6: =COUNTIFS(交易明細!$B$2:$B$73,$A6,交易明細!$C$2:$C$73,"做多") | D6: =COUNTIFS(交易明細!$B$2:$B$73,$A6,交易明細!$C$2:$C$73,"做空") | E6: =F6+G6+COUNTIFS(交易明細!$B$2:$B$73,$A6,交易明細!$J$2:$J$73,"時間出場") | F6: =COUNTIFS(交易明細!$B$2:$B$73,$A6,交易明細!$J$2:$J$73,"止盈") | G6: =COUNTIFS(交易明細!$B$2:$B$73,$A6,交易明細!$J$2:$J$73,"止損") | H6: =IFERROR(F6/E6,0) | I6: =IFERROR(AVERAGEIFS(交易明細!$L$2:$L$73,交易明細!$B$2:$B$73,$A6,交易明細!$J$2:$J$73,"<>未平倉"),0) | J6: =SUMIFS(交易明細!$L$2:$L$73,交易明細!$B$2:$B$73,$A6,交易明細!$J$2:$J$73,"<>未平倉") | K6: =IFERROR(AVERAGEIFS(交易明細!$K$2:$K$73,交易明細!$B$2:$B$73,$A6,交易明細!$J$2:$J$73,"<>未平倉"),0) | L6: =COUNTIFS(交易明細!$B$2:$B$73,$A6,交易明細!$J$2:$J$73,"未平倉")
A7: ARX_USDT_PERP | B7: =COUNTIFS(交易明細!$B$2:$B$73,$A7) | C7: =COUNTIFS(交易明細!$B$2:$B$73,$A7,交易明細!$C$2:$C$73,"做多") | D7: =COUNTIFS(交易明細!$B$2:$B$73,$A7,交易明細!$C$2:$C$73,"做空") | E7: =F7+G7+COUNTIFS(交易明細!$B$2:$B$73,$A7,交易明細!$J$2:$J$73,"時間出場") | F7: =COUNTIFS(交易明細!$B$2:$B$73,$A7,交易明細!$J$2:$J$73,"止盈") | G7: =COUNTIFS(交易明細!$B$2:$B$73,$A7,交易明細!$J$2:$J$73,"止損") | H7: =IFERROR(F7/E7,0) | I7: =IFERROR(AVERAGEIFS(交易明細!$L$2:$L$73,交易明細!$B$2:$B$73,$A7,交易明細!$J$2:$J$73,"<>未平倉"),0) | J7: =SUMIFS(交易明細!$L$2:$L$73,交易明細!$B$2:$B$73,$A7,交易明細!$J$2:$J$73,"<>未平倉") | K7: =IFERROR(AVERAGEIFS(交易明細!$K$2:$K$73,交易明細!$B$2:$B$73,$A7,交易明細!$J$2:$J$73,"<>未平倉"),0) | L7: =COUNTIFS(交易明細!$B$2:$B$73,$A7,交易明細!$J$2:$J$73,"未平倉")
A8: AGT_USDT_PERP | B8: =COUNTIFS(交易明細!$B$2:$B$73,$A8) | C8: =COUNTIFS(交易明細!$B$2:$B$73,$A8,交易明細!$C$2:$C$73,"做多") | D8: =COUNTIFS(交易明細!$B$2:$B$73,$A8,交易明細!$C$2:$C$73,"做空") | E8: =F8+G8+COUNTIFS(交易明細!$B$2:$B$73,$A8,交易明細!$J$2:$J$73,"時間出場") | F8: =COUNTIFS(交易明細!$B$2:$B$73,$A8,交易明細!$J$2:$J$73,"止盈") | G8: =COUNTIFS(交易明細!$B$2:$B$73,$A8,交易明細!$J$2:$J$73,"止損") | H8: =IFERROR(F8/E8,0) | I8: =IFERROR(AVERAGEIFS(交易明細!$L$2:$L$73,交易明細!$B$2:$B$73,$A8,交易明細!$J$2:$J$73,"<>未平倉"),0) | J8: =SUMIFS(交易明細!$L$2:$L$73,交易明細!$B$2:$B$73,$A8,交易明細!$J$2:$J$73,"<>未平倉") | K8: =IFERROR(AVERAGEIFS(交易明細!$K$2:$K$73,交易明細!$B$2:$B$73,$A8,交易明細!$J$2:$J$73,"<>未平倉"),0) | L8: =COUNTIFS(交易明細!$B$2:$B$73,$A8,交易明細!$J$2:$J$73,"未平倉")
A9: PHA_USDT_PERP | B9: =COUNTIFS(交易明細!$B$2:$B$73,$A9) | C9: =COUNTIFS(交易明細!$B$2:$B$73,$A9,交易明細!$C$2:$C$73,"做多") | D9: =COUNTIFS(交易明細!$B$2:$B$73,$A9,交易明細!$C$2:$C$73,"做空") | E9: =F9+G9+COUNTIFS(交易明細!$B$2:$B$73,$A9,交易明細!$J$2:$J$73,"時間出場") | F9: =COUNTIFS(交易明細!$B$2:$B$73,$A9,交易明細!$J$2:$J$73,"止盈") | G9: =COUNTIFS(交易明細!$B$2:$B$73,$A9,交易明細!$J$2:$J$73,"止損") | H9: =IFERROR(F9/E9,0) | I9: =IFERROR(AVERAGEIFS(交易明細!$L$2:$L$73,交易明細!$B$2:$B$73,$A9,交易明細!$J$2:$J$73,"<>未平倉"),0) | J9: =SUMIFS(交易明細!$L$2:$L$73,交易明細!$B$2:$B$73,$A9,交易明細!$J$2:$J$73,"<>未平倉") | K9: =IFERROR(AVERAGEIFS(交易明細!$K$2:$K$73,交易明細!$B$2:$B$73,$A9,交易明細!$J$2:$J$73,"<>未平倉"),0) | L9: =COUNTIFS(交易明細!$B$2:$B$73,$A9,交易明細!$J$2:$J$73,"未平倉")
A10: SPK_USDT_PERP | B10: =COUNTIFS(交易明細!$B$2:$B$73,$A10) | C10: =COUNTIFS(交易明細!$B$2:$B$73,$A10,交易明細!$C$2:$C$73,"做多") | D10: =COUNTIFS(交易明細!$B$2:$B$73,$A10,交易明細!$C$2:$C$73,"做空") | E10: =F10+G10+COUNTIFS(交易明細!$B$2:$B$73,$A10,交易明細!$J$2:$J$73,"時間出場") | F10: =COUNTIFS(交易明細!$B$2:$B$73,$A10,交易明細!$J$2:$J$73,"止盈") | G10: =COUNTIFS(交易明細!$B$2:$B$73,$A10,交易明細!$J$2:$J$73,"止損") | H10: =IFERROR(F10/E10,0) | I10: =IFERROR(AVERAGEIFS(交易明細!$L$2:$L$73,交易明細!$B$2:$B$73,$A10,交易明細!$J$2:$J$73,"<>未平倉"),0) | J10: =SUMIFS(交易明細!$L$2:$L$73,交易明細!$B$2:$B$73,$A10,交易明細!$J$2:$J$73,"<>未平倉") | K10: =IFERROR(AVERAGEIFS(交易明細!$K$2:$K$73,交易明細!$B$2:$B$73,$A10,交易明細!$J$2:$J$73,"<>未平倉"),0) | L10: =COUNTIFS(交易明細!$B$2:$B$73,$A10,交易明細!$J$2:$J$73,"未平倉")
A11: 2Z_USDT_PERP | B11: =COUNTIFS(交易明細!$B$2:$B$73,$A11) | C11: =COUNTIFS(交易明細!$B$2:$B$73,$A11,交易明細!$C$2:$C$73,"做多") | D11: =COUNTIFS(交易明細!$B$2:$B$73,$A11,交易明細!$C$2:$C$73,"做空") | E11: =F11+G11+COUNTIFS(交易明細!$B$2:$B$73,$A11,交易明細!$J$2:$J$73,"時間出場") | F11: =COUNTIFS(交易明細!$B$2:$B$73,$A11,交易明細!$J$2:$J$73,"止盈") | G11: =COUNTIFS(交易明細!$B$2:$B$73,$A11,交易明細!$J$2:$J$73,"止損") | H11: =IFERROR(F11/E11,0) | I11: =IFERROR(AVERAGEIFS(交易明細!$L$2:$L$73,交易明細!$B$2:$B$73,$A11,交易明細!$J$2:$J$73,"<>未平倉"),0) | J11: =SUMIFS(交易明細!$L$2:$L$73,交易明細!$B$2:$B$73,$A11,交易明細!$J$2:$J$73,"<>未平倉") | K11: =IFERROR(AVERAGEIFS(交易明細!$K$2:$K$73,交易明細!$B$2:$B$73,$A11,交易明細!$J$2:$J$73,"<>未平倉"),0) | L11: =COUNTIFS(交易明細!$B$2:$B$73,$A11,交易明細!$J$2:$J$73,"未平倉")
A12: SOON_USDT_PERP | B12: =COUNTIFS(交易明細!$B$2:$B$73,$A12) | C12: =COUNTIFS(交易明細!$B$2:$B$73,$A12,交易明細!$C$2:$C$73,"做多") | D12: =COUNTIFS(交易明細!$B$2:$B$73,$A12,交易明細!$C$2:$C$73,"做空") | E12: =F12+G12+COUNTIFS(交易明細!$B$2:$B$73,$A12,交易明細!$J$2:$J$73,"時間出場") | F12: =COUNTIFS(交易明細!$B$2:$B$73,$A12,交易明細!$J$2:$J$73,"止盈") | G12: =COUNTIFS(交易明細!$B$2:$B$73,$A12,交易明細!$J$2:$J$73,"止損") | H12: =IFERROR(F12/E12,0) | I12: =IFERROR(AVERAGEIFS(交易明細!$L$2:$L$73,交易明細!$B$2:$B$73,$A12,交易明細!$J$2:$J$73,"<>未平倉"),0) | J12: =SUMIFS(交易明細!$L$2:$L$73,交易明細!$B$2:$B$73,$A12,交易明細!$J$2:$J$73,"<>未平倉") | K12: =IFERROR(AVERAGEIFS(交易明細!$K$2:$K$73,交易明細!$B$2:$B$73,$A12,交易明細!$J$2:$J$73,"<>未平倉"),0) | L12: =COUNTIFS(交易明細!$B$2:$B$73,$A12,交易明細!$J$2:$J$73,"未平倉")
A13: PROS_USDT_PERP | B13: =COUNTIFS(交易明細!$B$2:$B$73,$A13) | C13: =COUNTIFS(交易明細!$B$2:$B$73,$A13,交易明細!$C$2:$C$73,"做多") | D13: =COUNTIFS(交易明細!$B$2:$B$73,$A13,交易明細!$C$2:$C$73,"做空") | E13: =F13+G13+COUNTIFS(交易明細!$B$2:$B$73,$A13,交易明細!$J$2:$J$73,"時間出場") | F13: =COUNTIFS(交易明細!$B$2:$B$73,$A13,交易明細!$J$2:$J$73,"止盈") | G13: =COUNTIFS(交易明細!$B$2:$B$73,$A13,交易明細!$J$2:$J$73,"止損") | H13: =IFERROR(F13/E13,0) | I13: =IFERROR(AVERAGEIFS(交易明細!$L$2:$L$73,交易明細!$B$2:$B$73,$A13,交易明細!$J$2:$J$73,"<>未平倉"),0) | J13: =SUMIFS(交易明細!$L$2:$L$73,交易明細!$B$2:$B$73,$A13,交易明細!$J$2:$J$73,"<>未平倉") | K13: =IFERROR(AVERAGEIFS(交易明細!$K$2:$K$73,交易明細!$B$2:$B$73,$A13,交易明細!$J$2:$J$73,"<>未平倉"),0) | L13: =COUNTIFS(交易明細!$B$2:$B$73,$A13,交易明細!$J$2:$J$73,"未平倉")
... A48: MAGIC_USDT_PERP | B48: =COUNTIFS(交易明細!$B$2:$B$73,$A48) | C48: =COUNTIFS(交易明細!$B$2:$B$73,$A48,交易明細!$C$2:$C$73,"做多") | D48: =COUNTIFS(交易明細!$B$2:$B$73,$A48,交易明細!$C$2:$C$73,"做空") | E48: =F48+G48+COUNTIFS(交易明細!$B$2:$B$73,$A48,交易明細!$J$2:$J$73,"時間出場") | F48: =COUNTIFS(交易明細!$B$2:$B$73,$A48,交易明細!$J$2:$J$73,"止盈") | G48: =COUNTIFS(交易明細!$B$2:$B$73,$A48,交易明細!$J$2:$J$73,"止損") | H48: =IFERROR(F48/E48,0) | I48: =IFERROR(AVERAGEIFS(交易明細!$L$2:$L$73,交易明細!$B$2:$B$73,$A48,交易明細!$J$2:$J$73,"<>未平倉"),0) | J48: =SUMIFS(交易明細!$L$2:$L$73,交易明細!$B$2:$B$73,$A48,交易明細!$J$2:$J$73,"<>未平倉") | K48: =IFERROR(AVERAGEIFS(交易明細!$K$2:$K$73,交易明細!$B$2:$B$73,$A48,交易明細!$J$2:$J$73,"<>未平倉"),0) | L48: =COUNTIFS(交易明細!$B$2:$B$73,$A48,交易明細!$J$2:$J$73,"未平倉")

Sheet 掃描清單
A1: 交易對 | B1: 狀態 | C1: 原因/備註 | D1: K棒數 | E1: 期間最低價 | F1: 期間最高價 | G1: 訊號數(多) | H1: 訊號數(空)
A2: 0G_USDT_PERP | B2: 已掃描
A3: 1INCH_USDT_PERP | B3: 已掃描
A4: 2Z_USDT_PERP | B4: 已掃描
A5: 4_USDT_PERP | B5: 已掃描
A6: AAVE_USDT_PERP | B6: 已掃描
A7: AAX_USDT_PERP | B7: 已掃描
A8: ACE_USDT_PERP | B8: 已掃描
A9: ACH_USDT_PERP | B9: 已掃描
A10: ACT_USDT_PERP | B10: 已掃描
A11: ADA_USDT_PERP | B11: 已掃描
A12: AERO_USDT_PERP | B12: 已掃描
A13: AEVO_USDT_PERP | B13: 已掃描
... A437: 牛来_USDT_PERP | B437: 已掃描
